[11/Aug/2014 17:13:15] ERROR [django.request:224] Internal Server Error: /contact/duplicates/29/
Traceback (most recent call last):
  File "/home/lenovo/Envs/contact/local/lib/python2.7/site-packages/django/core/handlers/base.py", line 112, in get_response
    response = wrapped_callback(request, *callback_args, **callback_kwargs)
  File "/home/lenovo/Envs/contact/local/lib/python2.7/site-packages/django/views/generic/base.py", line 69, in view
    return self.dispatch(request, *args, **kwargs)
  File "/home/lenovo/Envs/contact/local/lib/python2.7/site-packages/django/views/decorators/csrf.py", line 57, in wrapped_view
    return view_func(*args, **kwargs)
  File "/home/lenovo/Envs/contact/local/lib/python2.7/site-packages/rest_framework/views.py", line 400, in dispatch
    response = self.handle_exception(exc)
  File "/home/lenovo/Envs/contact/local/lib/python2.7/site-packages/rest_framework/views.py", line 397, in dispatch
    response = handler(request, *args, **kwargs)
  File "/home/lenovo/projects/contact/manager/views.py", line 42, in get
    c = UserContact.objects.get(pk=cid)
  File "/home/lenovo/Envs/contact/local/lib/python2.7/site-packages/django/db/models/manager.py", line 151, in get
    return self.get_queryset().get(*args, **kwargs)
  File "/home/lenovo/Envs/contact/local/lib/python2.7/site-packages/django/db/models/query.py", line 304, in get
    num = len(clone)
  File "/home/lenovo/Envs/contact/local/lib/python2.7/site-packages/django/db/models/query.py", line 77, in __len__
    self._fetch_all()
  File "/home/lenovo/Envs/contact/local/lib/python2.7/site-packages/django/db/models/query.py", line 857, in _fetch_all
    self._result_cache = list(self.iterator())
  File "/home/lenovo/Envs/contact/local/lib/python2.7/site-packages/django/db/models/query.py", line 220, in iterator
    for row in compiler.results_iter():
  File "/home/lenovo/Envs/contact/local/lib/python2.7/site-packages/django/db/models/sql/compiler.py", line 713, in results_iter
    for rows in self.execute_sql(MULTI):
  File "/home/lenovo/Envs/contact/local/lib/python2.7/site-packages/django/db/models/sql/compiler.py", line 786, in execute_sql
    cursor.execute(sql, params)
  File "/home/lenovo/Envs/contact/local/lib/python2.7/site-packages/django/db/backends/util.py", line 69, in execute
    return super(CursorDebugWrapper, self).execute(sql, params)
  File "/home/lenovo/Envs/contact/local/lib/python2.7/site-packages/django/db/backends/util.py", line 53, in execute
    return self.cursor.execute(sql, params)
  File "/home/lenovo/Envs/contact/local/lib/python2.7/site-packages/django/db/utils.py", line 99, in __exit__
    six.reraise(dj_exc_type, dj_exc_value, traceback)
  File "/home/lenovo/Envs/contact/local/lib/python2.7/site-packages/django/db/backends/util.py", line 53, in execute
    return self.cursor.execute(sql, params)
ProgrammingError: column contact_usercontact.note does not exist
LINE 1: ...tact"."status", "contact_usercontact"."category", "contact_u...
                                                             ^

[11/Aug/2014 17:13:15] ERROR [django.request:224] Internal Server Error: /contact/comm_items/29/
Traceback (most recent call last):
  File "/home/lenovo/Envs/contact/local/lib/python2.7/site-packages/django/core/handlers/base.py", line 112, in get_response
    response = wrapped_callback(request, *callback_args, **callback_kwargs)
  File "/home/lenovo/Envs/contact/local/lib/python2.7/site-packages/django/views/generic/base.py", line 69, in view
    return self.dispatch(request, *args, **kwargs)
  File "/home/lenovo/Envs/contact/local/lib/python2.7/site-packages/django/views/decorators/csrf.py", line 57, in wrapped_view
    return view_func(*args, **kwargs)
  File "/home/lenovo/Envs/contact/local/lib/python2.7/site-packages/rest_framework/views.py", line 400, in dispatch
    response = self.handle_exception(exc)
  File "/home/lenovo/Envs/contact/local/lib/python2.7/site-packages/rest_framework/views.py", line 397, in dispatch
    response = handler(request, *args, **kwargs)
  File "/home/lenovo/projects/contact/contact/views.py", line 52, in get
    contact = UserContact.objects.get(pk=cid)
  File "/home/lenovo/Envs/contact/local/lib/python2.7/site-packages/django/db/models/manager.py", line 151, in get
    return self.get_queryset().get(*args, **kwargs)
  File "/home/lenovo/Envs/contact/local/lib/python2.7/site-packages/django/db/models/query.py", line 304, in get
    num = len(clone)
  File "/home/lenovo/Envs/contact/local/lib/python2.7/site-packages/django/db/models/query.py", line 77, in __len__
    self._fetch_all()
  File "/home/lenovo/Envs/contact/local/lib/python2.7/site-packages/django/db/models/query.py", line 857, in _fetch_all
    self._result_cache = list(self.iterator())
  File "/home/lenovo/Envs/contact/local/lib/python2.7/site-packages/django/db/models/query.py", line 220, in iterator
    for row in compiler.results_iter():
  File "/home/lenovo/Envs/contact/local/lib/python2.7/site-packages/django/db/models/sql/compiler.py", line 713, in results_iter
    for rows in self.execute_sql(MULTI):
  File "/home/lenovo/Envs/contact/local/lib/python2.7/site-packages/django/db/models/sql/compiler.py", line 786, in execute_sql
    cursor.execute(sql, params)
  File "/home/lenovo/Envs/contact/local/lib/python2.7/site-packages/django/db/backends/util.py", line 69, in execute
    return super(CursorDebugWrapper, self).execute(sql, params)
  File "/home/lenovo/Envs/contact/local/lib/python2.7/site-packages/django/db/backends/util.py", line 53, in execute
    return self.cursor.execute(sql, params)
  File "/home/lenovo/Envs/contact/local/lib/python2.7/site-packages/django/db/utils.py", line 99, in __exit__
    six.reraise(dj_exc_type, dj_exc_value, traceback)
  File "/home/lenovo/Envs/contact/local/lib/python2.7/site-packages/django/db/backends/util.py", line 53, in execute
    return self.cursor.execute(sql, params)
ProgrammingError: column contact_usercontact.note does not exist
LINE 1: ...tact"."status", "contact_usercontact"."category", "contact_u...
                                                             ^

[11/Aug/2014 17:13:15] ERROR [django.request:224] Internal Server Error: /contact/by_month/29/
Traceback (most recent call last):
  File "/home/lenovo/Envs/contact/local/lib/python2.7/site-packages/django/core/handlers/base.py", line 112, in get_response
    response = wrapped_callback(request, *callback_args, **callback_kwargs)
  File "/home/lenovo/Envs/contact/local/lib/python2.7/site-packages/django/views/generic/base.py", line 69, in view
    return self.dispatch(request, *args, **kwargs)
  File "/home/lenovo/Envs/contact/local/lib/python2.7/site-packages/django/views/decorators/csrf.py", line 57, in wrapped_view
    return view_func(*args, **kwargs)
  File "/home/lenovo/Envs/contact/local/lib/python2.7/site-packages/rest_framework/views.py", line 400, in dispatch
    response = self.handle_exception(exc)
  File "/home/lenovo/Envs/contact/local/lib/python2.7/site-packages/rest_framework/views.py", line 397, in dispatch
    response = handler(request, *args, **kwargs)
  File "/home/lenovo/projects/contact/contact/views.py", line 61, in get
    contact = UserContact.objects.get(pk=cid)
  File "/home/lenovo/Envs/contact/local/lib/python2.7/site-packages/django/db/models/manager.py", line 151, in get
    return self.get_queryset().get(*args, **kwargs)
  File "/home/lenovo/Envs/contact/local/lib/python2.7/site-packages/django/db/models/query.py", line 304, in get
    num = len(clone)
  File "/home/lenovo/Envs/contact/local/lib/python2.7/site-packages/django/db/models/query.py", line 77, in __len__
    self._fetch_all()
  File "/home/lenovo/Envs/contact/local/lib/python2.7/site-packages/django/db/models/query.py", line 857, in _fetch_all
    self._result_cache = list(self.iterator())
  File "/home/lenovo/Envs/contact/local/lib/python2.7/site-packages/django/db/models/query.py", line 220, in iterator
    for row in compiler.results_iter():
  File "/home/lenovo/Envs/contact/local/lib/python2.7/site-packages/django/db/models/sql/compiler.py", line 713, in results_iter
    for rows in self.execute_sql(MULTI):
  File "/home/lenovo/Envs/contact/local/lib/python2.7/site-packages/django/db/models/sql/compiler.py", line 786, in execute_sql
    cursor.execute(sql, params)
  File "/home/lenovo/Envs/contact/local/lib/python2.7/site-packages/django/db/backends/util.py", line 69, in execute
    return super(CursorDebugWrapper, self).execute(sql, params)
  File "/home/lenovo/Envs/contact/local/lib/python2.7/site-packages/django/db/backends/util.py", line 53, in execute
    return self.cursor.execute(sql, params)
  File "/home/lenovo/Envs/contact/local/lib/python2.7/site-packages/django/db/utils.py", line 99, in __exit__
    six.reraise(dj_exc_type, dj_exc_value, traceback)
  File "/home/lenovo/Envs/contact/local/lib/python2.7/site-packages/django/db/backends/util.py", line 53, in execute
    return self.cursor.execute(sql, params)
ProgrammingError: column contact_usercontact.note does not exist
LINE 1: ...tact"."status", "contact_usercontact"."category", "contact_u...
                                                             ^

[11/Aug/2014 17:13:15] ERROR [django.request:224] Internal Server Error: /lkdn/duplicates/29/
Traceback (most recent call last):
  File "/home/lenovo/Envs/contact/local/lib/python2.7/site-packages/django/core/handlers/base.py", line 112, in get_response
    response = wrapped_callback(request, *callback_args, **callback_kwargs)
  File "/home/lenovo/Envs/contact/local/lib/python2.7/site-packages/django/views/generic/base.py", line 69, in view
    return self.dispatch(request, *args, **kwargs)
  File "/home/lenovo/Envs/contact/local/lib/python2.7/site-packages/django/views/decorators/csrf.py", line 57, in wrapped_view
    return view_func(*args, **kwargs)
  File "/home/lenovo/Envs/contact/local/lib/python2.7/site-packages/rest_framework/views.py", line 400, in dispatch
    response = self.handle_exception(exc)
  File "/home/lenovo/Envs/contact/local/lib/python2.7/site-packages/rest_framework/views.py", line 397, in dispatch
    response = handler(request, *args, **kwargs)
  File "/home/lenovo/projects/contact/lkdn/views.py", line 42, in get
    c = UserContact.objects.get(pk=cid)
  File "/home/lenovo/Envs/contact/local/lib/python2.7/site-packages/django/db/models/manager.py", line 151, in get
    return self.get_queryset().get(*args, **kwargs)
  File "/home/lenovo/Envs/contact/local/lib/python2.7/site-packages/django/db/models/query.py", line 304, in get
    num = len(clone)
  File "/home/lenovo/Envs/contact/local/lib/python2.7/site-packages/django/db/models/query.py", line 77, in __len__
    self._fetch_all()
  File "/home/lenovo/Envs/contact/local/lib/python2.7/site-packages/django/db/models/query.py", line 857, in _fetch_all
    self._result_cache = list(self.iterator())
  File "/home/lenovo/Envs/contact/local/lib/python2.7/site-packages/django/db/models/query.py", line 220, in iterator
    for row in compiler.results_iter():
  File "/home/lenovo/Envs/contact/local/lib/python2.7/site-packages/django/db/models/sql/compiler.py", line 713, in results_iter
    for rows in self.execute_sql(MULTI):
  File "/home/lenovo/Envs/contact/local/lib/python2.7/site-packages/django/db/models/sql/compiler.py", line 786, in execute_sql
    cursor.execute(sql, params)
  File "/home/lenovo/Envs/contact/local/lib/python2.7/site-packages/django/db/backends/util.py", line 69, in execute
    return super(CursorDebugWrapper, self).execute(sql, params)
  File "/home/lenovo/Envs/contact/local/lib/python2.7/site-packages/django/db/backends/util.py", line 53, in execute
    return self.cursor.execute(sql, params)
  File "/home/lenovo/Envs/contact/local/lib/python2.7/site-packages/django/db/utils.py", line 99, in __exit__
    six.reraise(dj_exc_type, dj_exc_value, traceback)
  File "/home/lenovo/Envs/contact/local/lib/python2.7/site-packages/django/db/backends/util.py", line 53, in execute
    return self.cursor.execute(sql, params)
ProgrammingError: column contact_usercontact.note does not exist
LINE 1: ...tact"."status", "contact_usercontact"."category", "contact_u...
                                                             ^

[11/Aug/2014 17:13:37] ERROR [django.request:224] Internal Server Error: /contacts/
Traceback (most recent call last):
  File "/home/lenovo/Envs/contact/local/lib/python2.7/site-packages/django/core/handlers/base.py", line 112, in get_response
    response = wrapped_callback(request, *callback_args, **callback_kwargs)
  File "/home/lenovo/Envs/contact/local/lib/python2.7/site-packages/django/views/generic/base.py", line 69, in view
    return self.dispatch(request, *args, **kwargs)
  File "/home/lenovo/Envs/contact/local/lib/python2.7/site-packages/django/views/decorators/csrf.py", line 57, in wrapped_view
    return view_func(*args, **kwargs)
  File "/home/lenovo/Envs/contact/local/lib/python2.7/site-packages/rest_framework/views.py", line 400, in dispatch
    response = self.handle_exception(exc)
  File "/home/lenovo/Envs/contact/local/lib/python2.7/site-packages/rest_framework/views.py", line 397, in dispatch
    response = handler(request, *args, **kwargs)
  File "/home/lenovo/projects/contact/manager/views.py", line 26, in get
    slz = ContactZoneSerializer(manager.contacts_with_zone, many=True)
  File "/home/lenovo/projects/contact/zone/__init__.py", line 29, in contacts_with_zone
    result = [self.get_contact_with_zone(c) for c in self.contacts]
  File "/home/lenovo/Envs/contact/local/lib/python2.7/site-packages/django/db/models/query.py", line 96, in __iter__
    self._fetch_all()
  File "/home/lenovo/Envs/contact/local/lib/python2.7/site-packages/django/db/models/query.py", line 857, in _fetch_all
    self._result_cache = list(self.iterator())
  File "/home/lenovo/Envs/contact/local/lib/python2.7/site-packages/django/db/models/query.py", line 220, in iterator
    for row in compiler.results_iter():
  File "/home/lenovo/Envs/contact/local/lib/python2.7/site-packages/django/db/models/sql/compiler.py", line 713, in results_iter
    for rows in self.execute_sql(MULTI):
  File "/home/lenovo/Envs/contact/local/lib/python2.7/site-packages/django/db/models/sql/compiler.py", line 786, in execute_sql
    cursor.execute(sql, params)
  File "/home/lenovo/Envs/contact/local/lib/python2.7/site-packages/django/db/backends/util.py", line 69, in execute
    return super(CursorDebugWrapper, self).execute(sql, params)
  File "/home/lenovo/Envs/contact/local/lib/python2.7/site-packages/django/db/backends/util.py", line 53, in execute
    return self.cursor.execute(sql, params)
  File "/home/lenovo/Envs/contact/local/lib/python2.7/site-packages/django/db/utils.py", line 99, in __exit__
    six.reraise(dj_exc_type, dj_exc_value, traceback)
  File "/home/lenovo/Envs/contact/local/lib/python2.7/site-packages/django/db/backends/util.py", line 53, in execute
    return self.cursor.execute(sql, params)
ProgrammingError: column contact_usercontact.note does not exist
LINE 1: ...tact"."status", "contact_usercontact"."category", "contact_u...
                                                             ^

[11/Aug/2014 17:13:37] ERROR [django.request:224] Internal Server Error: /inbox/recent/
Traceback (most recent call last):
  File "/home/lenovo/Envs/contact/local/lib/python2.7/site-packages/django/core/handlers/base.py", line 112, in get_response
    response = wrapped_callback(request, *callback_args, **callback_kwargs)
  File "/home/lenovo/Envs/contact/local/lib/python2.7/site-packages/django/views/generic/base.py", line 69, in view
    return self.dispatch(request, *args, **kwargs)
  File "/home/lenovo/Envs/contact/local/lib/python2.7/site-packages/django/views/decorators/csrf.py", line 57, in wrapped_view
    return view_func(*args, **kwargs)
  File "/home/lenovo/Envs/contact/local/lib/python2.7/site-packages/rest_framework/views.py", line 400, in dispatch
    response = self.handle_exception(exc)
  File "/home/lenovo/Envs/contact/local/lib/python2.7/site-packages/rest_framework/views.py", line 397, in dispatch
    response = handler(request, *args, **kwargs)
  File "/home/lenovo/projects/contact/inbox/views.py", line 23, in get
    return Response(slz.data)
  File "/home/lenovo/Envs/contact/local/lib/python2.7/site-packages/rest_framework/serializers.py", line 573, in data
    self._data = [self.to_native(item) for item in obj]
  File "/home/lenovo/Envs/contact/local/lib/python2.7/site-packages/rest_framework/serializers.py", line 351, in to_native
    value = field.field_to_native(obj, field_name)
  File "/home/lenovo/Envs/contact/local/lib/python2.7/site-packages/rest_framework/fields.py", line 1035, in field_to_native
    value = getattr(self.parent, self.method_name)(obj)
  File "/home/lenovo/projects/contact/inbox/serializers.py", line 27, in get_name
    return contacts[0].mail_contact.user_contact.name
  File "/home/lenovo/Envs/contact/local/lib/python2.7/site-packages/django/db/models/fields/related.py", line 320, in __get__
    rel_obj = qs.get()
  File "/home/lenovo/Envs/contact/local/lib/python2.7/site-packages/django/db/models/query.py", line 304, in get
    num = len(clone)
  File "/home/lenovo/Envs/contact/local/lib/python2.7/site-packages/django/db/models/query.py", line 77, in __len__
    self._fetch_all()
  File "/home/lenovo/Envs/contact/local/lib/python2.7/site-packages/django/db/models/query.py", line 857, in _fetch_all
    self._result_cache = list(self.iterator())
  File "/home/lenovo/Envs/contact/local/lib/python2.7/site-packages/django/db/models/query.py", line 220, in iterator
    for row in compiler.results_iter():
  File "/home/lenovo/Envs/contact/local/lib/python2.7/site-packages/django/db/models/sql/compiler.py", line 713, in results_iter
    for rows in self.execute_sql(MULTI):
  File "/home/lenovo/Envs/contact/local/lib/python2.7/site-packages/django/db/models/sql/compiler.py", line 786, in execute_sql
    cursor.execute(sql, params)
  File "/home/lenovo/Envs/contact/local/lib/python2.7/site-packages/django/db/backends/util.py", line 69, in execute
    return super(CursorDebugWrapper, self).execute(sql, params)
  File "/home/lenovo/Envs/contact/local/lib/python2.7/site-packages/django/db/backends/util.py", line 53, in execute
    return self.cursor.execute(sql, params)
  File "/home/lenovo/Envs/contact/local/lib/python2.7/site-packages/django/db/utils.py", line 99, in __exit__
    six.reraise(dj_exc_type, dj_exc_value, traceback)
  File "/home/lenovo/Envs/contact/local/lib/python2.7/site-packages/django/db/backends/util.py", line 53, in execute
    return self.cursor.execute(sql, params)
ProgrammingError: column contact_usercontact.note does not exist
LINE 1: ...tact"."status", "contact_usercontact"."category", "contact_u...
                                                             ^

[11/Aug/2014 17:13:37] WARNING [django.request:143] Not Found: /favicon.ico
[11/Aug/2014 17:13:45] ERROR [django.request:224] Internal Server Error: /inbox/refresh/
Traceback (most recent call last):
  File "/home/lenovo/Envs/contact/local/lib/python2.7/site-packages/django/core/handlers/base.py", line 112, in get_response
    response = wrapped_callback(request, *callback_args, **callback_kwargs)
  File "/home/lenovo/Envs/contact/local/lib/python2.7/site-packages/django/views/generic/base.py", line 69, in view
    return self.dispatch(request, *args, **kwargs)
  File "/home/lenovo/Envs/contact/local/lib/python2.7/site-packages/django/views/decorators/csrf.py", line 57, in wrapped_view
    return view_func(*args, **kwargs)
  File "/home/lenovo/Envs/contact/local/lib/python2.7/site-packages/rest_framework/views.py", line 400, in dispatch
    response = self.handle_exception(exc)
  File "/home/lenovo/Envs/contact/local/lib/python2.7/site-packages/rest_framework/views.py", line 397, in dispatch
    response = handler(request, *args, **kwargs)
  File "/home/lenovo/Envs/contact/local/lib/python2.7/site-packages/django/db/transaction.py", line 371, in inner
    return func(*args, **kwargs)
  File "/home/lenovo/projects/contact/gmail/views.py", line 36, in get
    result = in_import.import_new()
  File "/home/lenovo/projects/contact/gmail/parsers.py", line 49, in import_new
    return self.__import()
  File "/home/lenovo/projects/contact/gmail/parsers.py", line 37, in __import
    self.__process_response(response)
  File "/home/lenovo/projects/contact/gmail/parsers.py", line 28, in __process_response
    mail_import.import_msg()
  File "/home/lenovo/projects/contact/gmail/parsers.py", line 171, in import_msg
    [c.save() for c in self.contact_imports]
  File "/home/lenovo/projects/contact/gmail/parsers.py", line 105, in save
    c = self.__save_contact(c)
  File "/home/lenovo/projects/contact/gmail/parsers.py", line 95, in __save_contact
    user_contact.save()
  File "/home/lenovo/Envs/contact/local/lib/python2.7/site-packages/django/db/models/base.py", line 545, in save
    force_update=force_update, update_fields=update_fields)
  File "/home/lenovo/Envs/contact/local/lib/python2.7/site-packages/django/db/models/base.py", line 573, in save_base
    updated = self._save_table(raw, cls, force_insert, force_update, using, update_fields)
  File "/home/lenovo/Envs/contact/local/lib/python2.7/site-packages/django/db/models/base.py", line 654, in _save_table
    result = self._do_insert(cls._base_manager, using, fields, update_pk, raw)
  File "/home/lenovo/Envs/contact/local/lib/python2.7/site-packages/django/db/models/base.py", line 687, in _do_insert
    using=using, raw=raw)
  File "/home/lenovo/Envs/contact/local/lib/python2.7/site-packages/django/db/models/manager.py", line 232, in _insert
    return insert_query(self.model, objs, fields, **kwargs)
  File "/home/lenovo/Envs/contact/local/lib/python2.7/site-packages/django/db/models/query.py", line 1514, in insert_query
    return query.get_compiler(using=using).execute_sql(return_id)
  File "/home/lenovo/Envs/contact/local/lib/python2.7/site-packages/django/db/models/sql/compiler.py", line 903, in execute_sql
    cursor.execute(sql, params)
  File "/home/lenovo/Envs/contact/local/lib/python2.7/site-packages/django/db/backends/util.py", line 69, in execute
    return super(CursorDebugWrapper, self).execute(sql, params)
  File "/home/lenovo/Envs/contact/local/lib/python2.7/site-packages/django/db/backends/util.py", line 53, in execute
    return self.cursor.execute(sql, params)
  File "/home/lenovo/Envs/contact/local/lib/python2.7/site-packages/django/db/utils.py", line 99, in __exit__
    six.reraise(dj_exc_type, dj_exc_value, traceback)
  File "/home/lenovo/Envs/contact/local/lib/python2.7/site-packages/django/db/backends/util.py", line 53, in execute
    return self.cursor.execute(sql, params)
ProgrammingError: column "note" of relation "contact_usercontact" does not exist
LINE 1: ...ame", "company", "user_id", "status", "category", "note") VA...
                                                             ^

[11/Aug/2014 17:14:01] ERROR [django.request:224] Internal Server Error: /contacts/
Traceback (most recent call last):
  File "/home/lenovo/Envs/contact/local/lib/python2.7/site-packages/django/core/handlers/base.py", line 112, in get_response
    response = wrapped_callback(request, *callback_args, **callback_kwargs)
  File "/home/lenovo/Envs/contact/local/lib/python2.7/site-packages/django/views/generic/base.py", line 69, in view
    return self.dispatch(request, *args, **kwargs)
  File "/home/lenovo/Envs/contact/local/lib/python2.7/site-packages/django/views/decorators/csrf.py", line 57, in wrapped_view
    return view_func(*args, **kwargs)
  File "/home/lenovo/Envs/contact/local/lib/python2.7/site-packages/rest_framework/views.py", line 400, in dispatch
    response = self.handle_exception(exc)
  File "/home/lenovo/Envs/contact/local/lib/python2.7/site-packages/rest_framework/views.py", line 397, in dispatch
    response = handler(request, *args, **kwargs)
  File "/home/lenovo/projects/contact/manager/views.py", line 26, in get
    slz = ContactZoneSerializer(manager.contacts_with_zone, many=True)
  File "/home/lenovo/projects/contact/zone/__init__.py", line 29, in contacts_with_zone
    result = [self.get_contact_with_zone(c) for c in self.contacts]
  File "/home/lenovo/Envs/contact/local/lib/python2.7/site-packages/django/db/models/query.py", line 96, in __iter__
    self._fetch_all()
  File "/home/lenovo/Envs/contact/local/lib/python2.7/site-packages/django/db/models/query.py", line 857, in _fetch_all
    self._result_cache = list(self.iterator())
  File "/home/lenovo/Envs/contact/local/lib/python2.7/site-packages/django/db/models/query.py", line 220, in iterator
    for row in compiler.results_iter():
  File "/home/lenovo/Envs/contact/local/lib/python2.7/site-packages/django/db/models/sql/compiler.py", line 713, in results_iter
    for rows in self.execute_sql(MULTI):
  File "/home/lenovo/Envs/contact/local/lib/python2.7/site-packages/django/db/models/sql/compiler.py", line 786, in execute_sql
    cursor.execute(sql, params)
  File "/home/lenovo/Envs/contact/local/lib/python2.7/site-packages/django/db/backends/util.py", line 69, in execute
    return super(CursorDebugWrapper, self).execute(sql, params)
  File "/home/lenovo/Envs/contact/local/lib/python2.7/site-packages/django/db/backends/util.py", line 53, in execute
    return self.cursor.execute(sql, params)
  File "/home/lenovo/Envs/contact/local/lib/python2.7/site-packages/django/db/utils.py", line 99, in __exit__
    six.reraise(dj_exc_type, dj_exc_value, traceback)
  File "/home/lenovo/Envs/contact/local/lib/python2.7/site-packages/django/db/backends/util.py", line 53, in execute
    return self.cursor.execute(sql, params)
ProgrammingError: column contact_usercontact.note does not exist
LINE 1: ...tact"."status", "contact_usercontact"."category", "contact_u...
                                                             ^

[11/Aug/2014 18:12:28] ERROR [django.request:224] Internal Server Error: /contact/note/23/
Traceback (most recent call last):
  File "/home/lenovo/Envs/contact/local/lib/python2.7/site-packages/django/core/handlers/base.py", line 112, in get_response
    response = wrapped_callback(request, *callback_args, **callback_kwargs)
  File "/home/lenovo/Envs/contact/local/lib/python2.7/site-packages/django/views/generic/base.py", line 69, in view
    return self.dispatch(request, *args, **kwargs)
  File "/home/lenovo/Envs/contact/local/lib/python2.7/site-packages/django/views/generic/base.py", line 87, in dispatch
    return handler(request, *args, **kwargs)
TypeError: post() takes exactly 4 arguments (3 given)
[12/Aug/2014 04:06:16] WARNING [django.request:143] Not Found: /favicon.ico
[12/Aug/2014 04:06:16] WARNING [django.request:143] Not Found: /favicon.ico
[12/Aug/2014 04:20:55] ERROR [django.request:224] Internal Server Error: /inbox/refresh/
Traceback (most recent call last):
  File "/home/lenovo/Envs/contact/local/lib/python2.7/site-packages/django/core/handlers/base.py", line 112, in get_response
    response = wrapped_callback(request, *callback_args, **callback_kwargs)
  File "/home/lenovo/Envs/contact/local/lib/python2.7/site-packages/django/views/generic/base.py", line 69, in view
    return self.dispatch(request, *args, **kwargs)
  File "/home/lenovo/Envs/contact/local/lib/python2.7/site-packages/django/views/decorators/csrf.py", line 57, in wrapped_view
    return view_func(*args, **kwargs)
  File "/home/lenovo/Envs/contact/local/lib/python2.7/site-packages/rest_framework/views.py", line 400, in dispatch
    response = self.handle_exception(exc)
  File "/home/lenovo/Envs/contact/local/lib/python2.7/site-packages/rest_framework/views.py", line 397, in dispatch
    response = handler(request, *args, **kwargs)
  File "/home/lenovo/Envs/contact/local/lib/python2.7/site-packages/django/db/transaction.py", line 371, in inner
    return func(*args, **kwargs)
  File "/home/lenovo/projects/contact/gmail/views.py", line 35, in get
    in_import = InboxImport(user)
  File "/home/lenovo/projects/contact/gmail/parsers.py", line 17, in __init__
    self.service = Auth.get_gmail_srv(user)
  File "/home/lenovo/projects/contact/gmail/__init__.py", line 43, in get_gmail_srv
    return build('gmail', 'v1', http=http)
  File "/home/lenovo/Envs/contact/local/lib/python2.7/site-packages/oauth2client/util.py", line 132, in positional_wrapper
    return wrapped(*args, **kwargs)
  File "/home/lenovo/Envs/contact/local/lib/python2.7/site-packages/apiclient/discovery.py", line 192, in build
    resp, content = http.request(requested_url)
  File "/home/lenovo/Envs/contact/local/lib/python2.7/site-packages/oauth2client/util.py", line 132, in positional_wrapper
    return wrapped(*args, **kwargs)
  File "/home/lenovo/Envs/contact/local/lib/python2.7/site-packages/oauth2client/client.py", line 490, in new_request
    redirections, connection_type)
  File "/home/lenovo/Envs/contact/local/lib/python2.7/site-packages/httplib2/__init__.py", line 1593, in request
    (response, content) = self._request(conn, authority, uri, request_uri, method, body, headers, redirections, cachekey)
  File "/home/lenovo/Envs/contact/local/lib/python2.7/site-packages/httplib2/__init__.py", line 1335, in _request
    (response, content) = self._conn_request(conn, request_uri, method, body, headers)
  File "/home/lenovo/Envs/contact/local/lib/python2.7/site-packages/httplib2/__init__.py", line 1257, in _conn_request
    conn.connect()
  File "/home/lenovo/Envs/contact/local/lib/python2.7/site-packages/httplib2/__init__.py", line 1060, in connect
    raise socket.error, msg
error: [Errno 111] Connection refused
[12/Aug/2014 04:24:12] ERROR [django.request:224] Internal Server Error: /inbox/refresh/
Traceback (most recent call last):
  File "/home/lenovo/Envs/contact/local/lib/python2.7/site-packages/django/core/handlers/base.py", line 112, in get_response
    response = wrapped_callback(request, *callback_args, **callback_kwargs)
  File "/home/lenovo/Envs/contact/local/lib/python2.7/site-packages/django/views/generic/base.py", line 69, in view
    return self.dispatch(request, *args, **kwargs)
  File "/home/lenovo/Envs/contact/local/lib/python2.7/site-packages/django/views/decorators/csrf.py", line 57, in wrapped_view
    return view_func(*args, **kwargs)
  File "/home/lenovo/Envs/contact/local/lib/python2.7/site-packages/rest_framework/views.py", line 400, in dispatch
    response = self.handle_exception(exc)
  File "/home/lenovo/Envs/contact/local/lib/python2.7/site-packages/rest_framework/views.py", line 397, in dispatch
    response = handler(request, *args, **kwargs)
  File "/home/lenovo/Envs/contact/local/lib/python2.7/site-packages/django/db/transaction.py", line 371, in inner
    return func(*args, **kwargs)
  File "/home/lenovo/projects/contact/gmail/views.py", line 35, in get
    in_import = InboxImport(user)
  File "/home/lenovo/projects/contact/gmail/parsers.py", line 17, in __init__
    self.service = Auth.get_gmail_srv(user)
  File "/home/lenovo/projects/contact/gmail/__init__.py", line 43, in get_gmail_srv
    return build('gmail', 'v1', http=http)
  File "/home/lenovo/Envs/contact/local/lib/python2.7/site-packages/oauth2client/util.py", line 132, in positional_wrapper
    return wrapped(*args, **kwargs)
  File "/home/lenovo/Envs/contact/local/lib/python2.7/site-packages/apiclient/discovery.py", line 192, in build
    resp, content = http.request(requested_url)
  File "/home/lenovo/Envs/contact/local/lib/python2.7/site-packages/oauth2client/util.py", line 132, in positional_wrapper
    return wrapped(*args, **kwargs)
  File "/home/lenovo/Envs/contact/local/lib/python2.7/site-packages/oauth2client/client.py", line 490, in new_request
    redirections, connection_type)
  File "/home/lenovo/Envs/contact/local/lib/python2.7/site-packages/httplib2/__init__.py", line 1593, in request
    (response, content) = self._request(conn, authority, uri, request_uri, method, body, headers, redirections, cachekey)
  File "/home/lenovo/Envs/contact/local/lib/python2.7/site-packages/httplib2/__init__.py", line 1335, in _request
    (response, content) = self._conn_request(conn, request_uri, method, body, headers)
  File "/home/lenovo/Envs/contact/local/lib/python2.7/site-packages/httplib2/__init__.py", line 1257, in _conn_request
    conn.connect()
  File "/home/lenovo/Envs/contact/local/lib/python2.7/site-packages/httplib2/__init__.py", line 1060, in connect
    raise socket.error, msg
error: [Errno 111] Connection refused
[12/Aug/2014 04:27:33] ERROR [django.request:224] Internal Server Error: /inbox/refresh/
Traceback (most recent call last):
  File "/home/lenovo/Envs/contact/local/lib/python2.7/site-packages/django/core/handlers/base.py", line 112, in get_response
    response = wrapped_callback(request, *callback_args, **callback_kwargs)
  File "/home/lenovo/Envs/contact/local/lib/python2.7/site-packages/django/views/generic/base.py", line 69, in view
    return self.dispatch(request, *args, **kwargs)
  File "/home/lenovo/Envs/contact/local/lib/python2.7/site-packages/django/views/decorators/csrf.py", line 57, in wrapped_view
    return view_func(*args, **kwargs)
  File "/home/lenovo/Envs/contact/local/lib/python2.7/site-packages/rest_framework/views.py", line 400, in dispatch
    response = self.handle_exception(exc)
  File "/home/lenovo/Envs/contact/local/lib/python2.7/site-packages/rest_framework/views.py", line 397, in dispatch
    response = handler(request, *args, **kwargs)
  File "/home/lenovo/Envs/contact/local/lib/python2.7/site-packages/django/db/transaction.py", line 371, in inner
    return func(*args, **kwargs)
  File "/home/lenovo/projects/contact/gmail/views.py", line 35, in get
    in_import = InboxImport(user)
  File "/home/lenovo/projects/contact/gmail/parsers.py", line 17, in __init__
    self.service = Auth.get_gmail_srv(user)
  File "/home/lenovo/projects/contact/gmail/__init__.py", line 43, in get_gmail_srv
    return build('gmail', 'v1', http=http)
  File "/home/lenovo/Envs/contact/local/lib/python2.7/site-packages/oauth2client/util.py", line 132, in positional_wrapper
    return wrapped(*args, **kwargs)
  File "/home/lenovo/Envs/contact/local/lib/python2.7/site-packages/apiclient/discovery.py", line 192, in build
    resp, content = http.request(requested_url)
  File "/home/lenovo/Envs/contact/local/lib/python2.7/site-packages/oauth2client/util.py", line 132, in positional_wrapper
    return wrapped(*args, **kwargs)
  File "/home/lenovo/Envs/contact/local/lib/python2.7/site-packages/oauth2client/client.py", line 490, in new_request
    redirections, connection_type)
  File "/home/lenovo/Envs/contact/local/lib/python2.7/site-packages/httplib2/__init__.py", line 1593, in request
    (response, content) = self._request(conn, authority, uri, request_uri, method, body, headers, redirections, cachekey)
  File "/home/lenovo/Envs/contact/local/lib/python2.7/site-packages/httplib2/__init__.py", line 1335, in _request
    (response, content) = self._conn_request(conn, request_uri, method, body, headers)
  File "/home/lenovo/Envs/contact/local/lib/python2.7/site-packages/httplib2/__init__.py", line 1257, in _conn_request
    conn.connect()
  File "/home/lenovo/Envs/contact/local/lib/python2.7/site-packages/httplib2/__init__.py", line 1060, in connect
    raise socket.error, msg
error: [Errno 111] Connection refused
[12/Aug/2014 04:58:02] WARNING [django.request:143] Not Found: /favicon.ico
[12/Aug/2014 05:30:04] WARNING [django.request:143] Not Found: /contact/reminder/add
[12/Aug/2014 05:32:03] WARNING [django.request:143] Not Found: /contact/reminder/add
[12/Aug/2014 05:35:23] ERROR [django.request:224] Internal Server Error: /reminder/add
Traceback (most recent call last):
  File "/home/lenovo/Envs/contact/local/lib/python2.7/site-packages/django/core/handlers/base.py", line 88, in get_response
    response = middleware_method(request)
  File "/home/lenovo/Envs/contact/local/lib/python2.7/site-packages/django/middleware/common.py", line 81, in process_request
    "settings.") % (new_url[0], new_url[1]))
RuntimeError: You called this URL via POST, but the URL doesn't end in a slash and you have APPEND_SLASH set. Django can't redirect to the slash URL while maintaining POST data. Change your form to point to localhost:9000/reminder/add/ (note the trailing slash), or set APPEND_SLASH=False in your Django settings.
[12/Aug/2014 05:36:03] ERROR [django.request:224] Internal Server Error: /reminder/add/
Traceback (most recent call last):
  File "/home/lenovo/Envs/contact/local/lib/python2.7/site-packages/django/core/handlers/base.py", line 112, in get_response
    response = wrapped_callback(request, *callback_args, **callback_kwargs)
  File "/home/lenovo/Envs/contact/local/lib/python2.7/site-packages/django/views/generic/base.py", line 69, in view
    return self.dispatch(request, *args, **kwargs)
  File "/home/lenovo/Envs/contact/local/lib/python2.7/site-packages/django/views/decorators/csrf.py", line 57, in wrapped_view
    return view_func(*args, **kwargs)
  File "/home/lenovo/Envs/contact/local/lib/python2.7/site-packages/rest_framework/views.py", line 400, in dispatch
    response = self.handle_exception(exc)
  File "/home/lenovo/Envs/contact/local/lib/python2.7/site-packages/rest_framework/views.py", line 397, in dispatch
    response = handler(request, *args, **kwargs)
  File "/home/lenovo/projects/contact/reminder/views.py", line 15, in post
    data = json.loads(request.POST)
  File "/usr/lib/python2.7/json/__init__.py", line 338, in loads
    return _default_decoder.decode(s)
  File "/usr/lib/python2.7/json/decoder.py", line 366, in decode
    obj, end = self.raw_decode(s, idx=_w(s, 0).end())
TypeError: expected string or buffer
[12/Aug/2014 05:44:40] ERROR [django.request:224] Internal Server Error: /reminder/add/
Traceback (most recent call last):
  File "/home/lenovo/Envs/contact/local/lib/python2.7/site-packages/django/core/handlers/base.py", line 112, in get_response
    response = wrapped_callback(request, *callback_args, **callback_kwargs)
  File "/home/lenovo/Envs/contact/local/lib/python2.7/site-packages/django/views/generic/base.py", line 69, in view
    return self.dispatch(request, *args, **kwargs)
  File "/home/lenovo/Envs/contact/local/lib/python2.7/site-packages/django/views/decorators/csrf.py", line 57, in wrapped_view
    return view_func(*args, **kwargs)
  File "/home/lenovo/Envs/contact/local/lib/python2.7/site-packages/rest_framework/views.py", line 400, in dispatch
    response = self.handle_exception(exc)
  File "/home/lenovo/Envs/contact/local/lib/python2.7/site-packages/rest_framework/views.py", line 397, in dispatch
    response = handler(request, *args, **kwargs)
  File "/home/lenovo/projects/contact/reminder/views.py", line 15, in post
    data = json.loads(request.POST)
  File "/usr/lib/python2.7/json/__init__.py", line 338, in loads
    return _default_decoder.decode(s)
  File "/usr/lib/python2.7/json/decoder.py", line 366, in decode
    obj, end = self.raw_decode(s, idx=_w(s, 0).end())
TypeError: expected string or buffer
[12/Aug/2014 05:45:00] ERROR [django.request:224] Internal Server Error: /reminder/add/
Traceback (most recent call last):
  File "/home/lenovo/Envs/contact/local/lib/python2.7/site-packages/django/core/handlers/base.py", line 112, in get_response
    response = wrapped_callback(request, *callback_args, **callback_kwargs)
  File "/home/lenovo/Envs/contact/local/lib/python2.7/site-packages/django/views/generic/base.py", line 69, in view
    return self.dispatch(request, *args, **kwargs)
  File "/home/lenovo/Envs/contact/local/lib/python2.7/site-packages/django/views/decorators/csrf.py", line 57, in wrapped_view
    return view_func(*args, **kwargs)
  File "/home/lenovo/Envs/contact/local/lib/python2.7/site-packages/rest_framework/views.py", line 400, in dispatch
    response = self.handle_exception(exc)
  File "/home/lenovo/Envs/contact/local/lib/python2.7/site-packages/rest_framework/views.py", line 397, in dispatch
    response = handler(request, *args, **kwargs)
  File "/home/lenovo/projects/contact/reminder/views.py", line 15, in post
    data = json.loads(request.POST)
  File "/usr/lib/python2.7/json/__init__.py", line 338, in loads
    return _default_decoder.decode(s)
  File "/usr/lib/python2.7/json/decoder.py", line 366, in decode
    obj, end = self.raw_decode(s, idx=_w(s, 0).end())
TypeError: expected string or buffer
[12/Aug/2014 05:45:13] ERROR [django.request:224] Internal Server Error: /reminder/add/
Traceback (most recent call last):
  File "/home/lenovo/Envs/contact/local/lib/python2.7/site-packages/django/core/handlers/base.py", line 112, in get_response
    response = wrapped_callback(request, *callback_args, **callback_kwargs)
  File "/home/lenovo/Envs/contact/local/lib/python2.7/site-packages/django/views/generic/base.py", line 69, in view
    return self.dispatch(request, *args, **kwargs)
  File "/home/lenovo/Envs/contact/local/lib/python2.7/site-packages/django/views/decorators/csrf.py", line 57, in wrapped_view
    return view_func(*args, **kwargs)
  File "/home/lenovo/Envs/contact/local/lib/python2.7/site-packages/rest_framework/views.py", line 400, in dispatch
    response = self.handle_exception(exc)
  File "/home/lenovo/Envs/contact/local/lib/python2.7/site-packages/rest_framework/views.py", line 397, in dispatch
    response = handler(request, *args, **kwargs)
  File "/home/lenovo/projects/contact/reminder/views.py", line 15, in post
    data = json.loads(request.POST)
  File "/usr/lib/python2.7/json/__init__.py", line 338, in loads
    return _default_decoder.decode(s)
  File "/usr/lib/python2.7/json/decoder.py", line 366, in decode
    obj, end = self.raw_decode(s, idx=_w(s, 0).end())
TypeError: expected string or buffer
[12/Aug/2014 05:45:55] ERROR [django.request:224] Internal Server Error: /reminder/add/
Traceback (most recent call last):
  File "/home/lenovo/Envs/contact/local/lib/python2.7/site-packages/django/core/handlers/base.py", line 112, in get_response
    response = wrapped_callback(request, *callback_args, **callback_kwargs)
  File "/home/lenovo/Envs/contact/local/lib/python2.7/site-packages/django/views/generic/base.py", line 69, in view
    return self.dispatch(request, *args, **kwargs)
  File "/home/lenovo/Envs/contact/local/lib/python2.7/site-packages/django/views/decorators/csrf.py", line 57, in wrapped_view
    return view_func(*args, **kwargs)
  File "/home/lenovo/Envs/contact/local/lib/python2.7/site-packages/rest_framework/views.py", line 400, in dispatch
    response = self.handle_exception(exc)
  File "/home/lenovo/Envs/contact/local/lib/python2.7/site-packages/rest_framework/views.py", line 397, in dispatch
    response = handler(request, *args, **kwargs)
  File "/home/lenovo/projects/contact/reminder/views.py", line 16, in post
    data = json.loads(request.POST)
  File "/usr/lib/python2.7/json/__init__.py", line 338, in loads
    return _default_decoder.decode(s)
  File "/usr/lib/python2.7/json/decoder.py", line 366, in decode
    obj, end = self.raw_decode(s, idx=_w(s, 0).end())
TypeError: expected string or buffer
[12/Aug/2014 05:46:36] ERROR [django.request:224] Internal Server Error: /reminder/add/
Traceback (most recent call last):
  File "/home/lenovo/Envs/contact/local/lib/python2.7/site-packages/django/core/handlers/base.py", line 112, in get_response
    response = wrapped_callback(request, *callback_args, **callback_kwargs)
  File "/home/lenovo/Envs/contact/local/lib/python2.7/site-packages/django/views/generic/base.py", line 69, in view
    return self.dispatch(request, *args, **kwargs)
  File "/home/lenovo/Envs/contact/local/lib/python2.7/site-packages/django/views/decorators/csrf.py", line 57, in wrapped_view
    return view_func(*args, **kwargs)
  File "/home/lenovo/Envs/contact/local/lib/python2.7/site-packages/rest_framework/views.py", line 400, in dispatch
    response = self.handle_exception(exc)
  File "/home/lenovo/Envs/contact/local/lib/python2.7/site-packages/rest_framework/views.py", line 397, in dispatch
    response = handler(request, *args, **kwargs)
  File "/home/lenovo/projects/contact/reminder/views.py", line 16, in post
    data = json.loads(request.POST)
  File "/usr/lib/python2.7/json/__init__.py", line 338, in loads
    return _default_decoder.decode(s)
  File "/usr/lib/python2.7/json/decoder.py", line 366, in decode
    obj, end = self.raw_decode(s, idx=_w(s, 0).end())
TypeError: expected string or buffer
[12/Aug/2014 05:47:16] ERROR [django.request:224] Internal Server Error: /reminder/add/
Traceback (most recent call last):
  File "/home/lenovo/Envs/contact/local/lib/python2.7/site-packages/django/core/handlers/base.py", line 112, in get_response
    response = wrapped_callback(request, *callback_args, **callback_kwargs)
  File "/home/lenovo/Envs/contact/local/lib/python2.7/site-packages/django/views/generic/base.py", line 69, in view
    return self.dispatch(request, *args, **kwargs)
  File "/home/lenovo/Envs/contact/local/lib/python2.7/site-packages/django/views/decorators/csrf.py", line 57, in wrapped_view
    return view_func(*args, **kwargs)
  File "/home/lenovo/Envs/contact/local/lib/python2.7/site-packages/rest_framework/views.py", line 400, in dispatch
    response = self.handle_exception(exc)
  File "/home/lenovo/Envs/contact/local/lib/python2.7/site-packages/rest_framework/views.py", line 397, in dispatch
    response = handler(request, *args, **kwargs)
  File "/home/lenovo/projects/contact/reminder/views.py", line 23, in post
    reminder.save()
  File "/home/lenovo/Envs/contact/local/lib/python2.7/site-packages/django/db/models/base.py", line 545, in save
    force_update=force_update, update_fields=update_fields)
  File "/home/lenovo/Envs/contact/local/lib/python2.7/site-packages/django/db/models/base.py", line 573, in save_base
    updated = self._save_table(raw, cls, force_insert, force_update, using, update_fields)
  File "/home/lenovo/Envs/contact/local/lib/python2.7/site-packages/django/db/models/base.py", line 654, in _save_table
    result = self._do_insert(cls._base_manager, using, fields, update_pk, raw)
  File "/home/lenovo/Envs/contact/local/lib/python2.7/site-packages/django/db/models/base.py", line 687, in _do_insert
    using=using, raw=raw)
  File "/home/lenovo/Envs/contact/local/lib/python2.7/site-packages/django/db/models/manager.py", line 232, in _insert
    return insert_query(self.model, objs, fields, **kwargs)
  File "/home/lenovo/Envs/contact/local/lib/python2.7/site-packages/django/db/models/query.py", line 1514, in insert_query
    return query.get_compiler(using=using).execute_sql(return_id)
  File "/home/lenovo/Envs/contact/local/lib/python2.7/site-packages/django/db/models/sql/compiler.py", line 903, in execute_sql
    cursor.execute(sql, params)
  File "/home/lenovo/Envs/contact/local/lib/python2.7/site-packages/django/db/backends/util.py", line 69, in execute
    return super(CursorDebugWrapper, self).execute(sql, params)
  File "/home/lenovo/Envs/contact/local/lib/python2.7/site-packages/django/db/backends/util.py", line 53, in execute
    return self.cursor.execute(sql, params)
  File "/home/lenovo/Envs/contact/local/lib/python2.7/site-packages/django/db/utils.py", line 99, in __exit__
    six.reraise(dj_exc_type, dj_exc_value, traceback)
  File "/home/lenovo/Envs/contact/local/lib/python2.7/site-packages/django/db/backends/util.py", line 53, in execute
    return self.cursor.execute(sql, params)
ProgrammingError: relation "reminder_reminder" does not exist
LINE 1: INSERT INTO "reminder_reminder" ("created", "modified", "con...
                    ^

[12/Aug/2014 05:48:20] ERROR [django.request:224] Internal Server Error: /reminder/add/
Traceback (most recent call last):
  File "/home/lenovo/Envs/contact/local/lib/python2.7/site-packages/django/core/handlers/base.py", line 112, in get_response
    response = wrapped_callback(request, *callback_args, **callback_kwargs)
  File "/home/lenovo/Envs/contact/local/lib/python2.7/site-packages/django/views/generic/base.py", line 69, in view
    return self.dispatch(request, *args, **kwargs)
  File "/home/lenovo/Envs/contact/local/lib/python2.7/site-packages/django/views/decorators/csrf.py", line 57, in wrapped_view
    return view_func(*args, **kwargs)
  File "/home/lenovo/Envs/contact/local/lib/python2.7/site-packages/rest_framework/views.py", line 400, in dispatch
    response = self.handle_exception(exc)
  File "/home/lenovo/Envs/contact/local/lib/python2.7/site-packages/rest_framework/views.py", line 397, in dispatch
    response = handler(request, *args, **kwargs)
  File "/home/lenovo/projects/contact/reminder/views.py", line 23, in post
    reminder.save()
  File "/home/lenovo/Envs/contact/local/lib/python2.7/site-packages/django/db/models/base.py", line 545, in save
    force_update=force_update, update_fields=update_fields)
  File "/home/lenovo/Envs/contact/local/lib/python2.7/site-packages/django/db/models/base.py", line 573, in save_base
    updated = self._save_table(raw, cls, force_insert, force_update, using, update_fields)
  File "/home/lenovo/Envs/contact/local/lib/python2.7/site-packages/django/db/models/base.py", line 654, in _save_table
    result = self._do_insert(cls._base_manager, using, fields, update_pk, raw)
  File "/home/lenovo/Envs/contact/local/lib/python2.7/site-packages/django/db/models/base.py", line 687, in _do_insert
    using=using, raw=raw)
  File "/home/lenovo/Envs/contact/local/lib/python2.7/site-packages/django/db/models/manager.py", line 232, in _insert
    return insert_query(self.model, objs, fields, **kwargs)
  File "/home/lenovo/Envs/contact/local/lib/python2.7/site-packages/django/db/models/query.py", line 1514, in insert_query
    return query.get_compiler(using=using).execute_sql(return_id)
  File "/home/lenovo/Envs/contact/local/lib/python2.7/site-packages/django/db/models/sql/compiler.py", line 903, in execute_sql
    cursor.execute(sql, params)
  File "/home/lenovo/Envs/contact/local/lib/python2.7/site-packages/django/db/backends/util.py", line 69, in execute
    return super(CursorDebugWrapper, self).execute(sql, params)
  File "/home/lenovo/Envs/contact/local/lib/python2.7/site-packages/django/db/backends/util.py", line 53, in execute
    return self.cursor.execute(sql, params)
  File "/home/lenovo/Envs/contact/local/lib/python2.7/site-packages/django/db/utils.py", line 99, in __exit__
    six.reraise(dj_exc_type, dj_exc_value, traceback)
  File "/home/lenovo/Envs/contact/local/lib/python2.7/site-packages/django/db/backends/util.py", line 53, in execute
    return self.cursor.execute(sql, params)
IntegrityError: null value in column "mail_id" violates not-null constraint
DETAIL:  Failing row contains (1, 2014-08-12 05:48:20.919068+00, 2014-08-12 05:48:20.919114+00, 23, 2014-08-05 18:30:00+00, jkjkj, 0, null).

[12/Aug/2014 05:51:45] ERROR [django.request:224] Internal Server Error: /reminder/add/
Traceback (most recent call last):
  File "/home/lenovo/Envs/contact/local/lib/python2.7/site-packages/django/core/handlers/base.py", line 112, in get_response
    response = wrapped_callback(request, *callback_args, **callback_kwargs)
  File "/home/lenovo/Envs/contact/local/lib/python2.7/site-packages/django/views/generic/base.py", line 69, in view
    return self.dispatch(request, *args, **kwargs)
  File "/home/lenovo/Envs/contact/local/lib/python2.7/site-packages/django/views/decorators/csrf.py", line 57, in wrapped_view
    return view_func(*args, **kwargs)
  File "/home/lenovo/Envs/contact/local/lib/python2.7/site-packages/rest_framework/views.py", line 400, in dispatch
    response = self.handle_exception(exc)
  File "/home/lenovo/Envs/contact/local/lib/python2.7/site-packages/rest_framework/views.py", line 397, in dispatch
    response = handler(request, *args, **kwargs)
  File "/home/lenovo/projects/contact/reminder/views.py", line 24, in post
    reminder.save()
  File "/home/lenovo/Envs/contact/local/lib/python2.7/site-packages/django/db/models/base.py", line 545, in save
    force_update=force_update, update_fields=update_fields)
  File "/home/lenovo/Envs/contact/local/lib/python2.7/site-packages/django/db/models/base.py", line 573, in save_base
    updated = self._save_table(raw, cls, force_insert, force_update, using, update_fields)
  File "/home/lenovo/Envs/contact/local/lib/python2.7/site-packages/django/db/models/base.py", line 654, in _save_table
    result = self._do_insert(cls._base_manager, using, fields, update_pk, raw)
  File "/home/lenovo/Envs/contact/local/lib/python2.7/site-packages/django/db/models/base.py", line 687, in _do_insert
    using=using, raw=raw)
  File "/home/lenovo/Envs/contact/local/lib/python2.7/site-packages/django/db/models/manager.py", line 232, in _insert
    return insert_query(self.model, objs, fields, **kwargs)
  File "/home/lenovo/Envs/contact/local/lib/python2.7/site-packages/django/db/models/query.py", line 1514, in insert_query
    return query.get_compiler(using=using).execute_sql(return_id)
  File "/home/lenovo/Envs/contact/local/lib/python2.7/site-packages/django/db/models/sql/compiler.py", line 903, in execute_sql
    cursor.execute(sql, params)
  File "/home/lenovo/Envs/contact/local/lib/python2.7/site-packages/django/db/backends/util.py", line 69, in execute
    return super(CursorDebugWrapper, self).execute(sql, params)
  File "/home/lenovo/Envs/contact/local/lib/python2.7/site-packages/django/db/backends/util.py", line 53, in execute
    return self.cursor.execute(sql, params)
  File "/home/lenovo/Envs/contact/local/lib/python2.7/site-packages/django/db/utils.py", line 99, in __exit__
    six.reraise(dj_exc_type, dj_exc_value, traceback)
  File "/home/lenovo/Envs/contact/local/lib/python2.7/site-packages/django/db/backends/util.py", line 53, in execute
    return self.cursor.execute(sql, params)
IntegrityError: null value in column "mail_id" violates not-null constraint
DETAIL:  Failing row contains (2, 2014-08-12 05:51:45.069927+00, 2014-08-12 05:51:45.069954+00, 23, 2014-08-05 00:00:00+00, jkjkj, 0, null).

[12/Aug/2014 06:04:26] ERROR [django.request:224] Internal Server Error: /contact/reminders/2/
Traceback (most recent call last):
  File "/home/lenovo/Envs/contact/local/lib/python2.7/site-packages/django/core/handlers/base.py", line 112, in get_response
    response = wrapped_callback(request, *callback_args, **callback_kwargs)
  File "/home/lenovo/Envs/contact/local/lib/python2.7/site-packages/django/views/generic/base.py", line 69, in view
    return self.dispatch(request, *args, **kwargs)
  File "/home/lenovo/Envs/contact/local/lib/python2.7/site-packages/django/views/decorators/csrf.py", line 57, in wrapped_view
    return view_func(*args, **kwargs)
  File "/home/lenovo/Envs/contact/local/lib/python2.7/site-packages/rest_framework/views.py", line 400, in dispatch
    response = self.handle_exception(exc)
  File "/home/lenovo/Envs/contact/local/lib/python2.7/site-packages/rest_framework/views.py", line 397, in dispatch
    response = handler(request, *args, **kwargs)
  File "/home/lenovo/projects/contact/reminder/views.py", line 34, in get
    slz =ReminderSerializer(reminders, many=True)
  File "/home/lenovo/Envs/contact/local/lib/python2.7/site-packages/rest_framework/serializers.py", line 207, in __init__
    raise ValueError('instance should be a queryset or other iterable with many=True')
ValueError: instance should be a queryset or other iterable with many=True
[12/Aug/2014 06:04:33] ERROR [django.request:224] Internal Server Error: /contact/reminders/2/
Traceback (most recent call last):
  File "/home/lenovo/Envs/contact/local/lib/python2.7/site-packages/django/core/handlers/base.py", line 112, in get_response
    response = wrapped_callback(request, *callback_args, **callback_kwargs)
  File "/home/lenovo/Envs/contact/local/lib/python2.7/site-packages/django/views/generic/base.py", line 69, in view
    return self.dispatch(request, *args, **kwargs)
  File "/home/lenovo/Envs/contact/local/lib/python2.7/site-packages/django/views/decorators/csrf.py", line 57, in wrapped_view
    return view_func(*args, **kwargs)
  File "/home/lenovo/Envs/contact/local/lib/python2.7/site-packages/rest_framework/views.py", line 400, in dispatch
    response = self.handle_exception(exc)
  File "/home/lenovo/Envs/contact/local/lib/python2.7/site-packages/rest_framework/views.py", line 397, in dispatch
    response = handler(request, *args, **kwargs)
  File "/home/lenovo/projects/contact/reminder/views.py", line 34, in get
    slz =ReminderSerializer(reminders, many=True)
  File "/home/lenovo/Envs/contact/local/lib/python2.7/site-packages/rest_framework/serializers.py", line 207, in __init__
    raise ValueError('instance should be a queryset or other iterable with many=True')
ValueError: instance should be a queryset or other iterable with many=True
[12/Aug/2014 06:05:28] ERROR [django.request:224] Internal Server Error: /contact/reminders/2/
Traceback (most recent call last):
  File "/home/lenovo/Envs/contact/local/lib/python2.7/site-packages/django/core/handlers/base.py", line 137, in get_response
    response = response.render()
  File "/home/lenovo/Envs/contact/local/lib/python2.7/site-packages/django/template/response.py", line 105, in render
    self.content = self.rendered_content
  File "/home/lenovo/Envs/contact/local/lib/python2.7/site-packages/rest_framework/response.py", line 59, in rendered_content
    ret = renderer.render(self.data, media_type, context)
  File "/home/lenovo/Envs/contact/local/lib/python2.7/site-packages/rest_framework/renderers.py", line 600, in render
    template = loader.get_template(self.template)
  File "/home/lenovo/Envs/contact/local/lib/python2.7/site-packages/django/template/loader.py", line 138, in get_template
    template, origin = find_template(template_name)
  File "/home/lenovo/Envs/contact/local/lib/python2.7/site-packages/django/template/loader.py", line 131, in find_template
    raise TemplateDoesNotExist(name)
TemplateDoesNotExist: rest_framework/api.html
[12/Aug/2014 07:02:26] ERROR [django.request:224] Internal Server Error: /
Traceback (most recent call last):
  File "/home/lenovo/Envs/contact/local/lib/python2.7/site-packages/django/core/handlers/base.py", line 112, in get_response
    response = wrapped_callback(request, *callback_args, **callback_kwargs)
  File "/home/lenovo/Envs/contact/local/lib/python2.7/site-packages/django/contrib/auth/decorators.py", line 22, in _wrapped_view
    return view_func(request, *args, **kwargs)
  File "/home/lenovo/projects/contact/manager/views.py", line 20, in home
    send_mail('Subject here', 'Here is the message.', 'arun@rawdatatech.com',['arunghosh@gmail.com'], fail_silently=False)
  File "/home/lenovo/Envs/contact/local/lib/python2.7/site-packages/django/core/mail/__init__.py", line 50, in send_mail
    connection=connection).send()
  File "/home/lenovo/Envs/contact/local/lib/python2.7/site-packages/django/core/mail/message.py", line 274, in send
    return self.get_connection(fail_silently).send_messages([self])
  File "/home/lenovo/Envs/contact/local/lib/python2.7/site-packages/django/core/mail/backends/smtp.py", line 87, in send_messages
    new_conn_created = self.open()
  File "/home/lenovo/Envs/contact/local/lib/python2.7/site-packages/django/core/mail/backends/smtp.py", line 48, in open
    local_hostname=DNS_NAME.get_fqdn())
  File "/usr/lib/python2.7/smtplib.py", line 251, in __init__
    (code, msg) = self.connect(host, port)
  File "/usr/lib/python2.7/smtplib.py", line 311, in connect
    self.sock = self._get_socket(host, port, self.timeout)
  File "/usr/lib/python2.7/smtplib.py", line 286, in _get_socket
    return socket.create_connection((host, port), timeout)
  File "/usr/lib/python2.7/socket.py", line 571, in create_connection
    raise err
error: [Errno 111] Connection refused
[12/Aug/2014 08:45:35] ERROR [django.request:224] Internal Server Error: /inbox/refresh/
Traceback (most recent call last):
  File "/home/lenovo/Envs/contact/local/lib/python2.7/site-packages/django/core/handlers/base.py", line 112, in get_response
    response = wrapped_callback(request, *callback_args, **callback_kwargs)
  File "/home/lenovo/Envs/contact/local/lib/python2.7/site-packages/django/views/generic/base.py", line 69, in view
    return self.dispatch(request, *args, **kwargs)
  File "/home/lenovo/Envs/contact/local/lib/python2.7/site-packages/django/views/decorators/csrf.py", line 57, in wrapped_view
    return view_func(*args, **kwargs)
  File "/home/lenovo/Envs/contact/local/lib/python2.7/site-packages/rest_framework/views.py", line 400, in dispatch
    response = self.handle_exception(exc)
  File "/home/lenovo/Envs/contact/local/lib/python2.7/site-packages/rest_framework/views.py", line 397, in dispatch
    response = handler(request, *args, **kwargs)
  File "/home/lenovo/Envs/contact/local/lib/python2.7/site-packages/django/db/transaction.py", line 371, in inner
    return func(*args, **kwargs)
  File "/home/lenovo/projects/contact/gmail/views.py", line 35, in get
    in_import = InboxImport(user)
  File "/home/lenovo/projects/contact/gmail/parsers.py", line 17, in __init__
    self.service = Auth.get_gmail_srv(user)
  File "/home/lenovo/projects/contact/gmail/__init__.py", line 43, in get_gmail_srv
    return build('gmail', 'v1', http=http)
  File "/home/lenovo/Envs/contact/local/lib/python2.7/site-packages/oauth2client/util.py", line 132, in positional_wrapper
    return wrapped(*args, **kwargs)
  File "/home/lenovo/Envs/contact/local/lib/python2.7/site-packages/apiclient/discovery.py", line 192, in build
    resp, content = http.request(requested_url)
  File "/home/lenovo/Envs/contact/local/lib/python2.7/site-packages/oauth2client/util.py", line 132, in positional_wrapper
    return wrapped(*args, **kwargs)
  File "/home/lenovo/Envs/contact/local/lib/python2.7/site-packages/oauth2client/client.py", line 490, in new_request
    redirections, connection_type)
  File "/home/lenovo/Envs/contact/local/lib/python2.7/site-packages/httplib2/__init__.py", line 1593, in request
    (response, content) = self._request(conn, authority, uri, request_uri, method, body, headers, redirections, cachekey)
  File "/home/lenovo/Envs/contact/local/lib/python2.7/site-packages/httplib2/__init__.py", line 1335, in _request
    (response, content) = self._conn_request(conn, request_uri, method, body, headers)
  File "/home/lenovo/Envs/contact/local/lib/python2.7/site-packages/httplib2/__init__.py", line 1257, in _conn_request
    conn.connect()
  File "/home/lenovo/Envs/contact/local/lib/python2.7/site-packages/httplib2/__init__.py", line 1060, in connect
    raise socket.error, msg
error: [Errno 111] Connection refused
[12/Aug/2014 09:43:39] ERROR [django.request:224] Internal Server Error: /inbox/refresh/
Traceback (most recent call last):
  File "/home/lenovo/Envs/contact/local/lib/python2.7/site-packages/django/core/handlers/base.py", line 112, in get_response
    response = wrapped_callback(request, *callback_args, **callback_kwargs)
  File "/home/lenovo/Envs/contact/local/lib/python2.7/site-packages/django/views/generic/base.py", line 69, in view
    return self.dispatch(request, *args, **kwargs)
  File "/home/lenovo/Envs/contact/local/lib/python2.7/site-packages/django/views/decorators/csrf.py", line 57, in wrapped_view
    return view_func(*args, **kwargs)
  File "/home/lenovo/Envs/contact/local/lib/python2.7/site-packages/rest_framework/views.py", line 400, in dispatch
    response = self.handle_exception(exc)
  File "/home/lenovo/Envs/contact/local/lib/python2.7/site-packages/rest_framework/views.py", line 397, in dispatch
    response = handler(request, *args, **kwargs)
  File "/home/lenovo/Envs/contact/local/lib/python2.7/site-packages/django/db/transaction.py", line 371, in inner
    return func(*args, **kwargs)
  File "/home/lenovo/projects/contact/gmail/views.py", line 35, in get
    in_import = InboxImport(user)
  File "/home/lenovo/projects/contact/gmail/parsers.py", line 17, in __init__
    self.service = Auth.get_gmail_srv(user)
  File "/home/lenovo/projects/contact/gmail/__init__.py", line 43, in get_gmail_srv
    return build('gmail', 'v1', http=http)
  File "/home/lenovo/Envs/contact/local/lib/python2.7/site-packages/oauth2client/util.py", line 132, in positional_wrapper
    return wrapped(*args, **kwargs)
  File "/home/lenovo/Envs/contact/local/lib/python2.7/site-packages/apiclient/discovery.py", line 192, in build
    resp, content = http.request(requested_url)
  File "/home/lenovo/Envs/contact/local/lib/python2.7/site-packages/oauth2client/util.py", line 132, in positional_wrapper
    return wrapped(*args, **kwargs)
  File "/home/lenovo/Envs/contact/local/lib/python2.7/site-packages/oauth2client/client.py", line 490, in new_request
    redirections, connection_type)
  File "/home/lenovo/Envs/contact/local/lib/python2.7/site-packages/httplib2/__init__.py", line 1593, in request
    (response, content) = self._request(conn, authority, uri, request_uri, method, body, headers, redirections, cachekey)
  File "/home/lenovo/Envs/contact/local/lib/python2.7/site-packages/httplib2/__init__.py", line 1335, in _request
    (response, content) = self._conn_request(conn, request_uri, method, body, headers)
  File "/home/lenovo/Envs/contact/local/lib/python2.7/site-packages/httplib2/__init__.py", line 1257, in _conn_request
    conn.connect()
  File "/home/lenovo/Envs/contact/local/lib/python2.7/site-packages/httplib2/__init__.py", line 1060, in connect
    raise socket.error, msg
error: [Errno 111] Connection refused
[12/Aug/2014 09:59:14] ERROR [django.request:224] Internal Server Error: /inbox/refresh/
Traceback (most recent call last):
  File "/home/lenovo/Envs/contact/local/lib/python2.7/site-packages/django/core/handlers/base.py", line 112, in get_response
    response = wrapped_callback(request, *callback_args, **callback_kwargs)
  File "/home/lenovo/Envs/contact/local/lib/python2.7/site-packages/django/views/generic/base.py", line 69, in view
    return self.dispatch(request, *args, **kwargs)
  File "/home/lenovo/Envs/contact/local/lib/python2.7/site-packages/django/views/decorators/csrf.py", line 57, in wrapped_view
    return view_func(*args, **kwargs)
  File "/home/lenovo/Envs/contact/local/lib/python2.7/site-packages/rest_framework/views.py", line 400, in dispatch
    response = self.handle_exception(exc)
  File "/home/lenovo/Envs/contact/local/lib/python2.7/site-packages/rest_framework/views.py", line 397, in dispatch
    response = handler(request, *args, **kwargs)
  File "/home/lenovo/Envs/contact/local/lib/python2.7/site-packages/django/db/transaction.py", line 371, in inner
    return func(*args, **kwargs)
  File "/home/lenovo/projects/contact/gmail/views.py", line 35, in get
    in_import = InboxImport(user)
  File "/home/lenovo/projects/contact/gmail/parsers.py", line 17, in __init__
    self.service = Auth.get_gmail_srv(user)
  File "/home/lenovo/projects/contact/gmail/__init__.py", line 43, in get_gmail_srv
    return build('gmail', 'v1', http=http)
  File "/home/lenovo/Envs/contact/local/lib/python2.7/site-packages/oauth2client/util.py", line 132, in positional_wrapper
    return wrapped(*args, **kwargs)
  File "/home/lenovo/Envs/contact/local/lib/python2.7/site-packages/apiclient/discovery.py", line 192, in build
    resp, content = http.request(requested_url)
  File "/home/lenovo/Envs/contact/local/lib/python2.7/site-packages/oauth2client/util.py", line 132, in positional_wrapper
    return wrapped(*args, **kwargs)
  File "/home/lenovo/Envs/contact/local/lib/python2.7/site-packages/oauth2client/client.py", line 490, in new_request
    redirections, connection_type)
  File "/home/lenovo/Envs/contact/local/lib/python2.7/site-packages/httplib2/__init__.py", line 1593, in request
    (response, content) = self._request(conn, authority, uri, request_uri, method, body, headers, redirections, cachekey)
  File "/home/lenovo/Envs/contact/local/lib/python2.7/site-packages/httplib2/__init__.py", line 1335, in _request
    (response, content) = self._conn_request(conn, request_uri, method, body, headers)
  File "/home/lenovo/Envs/contact/local/lib/python2.7/site-packages/httplib2/__init__.py", line 1257, in _conn_request
    conn.connect()
  File "/home/lenovo/Envs/contact/local/lib/python2.7/site-packages/httplib2/__init__.py", line 1060, in connect
    raise socket.error, msg
error: [Errno 111] Connection refused
[12/Aug/2014 09:59:47] ERROR [django.request:224] Internal Server Error: /reminder/delete/
Traceback (most recent call last):
  File "/home/lenovo/Envs/contact/local/lib/python2.7/site-packages/django/core/handlers/base.py", line 112, in get_response
    response = wrapped_callback(request, *callback_args, **callback_kwargs)
  File "/home/lenovo/Envs/contact/local/lib/python2.7/site-packages/django/views/generic/base.py", line 69, in view
    return self.dispatch(request, *args, **kwargs)
  File "/home/lenovo/Envs/contact/local/lib/python2.7/site-packages/django/views/decorators/csrf.py", line 57, in wrapped_view
    return view_func(*args, **kwargs)
  File "/home/lenovo/Envs/contact/local/lib/python2.7/site-packages/rest_framework/views.py", line 400, in dispatch
    response = self.handle_exception(exc)
  File "/home/lenovo/Envs/contact/local/lib/python2.7/site-packages/rest_framework/views.py", line 397, in dispatch
    response = handler(request, *args, **kwargs)
  File "/home/lenovo/projects/contact/reminder/views.py", line 36, in post
    reminder = Reminder.objects.get(pk=data['id'])
KeyError: 'id'
[12/Aug/2014 09:59:57] ERROR [django.request:224] Internal Server Error: /inbox/refresh/
Traceback (most recent call last):
  File "/home/lenovo/Envs/contact/local/lib/python2.7/site-packages/django/core/handlers/base.py", line 112, in get_response
    response = wrapped_callback(request, *callback_args, **callback_kwargs)
  File "/home/lenovo/Envs/contact/local/lib/python2.7/site-packages/django/views/generic/base.py", line 69, in view
    return self.dispatch(request, *args, **kwargs)
  File "/home/lenovo/Envs/contact/local/lib/python2.7/site-packages/django/views/decorators/csrf.py", line 57, in wrapped_view
    return view_func(*args, **kwargs)
  File "/home/lenovo/Envs/contact/local/lib/python2.7/site-packages/rest_framework/views.py", line 400, in dispatch
    response = self.handle_exception(exc)
  File "/home/lenovo/Envs/contact/local/lib/python2.7/site-packages/rest_framework/views.py", line 397, in dispatch
    response = handler(request, *args, **kwargs)
  File "/home/lenovo/Envs/contact/local/lib/python2.7/site-packages/django/db/transaction.py", line 371, in inner
    return func(*args, **kwargs)
  File "/home/lenovo/projects/contact/gmail/views.py", line 35, in get
    in_import = InboxImport(user)
  File "/home/lenovo/projects/contact/gmail/parsers.py", line 17, in __init__
    self.service = Auth.get_gmail_srv(user)
  File "/home/lenovo/projects/contact/gmail/__init__.py", line 43, in get_gmail_srv
    return build('gmail', 'v1', http=http)
  File "/home/lenovo/Envs/contact/local/lib/python2.7/site-packages/oauth2client/util.py", line 132, in positional_wrapper
    return wrapped(*args, **kwargs)
  File "/home/lenovo/Envs/contact/local/lib/python2.7/site-packages/apiclient/discovery.py", line 192, in build
    resp, content = http.request(requested_url)
  File "/home/lenovo/Envs/contact/local/lib/python2.7/site-packages/oauth2client/util.py", line 132, in positional_wrapper
    return wrapped(*args, **kwargs)
  File "/home/lenovo/Envs/contact/local/lib/python2.7/site-packages/oauth2client/client.py", line 490, in new_request
    redirections, connection_type)
  File "/home/lenovo/Envs/contact/local/lib/python2.7/site-packages/httplib2/__init__.py", line 1593, in request
    (response, content) = self._request(conn, authority, uri, request_uri, method, body, headers, redirections, cachekey)
  File "/home/lenovo/Envs/contact/local/lib/python2.7/site-packages/httplib2/__init__.py", line 1335, in _request
    (response, content) = self._conn_request(conn, request_uri, method, body, headers)
  File "/home/lenovo/Envs/contact/local/lib/python2.7/site-packages/httplib2/__init__.py", line 1257, in _conn_request
    conn.connect()
  File "/home/lenovo/Envs/contact/local/lib/python2.7/site-packages/httplib2/__init__.py", line 1060, in connect
    raise socket.error, msg
error: [Errno 111] Connection refused
[12/Aug/2014 09:59:57] ERROR [django.request:224] Internal Server Error: /reminder/delete/
Traceback (most recent call last):
  File "/home/lenovo/Envs/contact/local/lib/python2.7/site-packages/django/core/handlers/base.py", line 112, in get_response
    response = wrapped_callback(request, *callback_args, **callback_kwargs)
  File "/home/lenovo/Envs/contact/local/lib/python2.7/site-packages/django/views/generic/base.py", line 69, in view
    return self.dispatch(request, *args, **kwargs)
  File "/home/lenovo/Envs/contact/local/lib/python2.7/site-packages/django/views/decorators/csrf.py", line 57, in wrapped_view
    return view_func(*args, **kwargs)
  File "/home/lenovo/Envs/contact/local/lib/python2.7/site-packages/rest_framework/views.py", line 400, in dispatch
    response = self.handle_exception(exc)
  File "/home/lenovo/Envs/contact/local/lib/python2.7/site-packages/rest_framework/views.py", line 397, in dispatch
    response = handler(request, *args, **kwargs)
  File "/home/lenovo/projects/contact/reminder/views.py", line 36, in post
    reminder = Reminder.objects.get(pk=data['id'])
KeyError: 'id'
[12/Aug/2014 09:59:58] ERROR [django.request:224] Internal Server Error: /reminder/delete/
Traceback (most recent call last):
  File "/home/lenovo/Envs/contact/local/lib/python2.7/site-packages/django/core/handlers/base.py", line 112, in get_response
    response = wrapped_callback(request, *callback_args, **callback_kwargs)
  File "/home/lenovo/Envs/contact/local/lib/python2.7/site-packages/django/views/generic/base.py", line 69, in view
    return self.dispatch(request, *args, **kwargs)
  File "/home/lenovo/Envs/contact/local/lib/python2.7/site-packages/django/views/decorators/csrf.py", line 57, in wrapped_view
    return view_func(*args, **kwargs)
  File "/home/lenovo/Envs/contact/local/lib/python2.7/site-packages/rest_framework/views.py", line 400, in dispatch
    response = self.handle_exception(exc)
  File "/home/lenovo/Envs/contact/local/lib/python2.7/site-packages/rest_framework/views.py", line 397, in dispatch
    response = handler(request, *args, **kwargs)
  File "/home/lenovo/projects/contact/reminder/views.py", line 36, in post
    reminder = Reminder.objects.get(pk=data['id'])
KeyError: 'id'
[12/Aug/2014 09:59:58] ERROR [django.request:224] Internal Server Error: /reminder/delete/
Traceback (most recent call last):
  File "/home/lenovo/Envs/contact/local/lib/python2.7/site-packages/django/core/handlers/base.py", line 112, in get_response
    response = wrapped_callback(request, *callback_args, **callback_kwargs)
  File "/home/lenovo/Envs/contact/local/lib/python2.7/site-packages/django/views/generic/base.py", line 69, in view
    return self.dispatch(request, *args, **kwargs)
  File "/home/lenovo/Envs/contact/local/lib/python2.7/site-packages/django/views/decorators/csrf.py", line 57, in wrapped_view
    return view_func(*args, **kwargs)
  File "/home/lenovo/Envs/contact/local/lib/python2.7/site-packages/rest_framework/views.py", line 400, in dispatch
    response = self.handle_exception(exc)
  File "/home/lenovo/Envs/contact/local/lib/python2.7/site-packages/rest_framework/views.py", line 397, in dispatch
    response = handler(request, *args, **kwargs)
  File "/home/lenovo/projects/contact/reminder/views.py", line 36, in post
    reminder = Reminder.objects.get(pk=data['id'])
KeyError: 'id'
[12/Aug/2014 10:01:23] ERROR [django.request:224] Internal Server Error: /reminder/delete/
Traceback (most recent call last):
  File "/home/lenovo/Envs/contact/local/lib/python2.7/site-packages/django/core/handlers/base.py", line 112, in get_response
    response = wrapped_callback(request, *callback_args, **callback_kwargs)
  File "/home/lenovo/Envs/contact/local/lib/python2.7/site-packages/django/views/generic/base.py", line 69, in view
    return self.dispatch(request, *args, **kwargs)
  File "/home/lenovo/Envs/contact/local/lib/python2.7/site-packages/django/views/decorators/csrf.py", line 57, in wrapped_view
    return view_func(*args, **kwargs)
  File "/home/lenovo/Envs/contact/local/lib/python2.7/site-packages/rest_framework/views.py", line 400, in dispatch
    response = self.handle_exception(exc)
  File "/home/lenovo/Envs/contact/local/lib/python2.7/site-packages/rest_framework/views.py", line 397, in dispatch
    response = handler(request, *args, **kwargs)
  File "/home/lenovo/projects/contact/reminder/views.py", line 38, in post
    reminder.save()
  File "/home/lenovo/Envs/contact/local/lib/python2.7/site-packages/django/db/models/base.py", line 545, in save
    force_update=force_update, update_fields=update_fields)
  File "/home/lenovo/Envs/contact/local/lib/python2.7/site-packages/django/db/models/base.py", line 573, in save_base
    updated = self._save_table(raw, cls, force_insert, force_update, using, update_fields)
  File "/home/lenovo/Envs/contact/local/lib/python2.7/site-packages/django/db/models/base.py", line 635, in _save_table
    forced_update)
  File "/home/lenovo/Envs/contact/local/lib/python2.7/site-packages/django/db/models/base.py", line 679, in _do_update
    return filtered._update(values) > 0
  File "/home/lenovo/Envs/contact/local/lib/python2.7/site-packages/django/db/models/query.py", line 510, in _update
    return query.get_compiler(self.db).execute_sql(None)
  File "/home/lenovo/Envs/contact/local/lib/python2.7/site-packages/django/db/models/sql/compiler.py", line 980, in execute_sql
    cursor = super(SQLUpdateCompiler, self).execute_sql(result_type)
  File "/home/lenovo/Envs/contact/local/lib/python2.7/site-packages/django/db/models/sql/compiler.py", line 776, in execute_sql
    sql, params = self.as_sql()
  File "/home/lenovo/Envs/contact/local/lib/python2.7/site-packages/django/db/models/sql/compiler.py", line 945, in as_sql
    val = field.get_db_prep_save(val, connection=self.connection)
  File "/home/lenovo/Envs/contact/local/lib/python2.7/site-packages/django/db/models/fields/__init__.py", line 350, in get_db_prep_save
    prepared=False)
  File "/home/lenovo/Envs/contact/local/lib/python2.7/site-packages/django/db/models/fields/__init__.py", line 342, in get_db_prep_value
    value = self.get_prep_value(value)
  File "/home/lenovo/Envs/contact/local/lib/python2.7/site-packages/django/db/models/fields/__init__.py", line 1079, in get_prep_value
    return int(value)
TypeError: int() argument must be a string or a number, not 'tuple'
[12/Aug/2014 10:01:29] ERROR [django.request:224] Internal Server Error: /reminder/delete/
Traceback (most recent call last):
  File "/home/lenovo/Envs/contact/local/lib/python2.7/site-packages/django/core/handlers/base.py", line 112, in get_response
    response = wrapped_callback(request, *callback_args, **callback_kwargs)
  File "/home/lenovo/Envs/contact/local/lib/python2.7/site-packages/django/views/generic/base.py", line 69, in view
    return self.dispatch(request, *args, **kwargs)
  File "/home/lenovo/Envs/contact/local/lib/python2.7/site-packages/django/views/decorators/csrf.py", line 57, in wrapped_view
    return view_func(*args, **kwargs)
  File "/home/lenovo/Envs/contact/local/lib/python2.7/site-packages/rest_framework/views.py", line 400, in dispatch
    response = self.handle_exception(exc)
  File "/home/lenovo/Envs/contact/local/lib/python2.7/site-packages/rest_framework/views.py", line 397, in dispatch
    response = handler(request, *args, **kwargs)
  File "/home/lenovo/projects/contact/reminder/views.py", line 38, in post
    reminder.save()
  File "/home/lenovo/Envs/contact/local/lib/python2.7/site-packages/django/db/models/base.py", line 545, in save
    force_update=force_update, update_fields=update_fields)
  File "/home/lenovo/Envs/contact/local/lib/python2.7/site-packages/django/db/models/base.py", line 573, in save_base
    updated = self._save_table(raw, cls, force_insert, force_update, using, update_fields)
  File "/home/lenovo/Envs/contact/local/lib/python2.7/site-packages/django/db/models/base.py", line 635, in _save_table
    forced_update)
  File "/home/lenovo/Envs/contact/local/lib/python2.7/site-packages/django/db/models/base.py", line 679, in _do_update
    return filtered._update(values) > 0
  File "/home/lenovo/Envs/contact/local/lib/python2.7/site-packages/django/db/models/query.py", line 510, in _update
    return query.get_compiler(self.db).execute_sql(None)
  File "/home/lenovo/Envs/contact/local/lib/python2.7/site-packages/django/db/models/sql/compiler.py", line 980, in execute_sql
    cursor = super(SQLUpdateCompiler, self).execute_sql(result_type)
  File "/home/lenovo/Envs/contact/local/lib/python2.7/site-packages/django/db/models/sql/compiler.py", line 776, in execute_sql
    sql, params = self.as_sql()
  File "/home/lenovo/Envs/contact/local/lib/python2.7/site-packages/django/db/models/sql/compiler.py", line 945, in as_sql
    val = field.get_db_prep_save(val, connection=self.connection)
  File "/home/lenovo/Envs/contact/local/lib/python2.7/site-packages/django/db/models/fields/__init__.py", line 350, in get_db_prep_save
    prepared=False)
  File "/home/lenovo/Envs/contact/local/lib/python2.7/site-packages/django/db/models/fields/__init__.py", line 342, in get_db_prep_value
    value = self.get_prep_value(value)
  File "/home/lenovo/Envs/contact/local/lib/python2.7/site-packages/django/db/models/fields/__init__.py", line 1079, in get_prep_value
    return int(value)
TypeError: int() argument must be a string or a number, not 'tuple'
[12/Aug/2014 10:01:35] ERROR [django.request:224] Internal Server Error: /inbox/refresh/
Traceback (most recent call last):
  File "/home/lenovo/Envs/contact/local/lib/python2.7/site-packages/django/core/handlers/base.py", line 112, in get_response
    response = wrapped_callback(request, *callback_args, **callback_kwargs)
  File "/home/lenovo/Envs/contact/local/lib/python2.7/site-packages/django/views/generic/base.py", line 69, in view
    return self.dispatch(request, *args, **kwargs)
  File "/home/lenovo/Envs/contact/local/lib/python2.7/site-packages/django/views/decorators/csrf.py", line 57, in wrapped_view
    return view_func(*args, **kwargs)
  File "/home/lenovo/Envs/contact/local/lib/python2.7/site-packages/rest_framework/views.py", line 400, in dispatch
    response = self.handle_exception(exc)
  File "/home/lenovo/Envs/contact/local/lib/python2.7/site-packages/rest_framework/views.py", line 397, in dispatch
    response = handler(request, *args, **kwargs)
  File "/home/lenovo/Envs/contact/local/lib/python2.7/site-packages/django/db/transaction.py", line 371, in inner
    return func(*args, **kwargs)
  File "/home/lenovo/projects/contact/gmail/views.py", line 35, in get
    in_import = InboxImport(user)
  File "/home/lenovo/projects/contact/gmail/parsers.py", line 17, in __init__
    self.service = Auth.get_gmail_srv(user)
  File "/home/lenovo/projects/contact/gmail/__init__.py", line 43, in get_gmail_srv
    return build('gmail', 'v1', http=http)
  File "/home/lenovo/Envs/contact/local/lib/python2.7/site-packages/oauth2client/util.py", line 132, in positional_wrapper
    return wrapped(*args, **kwargs)
  File "/home/lenovo/Envs/contact/local/lib/python2.7/site-packages/apiclient/discovery.py", line 192, in build
    resp, content = http.request(requested_url)
  File "/home/lenovo/Envs/contact/local/lib/python2.7/site-packages/oauth2client/util.py", line 132, in positional_wrapper
    return wrapped(*args, **kwargs)
  File "/home/lenovo/Envs/contact/local/lib/python2.7/site-packages/oauth2client/client.py", line 490, in new_request
    redirections, connection_type)
  File "/home/lenovo/Envs/contact/local/lib/python2.7/site-packages/httplib2/__init__.py", line 1593, in request
    (response, content) = self._request(conn, authority, uri, request_uri, method, body, headers, redirections, cachekey)
  File "/home/lenovo/Envs/contact/local/lib/python2.7/site-packages/httplib2/__init__.py", line 1335, in _request
    (response, content) = self._conn_request(conn, request_uri, method, body, headers)
  File "/home/lenovo/Envs/contact/local/lib/python2.7/site-packages/httplib2/__init__.py", line 1257, in _conn_request
    conn.connect()
  File "/home/lenovo/Envs/contact/local/lib/python2.7/site-packages/httplib2/__init__.py", line 1060, in connect
    raise socket.error, msg
error: [Errno 111] Connection refused
[12/Aug/2014 10:02:11] ERROR [django.request:224] Internal Server Error: /reminder/delete/
Traceback (most recent call last):
  File "/home/lenovo/Envs/contact/local/lib/python2.7/site-packages/django/core/handlers/base.py", line 112, in get_response
    response = wrapped_callback(request, *callback_args, **callback_kwargs)
  File "/home/lenovo/Envs/contact/local/lib/python2.7/site-packages/django/views/generic/base.py", line 69, in view
    return self.dispatch(request, *args, **kwargs)
  File "/home/lenovo/Envs/contact/local/lib/python2.7/site-packages/django/views/decorators/csrf.py", line 57, in wrapped_view
    return view_func(*args, **kwargs)
  File "/home/lenovo/Envs/contact/local/lib/python2.7/site-packages/rest_framework/views.py", line 400, in dispatch
    response = self.handle_exception(exc)
  File "/home/lenovo/Envs/contact/local/lib/python2.7/site-packages/rest_framework/views.py", line 397, in dispatch
    response = handler(request, *args, **kwargs)
  File "/home/lenovo/projects/contact/reminder/views.py", line 39, in post
    reminder.save()
  File "/home/lenovo/Envs/contact/local/lib/python2.7/site-packages/django/db/models/base.py", line 545, in save
    force_update=force_update, update_fields=update_fields)
  File "/home/lenovo/Envs/contact/local/lib/python2.7/site-packages/django/db/models/base.py", line 573, in save_base
    updated = self._save_table(raw, cls, force_insert, force_update, using, update_fields)
  File "/home/lenovo/Envs/contact/local/lib/python2.7/site-packages/django/db/models/base.py", line 635, in _save_table
    forced_update)
  File "/home/lenovo/Envs/contact/local/lib/python2.7/site-packages/django/db/models/base.py", line 679, in _do_update
    return filtered._update(values) > 0
  File "/home/lenovo/Envs/contact/local/lib/python2.7/site-packages/django/db/models/query.py", line 510, in _update
    return query.get_compiler(self.db).execute_sql(None)
  File "/home/lenovo/Envs/contact/local/lib/python2.7/site-packages/django/db/models/sql/compiler.py", line 980, in execute_sql
    cursor = super(SQLUpdateCompiler, self).execute_sql(result_type)
  File "/home/lenovo/Envs/contact/local/lib/python2.7/site-packages/django/db/models/sql/compiler.py", line 776, in execute_sql
    sql, params = self.as_sql()
  File "/home/lenovo/Envs/contact/local/lib/python2.7/site-packages/django/db/models/sql/compiler.py", line 945, in as_sql
    val = field.get_db_prep_save(val, connection=self.connection)
  File "/home/lenovo/Envs/contact/local/lib/python2.7/site-packages/django/db/models/fields/__init__.py", line 350, in get_db_prep_save
    prepared=False)
  File "/home/lenovo/Envs/contact/local/lib/python2.7/site-packages/django/db/models/fields/__init__.py", line 342, in get_db_prep_value
    value = self.get_prep_value(value)
  File "/home/lenovo/Envs/contact/local/lib/python2.7/site-packages/django/db/models/fields/__init__.py", line 1079, in get_prep_value
    return int(value)
TypeError: int() argument must be a string or a number, not 'tuple'
[12/Aug/2014 10:02:56] ERROR [django.request:224] Internal Server Error: /reminder/delete/
Traceback (most recent call last):
  File "/home/lenovo/Envs/contact/local/lib/python2.7/site-packages/django/core/handlers/base.py", line 112, in get_response
    response = wrapped_callback(request, *callback_args, **callback_kwargs)
  File "/home/lenovo/Envs/contact/local/lib/python2.7/site-packages/django/views/generic/base.py", line 69, in view
    return self.dispatch(request, *args, **kwargs)
  File "/home/lenovo/Envs/contact/local/lib/python2.7/site-packages/django/views/decorators/csrf.py", line 57, in wrapped_view
    return view_func(*args, **kwargs)
  File "/home/lenovo/Envs/contact/local/lib/python2.7/site-packages/rest_framework/views.py", line 400, in dispatch
    response = self.handle_exception(exc)
  File "/home/lenovo/Envs/contact/local/lib/python2.7/site-packages/rest_framework/views.py", line 397, in dispatch
    response = handler(request, *args, **kwargs)
  File "/home/lenovo/projects/contact/reminder/views.py", line 38, in post
    reminder.save()
  File "/home/lenovo/Envs/contact/local/lib/python2.7/site-packages/django/db/models/base.py", line 545, in save
    force_update=force_update, update_fields=update_fields)
  File "/home/lenovo/Envs/contact/local/lib/python2.7/site-packages/django/db/models/base.py", line 573, in save_base
    updated = self._save_table(raw, cls, force_insert, force_update, using, update_fields)
  File "/home/lenovo/Envs/contact/local/lib/python2.7/site-packages/django/db/models/base.py", line 635, in _save_table
    forced_update)
  File "/home/lenovo/Envs/contact/local/lib/python2.7/site-packages/django/db/models/base.py", line 679, in _do_update
    return filtered._update(values) > 0
  File "/home/lenovo/Envs/contact/local/lib/python2.7/site-packages/django/db/models/query.py", line 510, in _update
    return query.get_compiler(self.db).execute_sql(None)
  File "/home/lenovo/Envs/contact/local/lib/python2.7/site-packages/django/db/models/sql/compiler.py", line 980, in execute_sql
    cursor = super(SQLUpdateCompiler, self).execute_sql(result_type)
  File "/home/lenovo/Envs/contact/local/lib/python2.7/site-packages/django/db/models/sql/compiler.py", line 776, in execute_sql
    sql, params = self.as_sql()
  File "/home/lenovo/Envs/contact/local/lib/python2.7/site-packages/django/db/models/sql/compiler.py", line 945, in as_sql
    val = field.get_db_prep_save(val, connection=self.connection)
  File "/home/lenovo/Envs/contact/local/lib/python2.7/site-packages/django/db/models/fields/__init__.py", line 350, in get_db_prep_save
    prepared=False)
  File "/home/lenovo/Envs/contact/local/lib/python2.7/site-packages/django/db/models/fields/__init__.py", line 342, in get_db_prep_value
    value = self.get_prep_value(value)
  File "/home/lenovo/Envs/contact/local/lib/python2.7/site-packages/django/db/models/fields/__init__.py", line 1079, in get_prep_value
    return int(value)
TypeError: int() argument must be a string or a number, not 'tuple'
[12/Aug/2014 10:04:03] ERROR [django.request:224] Internal Server Error: /inbox/refresh/
Traceback (most recent call last):
  File "/home/lenovo/Envs/contact/local/lib/python2.7/site-packages/django/core/handlers/base.py", line 112, in get_response
    response = wrapped_callback(request, *callback_args, **callback_kwargs)
  File "/home/lenovo/Envs/contact/local/lib/python2.7/site-packages/django/views/generic/base.py", line 69, in view
    return self.dispatch(request, *args, **kwargs)
  File "/home/lenovo/Envs/contact/local/lib/python2.7/site-packages/django/views/decorators/csrf.py", line 57, in wrapped_view
    return view_func(*args, **kwargs)
  File "/home/lenovo/Envs/contact/local/lib/python2.7/site-packages/rest_framework/views.py", line 400, in dispatch
    response = self.handle_exception(exc)
  File "/home/lenovo/Envs/contact/local/lib/python2.7/site-packages/rest_framework/views.py", line 397, in dispatch
    response = handler(request, *args, **kwargs)
  File "/home/lenovo/Envs/contact/local/lib/python2.7/site-packages/django/db/transaction.py", line 371, in inner
    return func(*args, **kwargs)
  File "/home/lenovo/projects/contact/gmail/views.py", line 35, in get
    in_import = InboxImport(user)
  File "/home/lenovo/projects/contact/gmail/parsers.py", line 17, in __init__
    self.service = Auth.get_gmail_srv(user)
  File "/home/lenovo/projects/contact/gmail/__init__.py", line 43, in get_gmail_srv
    return build('gmail', 'v1', http=http)
  File "/home/lenovo/Envs/contact/local/lib/python2.7/site-packages/oauth2client/util.py", line 132, in positional_wrapper
    return wrapped(*args, **kwargs)
  File "/home/lenovo/Envs/contact/local/lib/python2.7/site-packages/apiclient/discovery.py", line 192, in build
    resp, content = http.request(requested_url)
  File "/home/lenovo/Envs/contact/local/lib/python2.7/site-packages/oauth2client/util.py", line 132, in positional_wrapper
    return wrapped(*args, **kwargs)
  File "/home/lenovo/Envs/contact/local/lib/python2.7/site-packages/oauth2client/client.py", line 490, in new_request
    redirections, connection_type)
  File "/home/lenovo/Envs/contact/local/lib/python2.7/site-packages/httplib2/__init__.py", line 1593, in request
    (response, content) = self._request(conn, authority, uri, request_uri, method, body, headers, redirections, cachekey)
  File "/home/lenovo/Envs/contact/local/lib/python2.7/site-packages/httplib2/__init__.py", line 1335, in _request
    (response, content) = self._conn_request(conn, request_uri, method, body, headers)
  File "/home/lenovo/Envs/contact/local/lib/python2.7/site-packages/httplib2/__init__.py", line 1257, in _conn_request
    conn.connect()
  File "/home/lenovo/Envs/contact/local/lib/python2.7/site-packages/httplib2/__init__.py", line 1060, in connect
    raise socket.error, msg
error: [Errno 111] Connection refused
[12/Aug/2014 10:04:55] ERROR [django.request:224] Internal Server Error: /reminder/delete/
Traceback (most recent call last):
  File "/home/lenovo/Envs/contact/local/lib/python2.7/site-packages/django/core/handlers/base.py", line 112, in get_response
    response = wrapped_callback(request, *callback_args, **callback_kwargs)
  File "/home/lenovo/Envs/contact/local/lib/python2.7/site-packages/django/views/generic/base.py", line 69, in view
    return self.dispatch(request, *args, **kwargs)
  File "/home/lenovo/Envs/contact/local/lib/python2.7/site-packages/django/views/generic/base.py", line 87, in dispatch
    return handler(request, *args, **kwargs)
  File "/home/lenovo/projects/contact/reminder/views.py", line 38, in post
    reminder.save()
  File "/home/lenovo/Envs/contact/local/lib/python2.7/site-packages/django/db/models/base.py", line 545, in save
    force_update=force_update, update_fields=update_fields)
  File "/home/lenovo/Envs/contact/local/lib/python2.7/site-packages/django/db/models/base.py", line 573, in save_base
    updated = self._save_table(raw, cls, force_insert, force_update, using, update_fields)
  File "/home/lenovo/Envs/contact/local/lib/python2.7/site-packages/django/db/models/base.py", line 635, in _save_table
    forced_update)
  File "/home/lenovo/Envs/contact/local/lib/python2.7/site-packages/django/db/models/base.py", line 679, in _do_update
    return filtered._update(values) > 0
  File "/home/lenovo/Envs/contact/local/lib/python2.7/site-packages/django/db/models/query.py", line 510, in _update
    return query.get_compiler(self.db).execute_sql(None)
  File "/home/lenovo/Envs/contact/local/lib/python2.7/site-packages/django/db/models/sql/compiler.py", line 980, in execute_sql
    cursor = super(SQLUpdateCompiler, self).execute_sql(result_type)
  File "/home/lenovo/Envs/contact/local/lib/python2.7/site-packages/django/db/models/sql/compiler.py", line 776, in execute_sql
    sql, params = self.as_sql()
  File "/home/lenovo/Envs/contact/local/lib/python2.7/site-packages/django/db/models/sql/compiler.py", line 945, in as_sql
    val = field.get_db_prep_save(val, connection=self.connection)
  File "/home/lenovo/Envs/contact/local/lib/python2.7/site-packages/django/db/models/fields/__init__.py", line 350, in get_db_prep_save
    prepared=False)
  File "/home/lenovo/Envs/contact/local/lib/python2.7/site-packages/django/db/models/fields/__init__.py", line 342, in get_db_prep_value
    value = self.get_prep_value(value)
  File "/home/lenovo/Envs/contact/local/lib/python2.7/site-packages/django/db/models/fields/__init__.py", line 1079, in get_prep_value
    return int(value)
TypeError: int() argument must be a string or a number, not 'tuple'
[12/Aug/2014 10:05:07] ERROR [django.request:224] Internal Server Error: /inbox/refresh/
Traceback (most recent call last):
  File "/home/lenovo/Envs/contact/local/lib/python2.7/site-packages/django/core/handlers/base.py", line 112, in get_response
    response = wrapped_callback(request, *callback_args, **callback_kwargs)
  File "/home/lenovo/Envs/contact/local/lib/python2.7/site-packages/django/views/generic/base.py", line 69, in view
    return self.dispatch(request, *args, **kwargs)
  File "/home/lenovo/Envs/contact/local/lib/python2.7/site-packages/django/views/decorators/csrf.py", line 57, in wrapped_view
    return view_func(*args, **kwargs)
  File "/home/lenovo/Envs/contact/local/lib/python2.7/site-packages/rest_framework/views.py", line 400, in dispatch
    response = self.handle_exception(exc)
  File "/home/lenovo/Envs/contact/local/lib/python2.7/site-packages/rest_framework/views.py", line 397, in dispatch
    response = handler(request, *args, **kwargs)
  File "/home/lenovo/Envs/contact/local/lib/python2.7/site-packages/django/db/transaction.py", line 371, in inner
    return func(*args, **kwargs)
  File "/home/lenovo/projects/contact/gmail/views.py", line 35, in get
    in_import = InboxImport(user)
  File "/home/lenovo/projects/contact/gmail/parsers.py", line 17, in __init__
    self.service = Auth.get_gmail_srv(user)
  File "/home/lenovo/projects/contact/gmail/__init__.py", line 43, in get_gmail_srv
    return build('gmail', 'v1', http=http)
  File "/home/lenovo/Envs/contact/local/lib/python2.7/site-packages/oauth2client/util.py", line 132, in positional_wrapper
    return wrapped(*args, **kwargs)
  File "/home/lenovo/Envs/contact/local/lib/python2.7/site-packages/apiclient/discovery.py", line 192, in build
    resp, content = http.request(requested_url)
  File "/home/lenovo/Envs/contact/local/lib/python2.7/site-packages/oauth2client/util.py", line 132, in positional_wrapper
    return wrapped(*args, **kwargs)
  File "/home/lenovo/Envs/contact/local/lib/python2.7/site-packages/oauth2client/client.py", line 490, in new_request
    redirections, connection_type)
  File "/home/lenovo/Envs/contact/local/lib/python2.7/site-packages/httplib2/__init__.py", line 1593, in request
    (response, content) = self._request(conn, authority, uri, request_uri, method, body, headers, redirections, cachekey)
  File "/home/lenovo/Envs/contact/local/lib/python2.7/site-packages/httplib2/__init__.py", line 1335, in _request
    (response, content) = self._conn_request(conn, request_uri, method, body, headers)
  File "/home/lenovo/Envs/contact/local/lib/python2.7/site-packages/httplib2/__init__.py", line 1257, in _conn_request
    conn.connect()
  File "/home/lenovo/Envs/contact/local/lib/python2.7/site-packages/httplib2/__init__.py", line 1060, in connect
    raise socket.error, msg
error: [Errno 111] Connection refused
[12/Aug/2014 10:05:58] ERROR [django.request:224] Internal Server Error: /reminder/delete/
Traceback (most recent call last):
  File "/home/lenovo/Envs/contact/local/lib/python2.7/site-packages/django/core/handlers/base.py", line 112, in get_response
    response = wrapped_callback(request, *callback_args, **callback_kwargs)
  File "/home/lenovo/Envs/contact/local/lib/python2.7/site-packages/django/views/generic/base.py", line 69, in view
    return self.dispatch(request, *args, **kwargs)
  File "/home/lenovo/Envs/contact/local/lib/python2.7/site-packages/django/views/generic/base.py", line 87, in dispatch
    return handler(request, *args, **kwargs)
  File "/home/lenovo/projects/contact/reminder/views.py", line 38, in post
    reminder.save()
  File "/home/lenovo/Envs/contact/local/lib/python2.7/site-packages/django/db/models/base.py", line 545, in save
    force_update=force_update, update_fields=update_fields)
  File "/home/lenovo/Envs/contact/local/lib/python2.7/site-packages/django/db/models/base.py", line 573, in save_base
    updated = self._save_table(raw, cls, force_insert, force_update, using, update_fields)
  File "/home/lenovo/Envs/contact/local/lib/python2.7/site-packages/django/db/models/base.py", line 635, in _save_table
    forced_update)
  File "/home/lenovo/Envs/contact/local/lib/python2.7/site-packages/django/db/models/base.py", line 679, in _do_update
    return filtered._update(values) > 0
  File "/home/lenovo/Envs/contact/local/lib/python2.7/site-packages/django/db/models/query.py", line 510, in _update
    return query.get_compiler(self.db).execute_sql(None)
  File "/home/lenovo/Envs/contact/local/lib/python2.7/site-packages/django/db/models/sql/compiler.py", line 980, in execute_sql
    cursor = super(SQLUpdateCompiler, self).execute_sql(result_type)
  File "/home/lenovo/Envs/contact/local/lib/python2.7/site-packages/django/db/models/sql/compiler.py", line 776, in execute_sql
    sql, params = self.as_sql()
  File "/home/lenovo/Envs/contact/local/lib/python2.7/site-packages/django/db/models/sql/compiler.py", line 945, in as_sql
    val = field.get_db_prep_save(val, connection=self.connection)
  File "/home/lenovo/Envs/contact/local/lib/python2.7/site-packages/django/db/models/fields/__init__.py", line 350, in get_db_prep_save
    prepared=False)
  File "/home/lenovo/Envs/contact/local/lib/python2.7/site-packages/django/db/models/fields/__init__.py", line 342, in get_db_prep_value
    value = self.get_prep_value(value)
  File "/home/lenovo/Envs/contact/local/lib/python2.7/site-packages/django/db/models/fields/__init__.py", line 1079, in get_prep_value
    return int(value)
TypeError: int() argument must be a string or a number, not 'tuple'
[12/Aug/2014 10:06:11] ERROR [django.request:224] Internal Server Error: /inbox/refresh/
Traceback (most recent call last):
  File "/home/lenovo/Envs/contact/local/lib/python2.7/site-packages/django/core/handlers/base.py", line 112, in get_response
    response = wrapped_callback(request, *callback_args, **callback_kwargs)
  File "/home/lenovo/Envs/contact/local/lib/python2.7/site-packages/django/views/generic/base.py", line 69, in view
    return self.dispatch(request, *args, **kwargs)
  File "/home/lenovo/Envs/contact/local/lib/python2.7/site-packages/django/views/decorators/csrf.py", line 57, in wrapped_view
    return view_func(*args, **kwargs)
  File "/home/lenovo/Envs/contact/local/lib/python2.7/site-packages/rest_framework/views.py", line 400, in dispatch
    response = self.handle_exception(exc)
  File "/home/lenovo/Envs/contact/local/lib/python2.7/site-packages/rest_framework/views.py", line 397, in dispatch
    response = handler(request, *args, **kwargs)
  File "/home/lenovo/Envs/contact/local/lib/python2.7/site-packages/django/db/transaction.py", line 371, in inner
    return func(*args, **kwargs)
  File "/home/lenovo/projects/contact/gmail/views.py", line 35, in get
    in_import = InboxImport(user)
  File "/home/lenovo/projects/contact/gmail/parsers.py", line 17, in __init__
    self.service = Auth.get_gmail_srv(user)
  File "/home/lenovo/projects/contact/gmail/__init__.py", line 43, in get_gmail_srv
    return build('gmail', 'v1', http=http)
  File "/home/lenovo/Envs/contact/local/lib/python2.7/site-packages/oauth2client/util.py", line 132, in positional_wrapper
    return wrapped(*args, **kwargs)
  File "/home/lenovo/Envs/contact/local/lib/python2.7/site-packages/apiclient/discovery.py", line 192, in build
    resp, content = http.request(requested_url)
  File "/home/lenovo/Envs/contact/local/lib/python2.7/site-packages/oauth2client/util.py", line 132, in positional_wrapper
    return wrapped(*args, **kwargs)
  File "/home/lenovo/Envs/contact/local/lib/python2.7/site-packages/oauth2client/client.py", line 490, in new_request
    redirections, connection_type)
  File "/home/lenovo/Envs/contact/local/lib/python2.7/site-packages/httplib2/__init__.py", line 1593, in request
    (response, content) = self._request(conn, authority, uri, request_uri, method, body, headers, redirections, cachekey)
  File "/home/lenovo/Envs/contact/local/lib/python2.7/site-packages/httplib2/__init__.py", line 1335, in _request
    (response, content) = self._conn_request(conn, request_uri, method, body, headers)
  File "/home/lenovo/Envs/contact/local/lib/python2.7/site-packages/httplib2/__init__.py", line 1257, in _conn_request
    conn.connect()
  File "/home/lenovo/Envs/contact/local/lib/python2.7/site-packages/httplib2/__init__.py", line 1060, in connect
    raise socket.error, msg
error: [Errno 111] Connection refused
[12/Aug/2014 10:06:56] ERROR [django.request:224] Internal Server Error: /inbox/refresh/
Traceback (most recent call last):
  File "/home/lenovo/Envs/contact/local/lib/python2.7/site-packages/django/core/handlers/base.py", line 112, in get_response
    response = wrapped_callback(request, *callback_args, **callback_kwargs)
  File "/home/lenovo/Envs/contact/local/lib/python2.7/site-packages/django/views/generic/base.py", line 69, in view
    return self.dispatch(request, *args, **kwargs)
  File "/home/lenovo/Envs/contact/local/lib/python2.7/site-packages/django/views/decorators/csrf.py", line 57, in wrapped_view
    return view_func(*args, **kwargs)
  File "/home/lenovo/Envs/contact/local/lib/python2.7/site-packages/rest_framework/views.py", line 400, in dispatch
    response = self.handle_exception(exc)
  File "/home/lenovo/Envs/contact/local/lib/python2.7/site-packages/rest_framework/views.py", line 397, in dispatch
    response = handler(request, *args, **kwargs)
  File "/home/lenovo/Envs/contact/local/lib/python2.7/site-packages/django/db/transaction.py", line 371, in inner
    return func(*args, **kwargs)
  File "/home/lenovo/projects/contact/gmail/views.py", line 35, in get
    in_import = InboxImport(user)
  File "/home/lenovo/projects/contact/gmail/parsers.py", line 17, in __init__
    self.service = Auth.get_gmail_srv(user)
  File "/home/lenovo/projects/contact/gmail/__init__.py", line 43, in get_gmail_srv
    return build('gmail', 'v1', http=http)
  File "/home/lenovo/Envs/contact/local/lib/python2.7/site-packages/oauth2client/util.py", line 132, in positional_wrapper
    return wrapped(*args, **kwargs)
  File "/home/lenovo/Envs/contact/local/lib/python2.7/site-packages/apiclient/discovery.py", line 192, in build
    resp, content = http.request(requested_url)
  File "/home/lenovo/Envs/contact/local/lib/python2.7/site-packages/oauth2client/util.py", line 132, in positional_wrapper
    return wrapped(*args, **kwargs)
  File "/home/lenovo/Envs/contact/local/lib/python2.7/site-packages/oauth2client/client.py", line 490, in new_request
    redirections, connection_type)
  File "/home/lenovo/Envs/contact/local/lib/python2.7/site-packages/httplib2/__init__.py", line 1593, in request
    (response, content) = self._request(conn, authority, uri, request_uri, method, body, headers, redirections, cachekey)
  File "/home/lenovo/Envs/contact/local/lib/python2.7/site-packages/httplib2/__init__.py", line 1335, in _request
    (response, content) = self._conn_request(conn, request_uri, method, body, headers)
  File "/home/lenovo/Envs/contact/local/lib/python2.7/site-packages/httplib2/__init__.py", line 1257, in _conn_request
    conn.connect()
  File "/home/lenovo/Envs/contact/local/lib/python2.7/site-packages/httplib2/__init__.py", line 1060, in connect
    raise socket.error, msg
error: [Errno 111] Connection refused
[12/Aug/2014 10:07:05] ERROR [django.request:224] Internal Server Error: /reminder/delete/
Traceback (most recent call last):
  File "/home/lenovo/Envs/contact/local/lib/python2.7/site-packages/django/core/handlers/base.py", line 112, in get_response
    response = wrapped_callback(request, *callback_args, **callback_kwargs)
  File "/home/lenovo/Envs/contact/local/lib/python2.7/site-packages/django/views/generic/base.py", line 69, in view
    return self.dispatch(request, *args, **kwargs)
  File "/home/lenovo/Envs/contact/local/lib/python2.7/site-packages/django/views/generic/base.py", line 87, in dispatch
    return handler(request, *args, **kwargs)
  File "/home/lenovo/projects/contact/reminder/views.py", line 38, in post
    reminder.save()
  File "/home/lenovo/Envs/contact/local/lib/python2.7/site-packages/django/db/models/base.py", line 545, in save
    force_update=force_update, update_fields=update_fields)
  File "/home/lenovo/Envs/contact/local/lib/python2.7/site-packages/django/db/models/base.py", line 573, in save_base
    updated = self._save_table(raw, cls, force_insert, force_update, using, update_fields)
  File "/home/lenovo/Envs/contact/local/lib/python2.7/site-packages/django/db/models/base.py", line 635, in _save_table
    forced_update)
  File "/home/lenovo/Envs/contact/local/lib/python2.7/site-packages/django/db/models/base.py", line 679, in _do_update
    return filtered._update(values) > 0
  File "/home/lenovo/Envs/contact/local/lib/python2.7/site-packages/django/db/models/query.py", line 510, in _update
    return query.get_compiler(self.db).execute_sql(None)
  File "/home/lenovo/Envs/contact/local/lib/python2.7/site-packages/django/db/models/sql/compiler.py", line 980, in execute_sql
    cursor = super(SQLUpdateCompiler, self).execute_sql(result_type)
  File "/home/lenovo/Envs/contact/local/lib/python2.7/site-packages/django/db/models/sql/compiler.py", line 776, in execute_sql
    sql, params = self.as_sql()
  File "/home/lenovo/Envs/contact/local/lib/python2.7/site-packages/django/db/models/sql/compiler.py", line 945, in as_sql
    val = field.get_db_prep_save(val, connection=self.connection)
  File "/home/lenovo/Envs/contact/local/lib/python2.7/site-packages/django/db/models/fields/__init__.py", line 350, in get_db_prep_save
    prepared=False)
  File "/home/lenovo/Envs/contact/local/lib/python2.7/site-packages/django/db/models/fields/__init__.py", line 342, in get_db_prep_value
    value = self.get_prep_value(value)
  File "/home/lenovo/Envs/contact/local/lib/python2.7/site-packages/django/db/models/fields/__init__.py", line 1079, in get_prep_value
    return int(value)
TypeError: int() argument must be a string or a number, not 'tuple'
[12/Aug/2014 10:07:08] ERROR [django.request:224] Internal Server Error: /reminder/delete/
Traceback (most recent call last):
  File "/home/lenovo/Envs/contact/local/lib/python2.7/site-packages/django/core/handlers/base.py", line 112, in get_response
    response = wrapped_callback(request, *callback_args, **callback_kwargs)
  File "/home/lenovo/Envs/contact/local/lib/python2.7/site-packages/django/views/generic/base.py", line 69, in view
    return self.dispatch(request, *args, **kwargs)
  File "/home/lenovo/Envs/contact/local/lib/python2.7/site-packages/django/views/generic/base.py", line 87, in dispatch
    return handler(request, *args, **kwargs)
  File "/home/lenovo/projects/contact/reminder/views.py", line 38, in post
    reminder.save()
  File "/home/lenovo/Envs/contact/local/lib/python2.7/site-packages/django/db/models/base.py", line 545, in save
    force_update=force_update, update_fields=update_fields)
  File "/home/lenovo/Envs/contact/local/lib/python2.7/site-packages/django/db/models/base.py", line 573, in save_base
    updated = self._save_table(raw, cls, force_insert, force_update, using, update_fields)
  File "/home/lenovo/Envs/contact/local/lib/python2.7/site-packages/django/db/models/base.py", line 635, in _save_table
    forced_update)
  File "/home/lenovo/Envs/contact/local/lib/python2.7/site-packages/django/db/models/base.py", line 679, in _do_update
    return filtered._update(values) > 0
  File "/home/lenovo/Envs/contact/local/lib/python2.7/site-packages/django/db/models/query.py", line 510, in _update
    return query.get_compiler(self.db).execute_sql(None)
  File "/home/lenovo/Envs/contact/local/lib/python2.7/site-packages/django/db/models/sql/compiler.py", line 980, in execute_sql
    cursor = super(SQLUpdateCompiler, self).execute_sql(result_type)
  File "/home/lenovo/Envs/contact/local/lib/python2.7/site-packages/django/db/models/sql/compiler.py", line 776, in execute_sql
    sql, params = self.as_sql()
  File "/home/lenovo/Envs/contact/local/lib/python2.7/site-packages/django/db/models/sql/compiler.py", line 945, in as_sql
    val = field.get_db_prep_save(val, connection=self.connection)
  File "/home/lenovo/Envs/contact/local/lib/python2.7/site-packages/django/db/models/fields/__init__.py", line 350, in get_db_prep_save
    prepared=False)
  File "/home/lenovo/Envs/contact/local/lib/python2.7/site-packages/django/db/models/fields/__init__.py", line 342, in get_db_prep_value
    value = self.get_prep_value(value)
  File "/home/lenovo/Envs/contact/local/lib/python2.7/site-packages/django/db/models/fields/__init__.py", line 1079, in get_prep_value
    return int(value)
TypeError: int() argument must be a string or a number, not 'tuple'
[12/Aug/2014 10:07:47] ERROR [django.request:224] Internal Server Error: /inbox/refresh/
Traceback (most recent call last):
  File "/home/lenovo/Envs/contact/local/lib/python2.7/site-packages/django/core/handlers/base.py", line 112, in get_response
    response = wrapped_callback(request, *callback_args, **callback_kwargs)
  File "/home/lenovo/Envs/contact/local/lib/python2.7/site-packages/django/views/generic/base.py", line 69, in view
    return self.dispatch(request, *args, **kwargs)
  File "/home/lenovo/Envs/contact/local/lib/python2.7/site-packages/django/views/decorators/csrf.py", line 57, in wrapped_view
    return view_func(*args, **kwargs)
  File "/home/lenovo/Envs/contact/local/lib/python2.7/site-packages/rest_framework/views.py", line 400, in dispatch
    response = self.handle_exception(exc)
  File "/home/lenovo/Envs/contact/local/lib/python2.7/site-packages/rest_framework/views.py", line 397, in dispatch
    response = handler(request, *args, **kwargs)
  File "/home/lenovo/Envs/contact/local/lib/python2.7/site-packages/django/db/transaction.py", line 371, in inner
    return func(*args, **kwargs)
  File "/home/lenovo/projects/contact/gmail/views.py", line 35, in get
    in_import = InboxImport(user)
  File "/home/lenovo/projects/contact/gmail/parsers.py", line 17, in __init__
    self.service = Auth.get_gmail_srv(user)
  File "/home/lenovo/projects/contact/gmail/__init__.py", line 43, in get_gmail_srv
    return build('gmail', 'v1', http=http)
  File "/home/lenovo/Envs/contact/local/lib/python2.7/site-packages/oauth2client/util.py", line 132, in positional_wrapper
    return wrapped(*args, **kwargs)
  File "/home/lenovo/Envs/contact/local/lib/python2.7/site-packages/apiclient/discovery.py", line 192, in build
    resp, content = http.request(requested_url)
  File "/home/lenovo/Envs/contact/local/lib/python2.7/site-packages/oauth2client/util.py", line 132, in positional_wrapper
    return wrapped(*args, **kwargs)
  File "/home/lenovo/Envs/contact/local/lib/python2.7/site-packages/oauth2client/client.py", line 490, in new_request
    redirections, connection_type)
  File "/home/lenovo/Envs/contact/local/lib/python2.7/site-packages/httplib2/__init__.py", line 1593, in request
    (response, content) = self._request(conn, authority, uri, request_uri, method, body, headers, redirections, cachekey)
  File "/home/lenovo/Envs/contact/local/lib/python2.7/site-packages/httplib2/__init__.py", line 1335, in _request
    (response, content) = self._conn_request(conn, request_uri, method, body, headers)
  File "/home/lenovo/Envs/contact/local/lib/python2.7/site-packages/httplib2/__init__.py", line 1257, in _conn_request
    conn.connect()
  File "/home/lenovo/Envs/contact/local/lib/python2.7/site-packages/httplib2/__init__.py", line 1060, in connect
    raise socket.error, msg
error: [Errno 111] Connection refused
[12/Aug/2014 10:08:25] ERROR [django.request:224] Internal Server Error: /reminder/delete/
Traceback (most recent call last):
  File "/home/lenovo/Envs/contact/local/lib/python2.7/site-packages/django/core/handlers/base.py", line 112, in get_response
    response = wrapped_callback(request, *callback_args, **callback_kwargs)
  File "/home/lenovo/Envs/contact/local/lib/python2.7/site-packages/django/views/generic/base.py", line 69, in view
    return self.dispatch(request, *args, **kwargs)
  File "/home/lenovo/Envs/contact/local/lib/python2.7/site-packages/django/views/generic/base.py", line 87, in dispatch
    return handler(request, *args, **kwargs)
  File "/home/lenovo/projects/contact/reminder/views.py", line 39, in post
    reminder.save()
  File "/home/lenovo/Envs/contact/local/lib/python2.7/site-packages/django/db/models/base.py", line 545, in save
    force_update=force_update, update_fields=update_fields)
  File "/home/lenovo/Envs/contact/local/lib/python2.7/site-packages/django/db/models/base.py", line 573, in save_base
    updated = self._save_table(raw, cls, force_insert, force_update, using, update_fields)
  File "/home/lenovo/Envs/contact/local/lib/python2.7/site-packages/django/db/models/base.py", line 635, in _save_table
    forced_update)
  File "/home/lenovo/Envs/contact/local/lib/python2.7/site-packages/django/db/models/base.py", line 679, in _do_update
    return filtered._update(values) > 0
  File "/home/lenovo/Envs/contact/local/lib/python2.7/site-packages/django/db/models/query.py", line 510, in _update
    return query.get_compiler(self.db).execute_sql(None)
  File "/home/lenovo/Envs/contact/local/lib/python2.7/site-packages/django/db/models/sql/compiler.py", line 980, in execute_sql
    cursor = super(SQLUpdateCompiler, self).execute_sql(result_type)
  File "/home/lenovo/Envs/contact/local/lib/python2.7/site-packages/django/db/models/sql/compiler.py", line 776, in execute_sql
    sql, params = self.as_sql()
  File "/home/lenovo/Envs/contact/local/lib/python2.7/site-packages/django/db/models/sql/compiler.py", line 945, in as_sql
    val = field.get_db_prep_save(val, connection=self.connection)
  File "/home/lenovo/Envs/contact/local/lib/python2.7/site-packages/django/db/models/fields/__init__.py", line 350, in get_db_prep_save
    prepared=False)
  File "/home/lenovo/Envs/contact/local/lib/python2.7/site-packages/django/db/models/fields/__init__.py", line 342, in get_db_prep_value
    value = self.get_prep_value(value)
  File "/home/lenovo/Envs/contact/local/lib/python2.7/site-packages/django/db/models/fields/__init__.py", line 1079, in get_prep_value
    return int(value)
TypeError: int() argument must be a string or a number, not 'tuple'
[12/Aug/2014 10:08:36] ERROR [django.request:224] Internal Server Error: /inbox/refresh/
Traceback (most recent call last):
  File "/home/lenovo/Envs/contact/local/lib/python2.7/site-packages/django/core/handlers/base.py", line 112, in get_response
    response = wrapped_callback(request, *callback_args, **callback_kwargs)
  File "/home/lenovo/Envs/contact/local/lib/python2.7/site-packages/django/views/generic/base.py", line 69, in view
    return self.dispatch(request, *args, **kwargs)
  File "/home/lenovo/Envs/contact/local/lib/python2.7/site-packages/django/views/decorators/csrf.py", line 57, in wrapped_view
    return view_func(*args, **kwargs)
  File "/home/lenovo/Envs/contact/local/lib/python2.7/site-packages/rest_framework/views.py", line 400, in dispatch
    response = self.handle_exception(exc)
  File "/home/lenovo/Envs/contact/local/lib/python2.7/site-packages/rest_framework/views.py", line 397, in dispatch
    response = handler(request, *args, **kwargs)
  File "/home/lenovo/Envs/contact/local/lib/python2.7/site-packages/django/db/transaction.py", line 371, in inner
    return func(*args, **kwargs)
  File "/home/lenovo/projects/contact/gmail/views.py", line 35, in get
    in_import = InboxImport(user)
  File "/home/lenovo/projects/contact/gmail/parsers.py", line 17, in __init__
    self.service = Auth.get_gmail_srv(user)
  File "/home/lenovo/projects/contact/gmail/__init__.py", line 43, in get_gmail_srv
    return build('gmail', 'v1', http=http)
  File "/home/lenovo/Envs/contact/local/lib/python2.7/site-packages/oauth2client/util.py", line 132, in positional_wrapper
    return wrapped(*args, **kwargs)
  File "/home/lenovo/Envs/contact/local/lib/python2.7/site-packages/apiclient/discovery.py", line 192, in build
    resp, content = http.request(requested_url)
  File "/home/lenovo/Envs/contact/local/lib/python2.7/site-packages/oauth2client/util.py", line 132, in positional_wrapper
    return wrapped(*args, **kwargs)
  File "/home/lenovo/Envs/contact/local/lib/python2.7/site-packages/oauth2client/client.py", line 490, in new_request
    redirections, connection_type)
  File "/home/lenovo/Envs/contact/local/lib/python2.7/site-packages/httplib2/__init__.py", line 1593, in request
    (response, content) = self._request(conn, authority, uri, request_uri, method, body, headers, redirections, cachekey)
  File "/home/lenovo/Envs/contact/local/lib/python2.7/site-packages/httplib2/__init__.py", line 1335, in _request
    (response, content) = self._conn_request(conn, request_uri, method, body, headers)
  File "/home/lenovo/Envs/contact/local/lib/python2.7/site-packages/httplib2/__init__.py", line 1257, in _conn_request
    conn.connect()
  File "/home/lenovo/Envs/contact/local/lib/python2.7/site-packages/httplib2/__init__.py", line 1060, in connect
    raise socket.error, msg
error: [Errno 111] Connection refused
[12/Aug/2014 10:08:37] ERROR [django.request:224] Internal Server Error: /inbox/refresh/
Traceback (most recent call last):
  File "/home/lenovo/Envs/contact/local/lib/python2.7/site-packages/django/core/handlers/base.py", line 112, in get_response
    response = wrapped_callback(request, *callback_args, **callback_kwargs)
  File "/home/lenovo/Envs/contact/local/lib/python2.7/site-packages/django/views/generic/base.py", line 69, in view
    return self.dispatch(request, *args, **kwargs)
  File "/home/lenovo/Envs/contact/local/lib/python2.7/site-packages/django/views/decorators/csrf.py", line 57, in wrapped_view
    return view_func(*args, **kwargs)
  File "/home/lenovo/Envs/contact/local/lib/python2.7/site-packages/rest_framework/views.py", line 400, in dispatch
    response = self.handle_exception(exc)
  File "/home/lenovo/Envs/contact/local/lib/python2.7/site-packages/rest_framework/views.py", line 397, in dispatch
    response = handler(request, *args, **kwargs)
  File "/home/lenovo/Envs/contact/local/lib/python2.7/site-packages/django/db/transaction.py", line 371, in inner
    return func(*args, **kwargs)
  File "/home/lenovo/projects/contact/gmail/views.py", line 35, in get
    in_import = InboxImport(user)
  File "/home/lenovo/projects/contact/gmail/parsers.py", line 17, in __init__
    self.service = Auth.get_gmail_srv(user)
  File "/home/lenovo/projects/contact/gmail/__init__.py", line 43, in get_gmail_srv
    return build('gmail', 'v1', http=http)
  File "/home/lenovo/Envs/contact/local/lib/python2.7/site-packages/oauth2client/util.py", line 132, in positional_wrapper
    return wrapped(*args, **kwargs)
  File "/home/lenovo/Envs/contact/local/lib/python2.7/site-packages/apiclient/discovery.py", line 192, in build
    resp, content = http.request(requested_url)
  File "/home/lenovo/Envs/contact/local/lib/python2.7/site-packages/oauth2client/util.py", line 132, in positional_wrapper
    return wrapped(*args, **kwargs)
  File "/home/lenovo/Envs/contact/local/lib/python2.7/site-packages/oauth2client/client.py", line 490, in new_request
    redirections, connection_type)
  File "/home/lenovo/Envs/contact/local/lib/python2.7/site-packages/httplib2/__init__.py", line 1593, in request
    (response, content) = self._request(conn, authority, uri, request_uri, method, body, headers, redirections, cachekey)
  File "/home/lenovo/Envs/contact/local/lib/python2.7/site-packages/httplib2/__init__.py", line 1335, in _request
    (response, content) = self._conn_request(conn, request_uri, method, body, headers)
  File "/home/lenovo/Envs/contact/local/lib/python2.7/site-packages/httplib2/__init__.py", line 1257, in _conn_request
    conn.connect()
  File "/home/lenovo/Envs/contact/local/lib/python2.7/site-packages/httplib2/__init__.py", line 1060, in connect
    raise socket.error, msg
error: [Errno 111] Connection refused
[12/Aug/2014 10:08:45] ERROR [django.request:224] Internal Server Error: /reminder/add/
Traceback (most recent call last):
  File "/home/lenovo/Envs/contact/local/lib/python2.7/site-packages/django/core/handlers/base.py", line 112, in get_response
    response = wrapped_callback(request, *callback_args, **callback_kwargs)
  File "/home/lenovo/Envs/contact/local/lib/python2.7/site-packages/django/views/generic/base.py", line 69, in view
    return self.dispatch(request, *args, **kwargs)
  File "/home/lenovo/Envs/contact/local/lib/python2.7/site-packages/django/views/decorators/csrf.py", line 57, in wrapped_view
    return view_func(*args, **kwargs)
  File "/home/lenovo/Envs/contact/local/lib/python2.7/site-packages/rest_framework/views.py", line 400, in dispatch
    response = self.handle_exception(exc)
  File "/home/lenovo/Envs/contact/local/lib/python2.7/site-packages/rest_framework/views.py", line 397, in dispatch
    response = handler(request, *args, **kwargs)
  File "/home/lenovo/projects/contact/reminder/views.py", line 27, in post
    reminder.save()
  File "/home/lenovo/Envs/contact/local/lib/python2.7/site-packages/django/db/models/base.py", line 545, in save
    force_update=force_update, update_fields=update_fields)
  File "/home/lenovo/Envs/contact/local/lib/python2.7/site-packages/django/db/models/base.py", line 573, in save_base
    updated = self._save_table(raw, cls, force_insert, force_update, using, update_fields)
  File "/home/lenovo/Envs/contact/local/lib/python2.7/site-packages/django/db/models/base.py", line 654, in _save_table
    result = self._do_insert(cls._base_manager, using, fields, update_pk, raw)
  File "/home/lenovo/Envs/contact/local/lib/python2.7/site-packages/django/db/models/base.py", line 687, in _do_insert
    using=using, raw=raw)
  File "/home/lenovo/Envs/contact/local/lib/python2.7/site-packages/django/db/models/manager.py", line 232, in _insert
    return insert_query(self.model, objs, fields, **kwargs)
  File "/home/lenovo/Envs/contact/local/lib/python2.7/site-packages/django/db/models/query.py", line 1514, in insert_query
    return query.get_compiler(using=using).execute_sql(return_id)
  File "/home/lenovo/Envs/contact/local/lib/python2.7/site-packages/django/db/models/sql/compiler.py", line 902, in execute_sql
    for sql, params in self.as_sql():
  File "/home/lenovo/Envs/contact/local/lib/python2.7/site-packages/django/db/models/sql/compiler.py", line 860, in as_sql
    for obj in self.query.objs
  File "/home/lenovo/Envs/contact/local/lib/python2.7/site-packages/django/db/models/fields/__init__.py", line 350, in get_db_prep_save
    prepared=False)
  File "/home/lenovo/Envs/contact/local/lib/python2.7/site-packages/django/db/models/fields/__init__.py", line 342, in get_db_prep_value
    value = self.get_prep_value(value)
  File "/home/lenovo/Envs/contact/local/lib/python2.7/site-packages/django/db/models/fields/__init__.py", line 1079, in get_prep_value
    return int(value)
TypeError: int() argument must be a string or a number, not 'tuple'
[12/Aug/2014 10:10:07] ERROR [django.request:224] Internal Server Error: /inbox/refresh/
Traceback (most recent call last):
  File "/home/lenovo/Envs/contact/local/lib/python2.7/site-packages/django/core/handlers/base.py", line 112, in get_response
    response = wrapped_callback(request, *callback_args, **callback_kwargs)
  File "/home/lenovo/Envs/contact/local/lib/python2.7/site-packages/django/views/generic/base.py", line 69, in view
    return self.dispatch(request, *args, **kwargs)
  File "/home/lenovo/Envs/contact/local/lib/python2.7/site-packages/django/views/decorators/csrf.py", line 57, in wrapped_view
    return view_func(*args, **kwargs)
  File "/home/lenovo/Envs/contact/local/lib/python2.7/site-packages/rest_framework/views.py", line 400, in dispatch
    response = self.handle_exception(exc)
  File "/home/lenovo/Envs/contact/local/lib/python2.7/site-packages/rest_framework/views.py", line 397, in dispatch
    response = handler(request, *args, **kwargs)
  File "/home/lenovo/Envs/contact/local/lib/python2.7/site-packages/django/db/transaction.py", line 371, in inner
    return func(*args, **kwargs)
  File "/home/lenovo/projects/contact/gmail/views.py", line 35, in get
    in_import = InboxImport(user)
  File "/home/lenovo/projects/contact/gmail/parsers.py", line 17, in __init__
    self.service = Auth.get_gmail_srv(user)
  File "/home/lenovo/projects/contact/gmail/__init__.py", line 43, in get_gmail_srv
    return build('gmail', 'v1', http=http)
  File "/home/lenovo/Envs/contact/local/lib/python2.7/site-packages/oauth2client/util.py", line 132, in positional_wrapper
    return wrapped(*args, **kwargs)
  File "/home/lenovo/Envs/contact/local/lib/python2.7/site-packages/apiclient/discovery.py", line 192, in build
    resp, content = http.request(requested_url)
  File "/home/lenovo/Envs/contact/local/lib/python2.7/site-packages/oauth2client/util.py", line 132, in positional_wrapper
    return wrapped(*args, **kwargs)
  File "/home/lenovo/Envs/contact/local/lib/python2.7/site-packages/oauth2client/client.py", line 490, in new_request
    redirections, connection_type)
  File "/home/lenovo/Envs/contact/local/lib/python2.7/site-packages/httplib2/__init__.py", line 1593, in request
    (response, content) = self._request(conn, authority, uri, request_uri, method, body, headers, redirections, cachekey)
  File "/home/lenovo/Envs/contact/local/lib/python2.7/site-packages/httplib2/__init__.py", line 1335, in _request
    (response, content) = self._conn_request(conn, request_uri, method, body, headers)
  File "/home/lenovo/Envs/contact/local/lib/python2.7/site-packages/httplib2/__init__.py", line 1257, in _conn_request
    conn.connect()
  File "/home/lenovo/Envs/contact/local/lib/python2.7/site-packages/httplib2/__init__.py", line 1060, in connect
    raise socket.error, msg
error: [Errno 111] Connection refused
[12/Aug/2014 10:11:14] ERROR [django.request:224] Internal Server Error: /inbox/refresh/
Traceback (most recent call last):
  File "/home/lenovo/Envs/contact/local/lib/python2.7/site-packages/django/core/handlers/base.py", line 112, in get_response
    response = wrapped_callback(request, *callback_args, **callback_kwargs)
  File "/home/lenovo/Envs/contact/local/lib/python2.7/site-packages/django/views/generic/base.py", line 69, in view
    return self.dispatch(request, *args, **kwargs)
  File "/home/lenovo/Envs/contact/local/lib/python2.7/site-packages/django/views/decorators/csrf.py", line 57, in wrapped_view
    return view_func(*args, **kwargs)
  File "/home/lenovo/Envs/contact/local/lib/python2.7/site-packages/rest_framework/views.py", line 400, in dispatch
    response = self.handle_exception(exc)
  File "/home/lenovo/Envs/contact/local/lib/python2.7/site-packages/rest_framework/views.py", line 397, in dispatch
    response = handler(request, *args, **kwargs)
  File "/home/lenovo/Envs/contact/local/lib/python2.7/site-packages/django/db/transaction.py", line 371, in inner
    return func(*args, **kwargs)
  File "/home/lenovo/projects/contact/gmail/views.py", line 35, in get
    in_import = InboxImport(user)
  File "/home/lenovo/projects/contact/gmail/parsers.py", line 17, in __init__
    self.service = Auth.get_gmail_srv(user)
  File "/home/lenovo/projects/contact/gmail/__init__.py", line 43, in get_gmail_srv
    return build('gmail', 'v1', http=http)
  File "/home/lenovo/Envs/contact/local/lib/python2.7/site-packages/oauth2client/util.py", line 132, in positional_wrapper
    return wrapped(*args, **kwargs)
  File "/home/lenovo/Envs/contact/local/lib/python2.7/site-packages/apiclient/discovery.py", line 192, in build
    resp, content = http.request(requested_url)
  File "/home/lenovo/Envs/contact/local/lib/python2.7/site-packages/oauth2client/util.py", line 132, in positional_wrapper
    return wrapped(*args, **kwargs)
  File "/home/lenovo/Envs/contact/local/lib/python2.7/site-packages/oauth2client/client.py", line 490, in new_request
    redirections, connection_type)
  File "/home/lenovo/Envs/contact/local/lib/python2.7/site-packages/httplib2/__init__.py", line 1593, in request
    (response, content) = self._request(conn, authority, uri, request_uri, method, body, headers, redirections, cachekey)
  File "/home/lenovo/Envs/contact/local/lib/python2.7/site-packages/httplib2/__init__.py", line 1335, in _request
    (response, content) = self._conn_request(conn, request_uri, method, body, headers)
  File "/home/lenovo/Envs/contact/local/lib/python2.7/site-packages/httplib2/__init__.py", line 1257, in _conn_request
    conn.connect()
  File "/home/lenovo/Envs/contact/local/lib/python2.7/site-packages/httplib2/__init__.py", line 1060, in connect
    raise socket.error, msg
error: [Errno 111] Connection refused
[12/Aug/2014 10:20:16] ERROR [django.request:224] Internal Server Error: /contact/reminders/2/
Traceback (most recent call last):
  File "/home/lenovo/Envs/contact/local/lib/python2.7/site-packages/django/core/handlers/base.py", line 112, in get_response
    response = wrapped_callback(request, *callback_args, **callback_kwargs)
  File "/home/lenovo/Envs/contact/local/lib/python2.7/site-packages/django/views/generic/base.py", line 69, in view
    return self.dispatch(request, *args, **kwargs)
  File "/home/lenovo/Envs/contact/local/lib/python2.7/site-packages/django/views/decorators/csrf.py", line 57, in wrapped_view
    return view_func(*args, **kwargs)
  File "/home/lenovo/Envs/contact/local/lib/python2.7/site-packages/rest_framework/views.py", line 400, in dispatch
    response = self.handle_exception(exc)
  File "/home/lenovo/Envs/contact/local/lib/python2.7/site-packages/rest_framework/views.py", line 397, in dispatch
    response = handler(request, *args, **kwargs)
  File "/home/lenovo/projects/contact/reminder/views.py", line 46, in get
    return Response(get_active_reminders(cid))
  File "/home/lenovo/projects/contact/reminder/__init__.py", line 22, in get_active_reminders
    reminders.sort(key=lambda x:x.date)
AttributeError: 'QuerySet' object has no attribute 'sort'
[12/Aug/2014 10:20:31] ERROR [django.request:224] Internal Server Error: /inbox/refresh/
Traceback (most recent call last):
  File "/home/lenovo/Envs/contact/local/lib/python2.7/site-packages/django/core/handlers/base.py", line 112, in get_response
    response = wrapped_callback(request, *callback_args, **callback_kwargs)
  File "/home/lenovo/Envs/contact/local/lib/python2.7/site-packages/django/views/generic/base.py", line 69, in view
    return self.dispatch(request, *args, **kwargs)
  File "/home/lenovo/Envs/contact/local/lib/python2.7/site-packages/django/views/decorators/csrf.py", line 57, in wrapped_view
    return view_func(*args, **kwargs)
  File "/home/lenovo/Envs/contact/local/lib/python2.7/site-packages/rest_framework/views.py", line 400, in dispatch
    response = self.handle_exception(exc)
  File "/home/lenovo/Envs/contact/local/lib/python2.7/site-packages/rest_framework/views.py", line 397, in dispatch
    response = handler(request, *args, **kwargs)
  File "/home/lenovo/Envs/contact/local/lib/python2.7/site-packages/django/db/transaction.py", line 371, in inner
    return func(*args, **kwargs)
  File "/home/lenovo/projects/contact/gmail/views.py", line 35, in get
    in_import = InboxImport(user)
  File "/home/lenovo/projects/contact/gmail/parsers.py", line 17, in __init__
    self.service = Auth.get_gmail_srv(user)
  File "/home/lenovo/projects/contact/gmail/__init__.py", line 43, in get_gmail_srv
    return build('gmail', 'v1', http=http)
  File "/home/lenovo/Envs/contact/local/lib/python2.7/site-packages/oauth2client/util.py", line 132, in positional_wrapper
    return wrapped(*args, **kwargs)
  File "/home/lenovo/Envs/contact/local/lib/python2.7/site-packages/apiclient/discovery.py", line 192, in build
    resp, content = http.request(requested_url)
  File "/home/lenovo/Envs/contact/local/lib/python2.7/site-packages/oauth2client/util.py", line 132, in positional_wrapper
    return wrapped(*args, **kwargs)
  File "/home/lenovo/Envs/contact/local/lib/python2.7/site-packages/oauth2client/client.py", line 490, in new_request
    redirections, connection_type)
  File "/home/lenovo/Envs/contact/local/lib/python2.7/site-packages/httplib2/__init__.py", line 1593, in request
    (response, content) = self._request(conn, authority, uri, request_uri, method, body, headers, redirections, cachekey)
  File "/home/lenovo/Envs/contact/local/lib/python2.7/site-packages/httplib2/__init__.py", line 1335, in _request
    (response, content) = self._conn_request(conn, request_uri, method, body, headers)
  File "/home/lenovo/Envs/contact/local/lib/python2.7/site-packages/httplib2/__init__.py", line 1257, in _conn_request
    conn.connect()
  File "/home/lenovo/Envs/contact/local/lib/python2.7/site-packages/httplib2/__init__.py", line 1060, in connect
    raise socket.error, msg
error: [Errno 111] Connection refused
[12/Aug/2014 10:21:31] ERROR [django.request:224] Internal Server Error: /contact/reminders/2/
Traceback (most recent call last):
  File "/home/lenovo/Envs/contact/local/lib/python2.7/site-packages/django/core/handlers/base.py", line 112, in get_response
    response = wrapped_callback(request, *callback_args, **callback_kwargs)
  File "/home/lenovo/Envs/contact/local/lib/python2.7/site-packages/django/views/generic/base.py", line 69, in view
    return self.dispatch(request, *args, **kwargs)
  File "/home/lenovo/Envs/contact/local/lib/python2.7/site-packages/django/views/decorators/csrf.py", line 57, in wrapped_view
    return view_func(*args, **kwargs)
  File "/home/lenovo/Envs/contact/local/lib/python2.7/site-packages/rest_framework/views.py", line 400, in dispatch
    response = self.handle_exception(exc)
  File "/home/lenovo/Envs/contact/local/lib/python2.7/site-packages/rest_framework/views.py", line 397, in dispatch
    response = handler(request, *args, **kwargs)
  File "/home/lenovo/projects/contact/reminder/views.py", line 46, in get
    return Response(get_active_reminders(cid))
  File "/home/lenovo/projects/contact/reminder/__init__.py", line 22, in get_active_reminders
    reminders.sort(key=lambda x: x.date)
AttributeError: 'QuerySet' object has no attribute 'sort'
[12/Aug/2014 10:21:39] ERROR [django.request:224] Internal Server Error: /contact/reminders/2/
Traceback (most recent call last):
  File "/home/lenovo/Envs/contact/local/lib/python2.7/site-packages/django/core/handlers/base.py", line 112, in get_response
    response = wrapped_callback(request, *callback_args, **callback_kwargs)
  File "/home/lenovo/Envs/contact/local/lib/python2.7/site-packages/django/views/generic/base.py", line 69, in view
    return self.dispatch(request, *args, **kwargs)
  File "/home/lenovo/Envs/contact/local/lib/python2.7/site-packages/django/views/decorators/csrf.py", line 57, in wrapped_view
    return view_func(*args, **kwargs)
  File "/home/lenovo/Envs/contact/local/lib/python2.7/site-packages/rest_framework/views.py", line 400, in dispatch
    response = self.handle_exception(exc)
  File "/home/lenovo/Envs/contact/local/lib/python2.7/site-packages/rest_framework/views.py", line 397, in dispatch
    response = handler(request, *args, **kwargs)
  File "/home/lenovo/projects/contact/reminder/views.py", line 46, in get
    return Response(get_active_reminders(cid))
  File "/home/lenovo/projects/contact/reminder/__init__.py", line 22, in get_active_reminders
    reminders.sort(key=lambda x: x.date)
AttributeError: 'QuerySet' object has no attribute 'sort'
[12/Aug/2014 10:21:46] ERROR [django.request:224] Internal Server Error: /inbox/refresh/
Traceback (most recent call last):
  File "/home/lenovo/Envs/contact/local/lib/python2.7/site-packages/django/core/handlers/base.py", line 112, in get_response
    response = wrapped_callback(request, *callback_args, **callback_kwargs)
  File "/home/lenovo/Envs/contact/local/lib/python2.7/site-packages/django/views/generic/base.py", line 69, in view
    return self.dispatch(request, *args, **kwargs)
  File "/home/lenovo/Envs/contact/local/lib/python2.7/site-packages/django/views/decorators/csrf.py", line 57, in wrapped_view
    return view_func(*args, **kwargs)
  File "/home/lenovo/Envs/contact/local/lib/python2.7/site-packages/rest_framework/views.py", line 400, in dispatch
    response = self.handle_exception(exc)
  File "/home/lenovo/Envs/contact/local/lib/python2.7/site-packages/rest_framework/views.py", line 397, in dispatch
    response = handler(request, *args, **kwargs)
  File "/home/lenovo/Envs/contact/local/lib/python2.7/site-packages/django/db/transaction.py", line 371, in inner
    return func(*args, **kwargs)
  File "/home/lenovo/projects/contact/gmail/views.py", line 35, in get
    in_import = InboxImport(user)
  File "/home/lenovo/projects/contact/gmail/parsers.py", line 17, in __init__
    self.service = Auth.get_gmail_srv(user)
  File "/home/lenovo/projects/contact/gmail/__init__.py", line 43, in get_gmail_srv
    return build('gmail', 'v1', http=http)
  File "/home/lenovo/Envs/contact/local/lib/python2.7/site-packages/oauth2client/util.py", line 132, in positional_wrapper
    return wrapped(*args, **kwargs)
  File "/home/lenovo/Envs/contact/local/lib/python2.7/site-packages/apiclient/discovery.py", line 192, in build
    resp, content = http.request(requested_url)
  File "/home/lenovo/Envs/contact/local/lib/python2.7/site-packages/oauth2client/util.py", line 132, in positional_wrapper
    return wrapped(*args, **kwargs)
  File "/home/lenovo/Envs/contact/local/lib/python2.7/site-packages/oauth2client/client.py", line 490, in new_request
    redirections, connection_type)
  File "/home/lenovo/Envs/contact/local/lib/python2.7/site-packages/httplib2/__init__.py", line 1593, in request
    (response, content) = self._request(conn, authority, uri, request_uri, method, body, headers, redirections, cachekey)
  File "/home/lenovo/Envs/contact/local/lib/python2.7/site-packages/httplib2/__init__.py", line 1335, in _request
    (response, content) = self._conn_request(conn, request_uri, method, body, headers)
  File "/home/lenovo/Envs/contact/local/lib/python2.7/site-packages/httplib2/__init__.py", line 1257, in _conn_request
    conn.connect()
  File "/home/lenovo/Envs/contact/local/lib/python2.7/site-packages/httplib2/__init__.py", line 1060, in connect
    raise socket.error, msg
error: [Errno 111] Connection refused
[12/Aug/2014 10:21:53] ERROR [django.request:224] Internal Server Error: /inbox/refresh/
Traceback (most recent call last):
  File "/home/lenovo/Envs/contact/local/lib/python2.7/site-packages/django/core/handlers/base.py", line 112, in get_response
    response = wrapped_callback(request, *callback_args, **callback_kwargs)
  File "/home/lenovo/Envs/contact/local/lib/python2.7/site-packages/django/views/generic/base.py", line 69, in view
    return self.dispatch(request, *args, **kwargs)
  File "/home/lenovo/Envs/contact/local/lib/python2.7/site-packages/django/views/decorators/csrf.py", line 57, in wrapped_view
    return view_func(*args, **kwargs)
  File "/home/lenovo/Envs/contact/local/lib/python2.7/site-packages/rest_framework/views.py", line 400, in dispatch
    response = self.handle_exception(exc)
  File "/home/lenovo/Envs/contact/local/lib/python2.7/site-packages/rest_framework/views.py", line 397, in dispatch
    response = handler(request, *args, **kwargs)
  File "/home/lenovo/Envs/contact/local/lib/python2.7/site-packages/django/db/transaction.py", line 371, in inner
    return func(*args, **kwargs)
  File "/home/lenovo/projects/contact/gmail/views.py", line 35, in get
    in_import = InboxImport(user)
  File "/home/lenovo/projects/contact/gmail/parsers.py", line 17, in __init__
    self.service = Auth.get_gmail_srv(user)
  File "/home/lenovo/projects/contact/gmail/__init__.py", line 43, in get_gmail_srv
    return build('gmail', 'v1', http=http)
  File "/home/lenovo/Envs/contact/local/lib/python2.7/site-packages/oauth2client/util.py", line 132, in positional_wrapper
    return wrapped(*args, **kwargs)
  File "/home/lenovo/Envs/contact/local/lib/python2.7/site-packages/apiclient/discovery.py", line 192, in build
    resp, content = http.request(requested_url)
  File "/home/lenovo/Envs/contact/local/lib/python2.7/site-packages/oauth2client/util.py", line 132, in positional_wrapper
    return wrapped(*args, **kwargs)
  File "/home/lenovo/Envs/contact/local/lib/python2.7/site-packages/oauth2client/client.py", line 490, in new_request
    redirections, connection_type)
  File "/home/lenovo/Envs/contact/local/lib/python2.7/site-packages/httplib2/__init__.py", line 1593, in request
    (response, content) = self._request(conn, authority, uri, request_uri, method, body, headers, redirections, cachekey)
  File "/home/lenovo/Envs/contact/local/lib/python2.7/site-packages/httplib2/__init__.py", line 1335, in _request
    (response, content) = self._conn_request(conn, request_uri, method, body, headers)
  File "/home/lenovo/Envs/contact/local/lib/python2.7/site-packages/httplib2/__init__.py", line 1257, in _conn_request
    conn.connect()
  File "/home/lenovo/Envs/contact/local/lib/python2.7/site-packages/httplib2/__init__.py", line 1060, in connect
    raise socket.error, msg
error: [Errno 111] Connection refused
[12/Aug/2014 10:23:19] ERROR [django.request:224] Internal Server Error: /inbox/refresh/
Traceback (most recent call last):
  File "/home/lenovo/Envs/contact/local/lib/python2.7/site-packages/django/core/handlers/base.py", line 112, in get_response
    response = wrapped_callback(request, *callback_args, **callback_kwargs)
  File "/home/lenovo/Envs/contact/local/lib/python2.7/site-packages/django/views/generic/base.py", line 69, in view
    return self.dispatch(request, *args, **kwargs)
  File "/home/lenovo/Envs/contact/local/lib/python2.7/site-packages/django/views/decorators/csrf.py", line 57, in wrapped_view
    return view_func(*args, **kwargs)
  File "/home/lenovo/Envs/contact/local/lib/python2.7/site-packages/rest_framework/views.py", line 400, in dispatch
    response = self.handle_exception(exc)
  File "/home/lenovo/Envs/contact/local/lib/python2.7/site-packages/rest_framework/views.py", line 397, in dispatch
    response = handler(request, *args, **kwargs)
  File "/home/lenovo/Envs/contact/local/lib/python2.7/site-packages/django/db/transaction.py", line 371, in inner
    return func(*args, **kwargs)
  File "/home/lenovo/projects/contact/gmail/views.py", line 35, in get
    in_import = InboxImport(user)
  File "/home/lenovo/projects/contact/gmail/parsers.py", line 17, in __init__
    self.service = Auth.get_gmail_srv(user)
  File "/home/lenovo/projects/contact/gmail/__init__.py", line 43, in get_gmail_srv
    return build('gmail', 'v1', http=http)
  File "/home/lenovo/Envs/contact/local/lib/python2.7/site-packages/oauth2client/util.py", line 132, in positional_wrapper
    return wrapped(*args, **kwargs)
  File "/home/lenovo/Envs/contact/local/lib/python2.7/site-packages/apiclient/discovery.py", line 192, in build
    resp, content = http.request(requested_url)
  File "/home/lenovo/Envs/contact/local/lib/python2.7/site-packages/oauth2client/util.py", line 132, in positional_wrapper
    return wrapped(*args, **kwargs)
  File "/home/lenovo/Envs/contact/local/lib/python2.7/site-packages/oauth2client/client.py", line 490, in new_request
    redirections, connection_type)
  File "/home/lenovo/Envs/contact/local/lib/python2.7/site-packages/httplib2/__init__.py", line 1593, in request
    (response, content) = self._request(conn, authority, uri, request_uri, method, body, headers, redirections, cachekey)
  File "/home/lenovo/Envs/contact/local/lib/python2.7/site-packages/httplib2/__init__.py", line 1335, in _request
    (response, content) = self._conn_request(conn, request_uri, method, body, headers)
  File "/home/lenovo/Envs/contact/local/lib/python2.7/site-packages/httplib2/__init__.py", line 1257, in _conn_request
    conn.connect()
  File "/home/lenovo/Envs/contact/local/lib/python2.7/site-packages/httplib2/__init__.py", line 1060, in connect
    raise socket.error, msg
error: [Errno 111] Connection refused
[12/Aug/2014 10:24:16] ERROR [django.request:224] Internal Server Error: /inbox/refresh/
Traceback (most recent call last):
  File "/home/lenovo/Envs/contact/local/lib/python2.7/site-packages/django/core/handlers/base.py", line 112, in get_response
    response = wrapped_callback(request, *callback_args, **callback_kwargs)
  File "/home/lenovo/Envs/contact/local/lib/python2.7/site-packages/django/views/generic/base.py", line 69, in view
    return self.dispatch(request, *args, **kwargs)
  File "/home/lenovo/Envs/contact/local/lib/python2.7/site-packages/django/views/decorators/csrf.py", line 57, in wrapped_view
    return view_func(*args, **kwargs)
  File "/home/lenovo/Envs/contact/local/lib/python2.7/site-packages/rest_framework/views.py", line 400, in dispatch
    response = self.handle_exception(exc)
  File "/home/lenovo/Envs/contact/local/lib/python2.7/site-packages/rest_framework/views.py", line 397, in dispatch
    response = handler(request, *args, **kwargs)
  File "/home/lenovo/Envs/contact/local/lib/python2.7/site-packages/django/db/transaction.py", line 371, in inner
    return func(*args, **kwargs)
  File "/home/lenovo/projects/contact/gmail/views.py", line 35, in get
    in_import = InboxImport(user)
  File "/home/lenovo/projects/contact/gmail/parsers.py", line 17, in __init__
    self.service = Auth.get_gmail_srv(user)
  File "/home/lenovo/projects/contact/gmail/__init__.py", line 43, in get_gmail_srv
    return build('gmail', 'v1', http=http)
  File "/home/lenovo/Envs/contact/local/lib/python2.7/site-packages/oauth2client/util.py", line 132, in positional_wrapper
    return wrapped(*args, **kwargs)
  File "/home/lenovo/Envs/contact/local/lib/python2.7/site-packages/apiclient/discovery.py", line 192, in build
    resp, content = http.request(requested_url)
  File "/home/lenovo/Envs/contact/local/lib/python2.7/site-packages/oauth2client/util.py", line 132, in positional_wrapper
    return wrapped(*args, **kwargs)
  File "/home/lenovo/Envs/contact/local/lib/python2.7/site-packages/oauth2client/client.py", line 490, in new_request
    redirections, connection_type)
  File "/home/lenovo/Envs/contact/local/lib/python2.7/site-packages/httplib2/__init__.py", line 1593, in request
    (response, content) = self._request(conn, authority, uri, request_uri, method, body, headers, redirections, cachekey)
  File "/home/lenovo/Envs/contact/local/lib/python2.7/site-packages/httplib2/__init__.py", line 1335, in _request
    (response, content) = self._conn_request(conn, request_uri, method, body, headers)
  File "/home/lenovo/Envs/contact/local/lib/python2.7/site-packages/httplib2/__init__.py", line 1257, in _conn_request
    conn.connect()
  File "/home/lenovo/Envs/contact/local/lib/python2.7/site-packages/httplib2/__init__.py", line 1060, in connect
    raise socket.error, msg
error: [Errno 111] Connection refused
[12/Aug/2014 10:25:38] ERROR [django.request:224] Internal Server Error: /inbox/refresh/
Traceback (most recent call last):
  File "/home/lenovo/Envs/contact/local/lib/python2.7/site-packages/django/core/handlers/base.py", line 112, in get_response
    response = wrapped_callback(request, *callback_args, **callback_kwargs)
  File "/home/lenovo/Envs/contact/local/lib/python2.7/site-packages/django/views/generic/base.py", line 69, in view
    return self.dispatch(request, *args, **kwargs)
  File "/home/lenovo/Envs/contact/local/lib/python2.7/site-packages/django/views/decorators/csrf.py", line 57, in wrapped_view
    return view_func(*args, **kwargs)
  File "/home/lenovo/Envs/contact/local/lib/python2.7/site-packages/rest_framework/views.py", line 400, in dispatch
    response = self.handle_exception(exc)
  File "/home/lenovo/Envs/contact/local/lib/python2.7/site-packages/rest_framework/views.py", line 397, in dispatch
    response = handler(request, *args, **kwargs)
  File "/home/lenovo/Envs/contact/local/lib/python2.7/site-packages/django/db/transaction.py", line 371, in inner
    return func(*args, **kwargs)
  File "/home/lenovo/projects/contact/gmail/views.py", line 35, in get
    in_import = InboxImport(user)
  File "/home/lenovo/projects/contact/gmail/parsers.py", line 17, in __init__
    self.service = Auth.get_gmail_srv(user)
  File "/home/lenovo/projects/contact/gmail/__init__.py", line 43, in get_gmail_srv
    return build('gmail', 'v1', http=http)
  File "/home/lenovo/Envs/contact/local/lib/python2.7/site-packages/oauth2client/util.py", line 132, in positional_wrapper
    return wrapped(*args, **kwargs)
  File "/home/lenovo/Envs/contact/local/lib/python2.7/site-packages/apiclient/discovery.py", line 192, in build
    resp, content = http.request(requested_url)
  File "/home/lenovo/Envs/contact/local/lib/python2.7/site-packages/oauth2client/util.py", line 132, in positional_wrapper
    return wrapped(*args, **kwargs)
  File "/home/lenovo/Envs/contact/local/lib/python2.7/site-packages/oauth2client/client.py", line 490, in new_request
    redirections, connection_type)
  File "/home/lenovo/Envs/contact/local/lib/python2.7/site-packages/httplib2/__init__.py", line 1593, in request
    (response, content) = self._request(conn, authority, uri, request_uri, method, body, headers, redirections, cachekey)
  File "/home/lenovo/Envs/contact/local/lib/python2.7/site-packages/httplib2/__init__.py", line 1335, in _request
    (response, content) = self._conn_request(conn, request_uri, method, body, headers)
  File "/home/lenovo/Envs/contact/local/lib/python2.7/site-packages/httplib2/__init__.py", line 1257, in _conn_request
    conn.connect()
  File "/home/lenovo/Envs/contact/local/lib/python2.7/site-packages/httplib2/__init__.py", line 1060, in connect
    raise socket.error, msg
error: [Errno 111] Connection refused
[12/Aug/2014 10:30:06] ERROR [django.request:224] Internal Server Error: /inbox/refresh/
Traceback (most recent call last):
  File "/home/lenovo/Envs/contact/local/lib/python2.7/site-packages/django/core/handlers/base.py", line 112, in get_response
    response = wrapped_callback(request, *callback_args, **callback_kwargs)
  File "/home/lenovo/Envs/contact/local/lib/python2.7/site-packages/django/views/generic/base.py", line 69, in view
    return self.dispatch(request, *args, **kwargs)
  File "/home/lenovo/Envs/contact/local/lib/python2.7/site-packages/django/views/decorators/csrf.py", line 57, in wrapped_view
    return view_func(*args, **kwargs)
  File "/home/lenovo/Envs/contact/local/lib/python2.7/site-packages/rest_framework/views.py", line 400, in dispatch
    response = self.handle_exception(exc)
  File "/home/lenovo/Envs/contact/local/lib/python2.7/site-packages/rest_framework/views.py", line 397, in dispatch
    response = handler(request, *args, **kwargs)
  File "/home/lenovo/Envs/contact/local/lib/python2.7/site-packages/django/db/transaction.py", line 371, in inner
    return func(*args, **kwargs)
  File "/home/lenovo/projects/contact/gmail/views.py", line 35, in get
    in_import = InboxImport(user)
  File "/home/lenovo/projects/contact/gmail/parsers.py", line 17, in __init__
    self.service = Auth.get_gmail_srv(user)
  File "/home/lenovo/projects/contact/gmail/__init__.py", line 43, in get_gmail_srv
    return build('gmail', 'v1', http=http)
  File "/home/lenovo/Envs/contact/local/lib/python2.7/site-packages/oauth2client/util.py", line 132, in positional_wrapper
    return wrapped(*args, **kwargs)
  File "/home/lenovo/Envs/contact/local/lib/python2.7/site-packages/apiclient/discovery.py", line 192, in build
    resp, content = http.request(requested_url)
  File "/home/lenovo/Envs/contact/local/lib/python2.7/site-packages/oauth2client/util.py", line 132, in positional_wrapper
    return wrapped(*args, **kwargs)
  File "/home/lenovo/Envs/contact/local/lib/python2.7/site-packages/oauth2client/client.py", line 490, in new_request
    redirections, connection_type)
  File "/home/lenovo/Envs/contact/local/lib/python2.7/site-packages/httplib2/__init__.py", line 1593, in request
    (response, content) = self._request(conn, authority, uri, request_uri, method, body, headers, redirections, cachekey)
  File "/home/lenovo/Envs/contact/local/lib/python2.7/site-packages/httplib2/__init__.py", line 1335, in _request
    (response, content) = self._conn_request(conn, request_uri, method, body, headers)
  File "/home/lenovo/Envs/contact/local/lib/python2.7/site-packages/httplib2/__init__.py", line 1257, in _conn_request
    conn.connect()
  File "/home/lenovo/Envs/contact/local/lib/python2.7/site-packages/httplib2/__init__.py", line 1060, in connect
    raise socket.error, msg
error: [Errno 111] Connection refused
[12/Aug/2014 10:34:49] ERROR [django.request:224] Internal Server Error: /inbox/refresh/
Traceback (most recent call last):
  File "/home/lenovo/Envs/contact/local/lib/python2.7/site-packages/django/core/handlers/base.py", line 112, in get_response
    response = wrapped_callback(request, *callback_args, **callback_kwargs)
  File "/home/lenovo/Envs/contact/local/lib/python2.7/site-packages/django/views/generic/base.py", line 69, in view
    return self.dispatch(request, *args, **kwargs)
  File "/home/lenovo/Envs/contact/local/lib/python2.7/site-packages/django/views/decorators/csrf.py", line 57, in wrapped_view
    return view_func(*args, **kwargs)
  File "/home/lenovo/Envs/contact/local/lib/python2.7/site-packages/rest_framework/views.py", line 400, in dispatch
    response = self.handle_exception(exc)
  File "/home/lenovo/Envs/contact/local/lib/python2.7/site-packages/rest_framework/views.py", line 397, in dispatch
    response = handler(request, *args, **kwargs)
  File "/home/lenovo/Envs/contact/local/lib/python2.7/site-packages/django/db/transaction.py", line 371, in inner
    return func(*args, **kwargs)
  File "/home/lenovo/projects/contact/gmail/views.py", line 35, in get
    in_import = InboxImport(user)
  File "/home/lenovo/projects/contact/gmail/parsers.py", line 17, in __init__
    self.service = Auth.get_gmail_srv(user)
  File "/home/lenovo/projects/contact/gmail/__init__.py", line 43, in get_gmail_srv
    return build('gmail', 'v1', http=http)
  File "/home/lenovo/Envs/contact/local/lib/python2.7/site-packages/oauth2client/util.py", line 132, in positional_wrapper
    return wrapped(*args, **kwargs)
  File "/home/lenovo/Envs/contact/local/lib/python2.7/site-packages/apiclient/discovery.py", line 192, in build
    resp, content = http.request(requested_url)
  File "/home/lenovo/Envs/contact/local/lib/python2.7/site-packages/oauth2client/util.py", line 132, in positional_wrapper
    return wrapped(*args, **kwargs)
  File "/home/lenovo/Envs/contact/local/lib/python2.7/site-packages/oauth2client/client.py", line 490, in new_request
    redirections, connection_type)
  File "/home/lenovo/Envs/contact/local/lib/python2.7/site-packages/httplib2/__init__.py", line 1593, in request
    (response, content) = self._request(conn, authority, uri, request_uri, method, body, headers, redirections, cachekey)
  File "/home/lenovo/Envs/contact/local/lib/python2.7/site-packages/httplib2/__init__.py", line 1335, in _request
    (response, content) = self._conn_request(conn, request_uri, method, body, headers)
  File "/home/lenovo/Envs/contact/local/lib/python2.7/site-packages/httplib2/__init__.py", line 1257, in _conn_request
    conn.connect()
  File "/home/lenovo/Envs/contact/local/lib/python2.7/site-packages/httplib2/__init__.py", line 1060, in connect
    raise socket.error, msg
error: [Errno 111] Connection refused
[12/Aug/2014 10:50:15] WARNING [django.request:143] Not Found: /reminders/
[12/Aug/2014 11:15:55] ERROR [django.request:224] Internal Server Error: /reminders/
Traceback (most recent call last):
  File "/home/lenovo/Envs/contact/local/lib/python2.7/site-packages/django/core/handlers/base.py", line 137, in get_response
    response = response.render()
  File "/home/lenovo/Envs/contact/local/lib/python2.7/site-packages/django/template/response.py", line 105, in render
    self.content = self.rendered_content
  File "/home/lenovo/Envs/contact/local/lib/python2.7/site-packages/rest_framework/response.py", line 59, in rendered_content
    ret = renderer.render(self.data, media_type, context)
  File "/home/lenovo/Envs/contact/local/lib/python2.7/site-packages/rest_framework/renderers.py", line 600, in render
    template = loader.get_template(self.template)
  File "/home/lenovo/Envs/contact/local/lib/python2.7/site-packages/django/template/loader.py", line 138, in get_template
    template, origin = find_template(template_name)
  File "/home/lenovo/Envs/contact/local/lib/python2.7/site-packages/django/template/loader.py", line 131, in find_template
    raise TemplateDoesNotExist(name)
TemplateDoesNotExist: rest_framework/api.html
[12/Aug/2014 11:16:21] ERROR [django.request:224] Internal Server Error: /reminders/
Traceback (most recent call last):
  File "/home/lenovo/Envs/contact/local/lib/python2.7/site-packages/django/core/handlers/base.py", line 112, in get_response
    response = wrapped_callback(request, *callback_args, **callback_kwargs)
  File "/home/lenovo/Envs/contact/local/lib/python2.7/site-packages/django/views/generic/base.py", line 69, in view
    return self.dispatch(request, *args, **kwargs)
  File "/home/lenovo/Envs/contact/local/lib/python2.7/site-packages/django/views/decorators/csrf.py", line 57, in wrapped_view
    return view_func(*args, **kwargs)
  File "/home/lenovo/Envs/contact/local/lib/python2.7/site-packages/rest_framework/views.py", line 400, in dispatch
    response = self.handle_exception(exc)
  File "/home/lenovo/Envs/contact/local/lib/python2.7/site-packages/rest_framework/views.py", line 397, in dispatch
    response = handler(request, *args, **kwargs)
TypeError: get() takes exactly 3 arguments (2 given)
[12/Aug/2014 11:16:40] ERROR [django.request:224] Internal Server Error: /reminders/
Traceback (most recent call last):
  File "/home/lenovo/Envs/contact/local/lib/python2.7/site-packages/django/core/handlers/base.py", line 112, in get_response
    response = wrapped_callback(request, *callback_args, **callback_kwargs)
  File "/home/lenovo/Envs/contact/local/lib/python2.7/site-packages/django/views/generic/base.py", line 69, in view
    return self.dispatch(request, *args, **kwargs)
  File "/home/lenovo/Envs/contact/local/lib/python2.7/site-packages/django/views/decorators/csrf.py", line 57, in wrapped_view
    return view_func(*args, **kwargs)
  File "/home/lenovo/Envs/contact/local/lib/python2.7/site-packages/rest_framework/views.py", line 400, in dispatch
    response = self.handle_exception(exc)
  File "/home/lenovo/Envs/contact/local/lib/python2.7/site-packages/rest_framework/views.py", line 397, in dispatch
    response = handler(request, *args, **kwargs)
  File "/home/lenovo/projects/contact/reminder/views.py", line 53, in get
    reminders = [r for c in user.contact_set for r in c.reminder_set]
  File "/home/lenovo/Envs/contact/local/lib/python2.7/site-packages/django/utils/functional.py", line 214, in inner
    return func(self._wrapped, *args)
AttributeError: 'MyUser' object has no attribute 'contact_set'
[12/Aug/2014 11:17:19] ERROR [django.request:224] Internal Server Error: /reminders/
Traceback (most recent call last):
  File "/home/lenovo/Envs/contact/local/lib/python2.7/site-packages/django/core/handlers/base.py", line 112, in get_response
    response = wrapped_callback(request, *callback_args, **callback_kwargs)
  File "/home/lenovo/Envs/contact/local/lib/python2.7/site-packages/django/views/generic/base.py", line 69, in view
    return self.dispatch(request, *args, **kwargs)
  File "/home/lenovo/Envs/contact/local/lib/python2.7/site-packages/django/views/decorators/csrf.py", line 57, in wrapped_view
    return view_func(*args, **kwargs)
  File "/home/lenovo/Envs/contact/local/lib/python2.7/site-packages/rest_framework/views.py", line 400, in dispatch
    response = self.handle_exception(exc)
  File "/home/lenovo/Envs/contact/local/lib/python2.7/site-packages/rest_framework/views.py", line 397, in dispatch
    response = handler(request, *args, **kwargs)
  File "/home/lenovo/projects/contact/reminder/views.py", line 53, in get
    reminders = [r for c in user.usercontact_set for r in c.reminder_set]
TypeError: 'RelatedManager' object is not iterable
[12/Aug/2014 11:17:27] ERROR [django.request:224] Internal Server Error: /reminders/
Traceback (most recent call last):
  File "/home/lenovo/Envs/contact/local/lib/python2.7/site-packages/django/core/handlers/base.py", line 112, in get_response
    response = wrapped_callback(request, *callback_args, **callback_kwargs)
  File "/home/lenovo/Envs/contact/local/lib/python2.7/site-packages/django/views/generic/base.py", line 69, in view
    return self.dispatch(request, *args, **kwargs)
  File "/home/lenovo/Envs/contact/local/lib/python2.7/site-packages/django/views/decorators/csrf.py", line 57, in wrapped_view
    return view_func(*args, **kwargs)
  File "/home/lenovo/Envs/contact/local/lib/python2.7/site-packages/rest_framework/views.py", line 400, in dispatch
    response = self.handle_exception(exc)
  File "/home/lenovo/Envs/contact/local/lib/python2.7/site-packages/rest_framework/views.py", line 397, in dispatch
    response = handler(request, *args, **kwargs)
  File "/home/lenovo/projects/contact/reminder/views.py", line 53, in get
    reminders = [r for c in user.usercontact_set for r in c.reminder_set]
TypeError: 'RelatedManager' object is not iterable
[12/Aug/2014 11:17:49] ERROR [django.request:224] Internal Server Error: /reminders/
Traceback (most recent call last):
  File "/home/lenovo/Envs/contact/local/lib/python2.7/site-packages/django/core/handlers/base.py", line 137, in get_response
    response = response.render()
  File "/home/lenovo/Envs/contact/local/lib/python2.7/site-packages/django/template/response.py", line 105, in render
    self.content = self.rendered_content
  File "/home/lenovo/Envs/contact/local/lib/python2.7/site-packages/rest_framework/response.py", line 59, in rendered_content
    ret = renderer.render(self.data, media_type, context)
  File "/home/lenovo/Envs/contact/local/lib/python2.7/site-packages/rest_framework/renderers.py", line 600, in render
    template = loader.get_template(self.template)
  File "/home/lenovo/Envs/contact/local/lib/python2.7/site-packages/django/template/loader.py", line 138, in get_template
    template, origin = find_template(template_name)
  File "/home/lenovo/Envs/contact/local/lib/python2.7/site-packages/django/template/loader.py", line 131, in find_template
    raise TemplateDoesNotExist(name)
TemplateDoesNotExist: rest_framework/api.html
[12/Aug/2014 11:23:13] ERROR [django.request:224] Internal Server Error: /reminders/
Traceback (most recent call last):
  File "/home/lenovo/Envs/contact/local/lib/python2.7/site-packages/django/core/handlers/base.py", line 112, in get_response
    response = wrapped_callback(request, *callback_args, **callback_kwargs)
  File "/home/lenovo/Envs/contact/local/lib/python2.7/site-packages/django/views/generic/base.py", line 69, in view
    return self.dispatch(request, *args, **kwargs)
  File "/home/lenovo/Envs/contact/local/lib/python2.7/site-packages/django/views/decorators/csrf.py", line 57, in wrapped_view
    return view_func(*args, **kwargs)
  File "/home/lenovo/Envs/contact/local/lib/python2.7/site-packages/rest_framework/views.py", line 400, in dispatch
    response = self.handle_exception(exc)
  File "/home/lenovo/Envs/contact/local/lib/python2.7/site-packages/rest_framework/views.py", line 397, in dispatch
    response = handler(request, *args, **kwargs)
  File "/home/lenovo/projects/contact/reminder/views.py", line 55, in get
    return Response(slz.data)
  File "/home/lenovo/Envs/contact/local/lib/python2.7/site-packages/rest_framework/serializers.py", line 573, in data
    self._data = [self.to_native(item) for item in obj]
  File "/home/lenovo/Envs/contact/local/lib/python2.7/site-packages/rest_framework/serializers.py", line 351, in to_native
    value = field.field_to_native(obj, field_name)
  File "/home/lenovo/Envs/contact/local/lib/python2.7/site-packages/rest_framework/fields.py", line 1035, in field_to_native
    value = getattr(self.parent, self.method_name)(obj)
  File "/home/lenovo/projects/contact/reminder/serializers.py", line 16, in get_name
    return len(obj.usercontact.name)
AttributeError: 'Reminder' object has no attribute 'usercontact'
[12/Aug/2014 11:23:14] ERROR [django.request:224] Internal Server Error: /contact/reminders/2/
Traceback (most recent call last):
  File "/home/lenovo/Envs/contact/local/lib/python2.7/site-packages/django/core/handlers/base.py", line 112, in get_response
    response = wrapped_callback(request, *callback_args, **callback_kwargs)
  File "/home/lenovo/Envs/contact/local/lib/python2.7/site-packages/django/views/generic/base.py", line 69, in view
    return self.dispatch(request, *args, **kwargs)
  File "/home/lenovo/Envs/contact/local/lib/python2.7/site-packages/django/views/decorators/csrf.py", line 57, in wrapped_view
    return view_func(*args, **kwargs)
  File "/home/lenovo/Envs/contact/local/lib/python2.7/site-packages/rest_framework/views.py", line 400, in dispatch
    response = self.handle_exception(exc)
  File "/home/lenovo/Envs/contact/local/lib/python2.7/site-packages/rest_framework/views.py", line 397, in dispatch
    response = handler(request, *args, **kwargs)
  File "/home/lenovo/projects/contact/reminder/views.py", line 46, in get
    return Response(get_active_reminders(cid))
  File "/home/lenovo/projects/contact/reminder/__init__.py", line 24, in get_active_reminders
    return slz.data
  File "/home/lenovo/Envs/contact/local/lib/python2.7/site-packages/rest_framework/serializers.py", line 573, in data
    self._data = [self.to_native(item) for item in obj]
  File "/home/lenovo/Envs/contact/local/lib/python2.7/site-packages/rest_framework/serializers.py", line 351, in to_native
    value = field.field_to_native(obj, field_name)
  File "/home/lenovo/Envs/contact/local/lib/python2.7/site-packages/rest_framework/fields.py", line 1035, in field_to_native
    value = getattr(self.parent, self.method_name)(obj)
  File "/home/lenovo/projects/contact/reminder/serializers.py", line 16, in get_name
    return len(obj.usercontact.name)
AttributeError: 'Reminder' object has no attribute 'usercontact'
[12/Aug/2014 11:23:22] ERROR [django.request:224] Internal Server Error: /reminders/
Traceback (most recent call last):
  File "/home/lenovo/Envs/contact/local/lib/python2.7/site-packages/django/core/handlers/base.py", line 112, in get_response
    response = wrapped_callback(request, *callback_args, **callback_kwargs)
  File "/home/lenovo/Envs/contact/local/lib/python2.7/site-packages/django/views/generic/base.py", line 69, in view
    return self.dispatch(request, *args, **kwargs)
  File "/home/lenovo/Envs/contact/local/lib/python2.7/site-packages/django/views/decorators/csrf.py", line 57, in wrapped_view
    return view_func(*args, **kwargs)
  File "/home/lenovo/Envs/contact/local/lib/python2.7/site-packages/rest_framework/views.py", line 400, in dispatch
    response = self.handle_exception(exc)
  File "/home/lenovo/Envs/contact/local/lib/python2.7/site-packages/rest_framework/views.py", line 397, in dispatch
    response = handler(request, *args, **kwargs)
  File "/home/lenovo/projects/contact/reminder/views.py", line 55, in get
    return Response(slz.data)
  File "/home/lenovo/Envs/contact/local/lib/python2.7/site-packages/rest_framework/serializers.py", line 573, in data
    self._data = [self.to_native(item) for item in obj]
  File "/home/lenovo/Envs/contact/local/lib/python2.7/site-packages/rest_framework/serializers.py", line 351, in to_native
    value = field.field_to_native(obj, field_name)
  File "/home/lenovo/Envs/contact/local/lib/python2.7/site-packages/rest_framework/fields.py", line 1035, in field_to_native
    value = getattr(self.parent, self.method_name)(obj)
  File "/home/lenovo/projects/contact/reminder/serializers.py", line 16, in get_name
    return len(obj.usercontact.name)
AttributeError: 'Reminder' object has no attribute 'usercontact'
[12/Aug/2014 11:23:23] ERROR [django.request:224] Internal Server Error: /contact/reminders/2/
Traceback (most recent call last):
  File "/home/lenovo/Envs/contact/local/lib/python2.7/site-packages/django/core/handlers/base.py", line 112, in get_response
    response = wrapped_callback(request, *callback_args, **callback_kwargs)
  File "/home/lenovo/Envs/contact/local/lib/python2.7/site-packages/django/views/generic/base.py", line 69, in view
    return self.dispatch(request, *args, **kwargs)
  File "/home/lenovo/Envs/contact/local/lib/python2.7/site-packages/django/views/decorators/csrf.py", line 57, in wrapped_view
    return view_func(*args, **kwargs)
  File "/home/lenovo/Envs/contact/local/lib/python2.7/site-packages/rest_framework/views.py", line 400, in dispatch
    response = self.handle_exception(exc)
  File "/home/lenovo/Envs/contact/local/lib/python2.7/site-packages/rest_framework/views.py", line 397, in dispatch
    response = handler(request, *args, **kwargs)
  File "/home/lenovo/projects/contact/reminder/views.py", line 46, in get
    return Response(get_active_reminders(cid))
  File "/home/lenovo/projects/contact/reminder/__init__.py", line 24, in get_active_reminders
    return slz.data
  File "/home/lenovo/Envs/contact/local/lib/python2.7/site-packages/rest_framework/serializers.py", line 573, in data
    self._data = [self.to_native(item) for item in obj]
  File "/home/lenovo/Envs/contact/local/lib/python2.7/site-packages/rest_framework/serializers.py", line 351, in to_native
    value = field.field_to_native(obj, field_name)
  File "/home/lenovo/Envs/contact/local/lib/python2.7/site-packages/rest_framework/fields.py", line 1035, in field_to_native
    value = getattr(self.parent, self.method_name)(obj)
  File "/home/lenovo/projects/contact/reminder/serializers.py", line 16, in get_name
    return len(obj.usercontact.name)
AttributeError: 'Reminder' object has no attribute 'usercontact'
[12/Aug/2014 11:24:18] ERROR [django.request:224] Internal Server Error: /reminders/
Traceback (most recent call last):
  File "/home/lenovo/Envs/contact/local/lib/python2.7/site-packages/django/core/handlers/base.py", line 112, in get_response
    response = wrapped_callback(request, *callback_args, **callback_kwargs)
  File "/home/lenovo/Envs/contact/local/lib/python2.7/site-packages/django/views/generic/base.py", line 69, in view
    return self.dispatch(request, *args, **kwargs)
  File "/home/lenovo/Envs/contact/local/lib/python2.7/site-packages/django/views/decorators/csrf.py", line 57, in wrapped_view
    return view_func(*args, **kwargs)
  File "/home/lenovo/Envs/contact/local/lib/python2.7/site-packages/rest_framework/views.py", line 400, in dispatch
    response = self.handle_exception(exc)
  File "/home/lenovo/Envs/contact/local/lib/python2.7/site-packages/rest_framework/views.py", line 397, in dispatch
    response = handler(request, *args, **kwargs)
  File "/home/lenovo/projects/contact/reminder/views.py", line 55, in get
    return Response(slz.data)
  File "/home/lenovo/Envs/contact/local/lib/python2.7/site-packages/rest_framework/serializers.py", line 573, in data
    self._data = [self.to_native(item) for item in obj]
  File "/home/lenovo/Envs/contact/local/lib/python2.7/site-packages/rest_framework/serializers.py", line 351, in to_native
    value = field.field_to_native(obj, field_name)
  File "/home/lenovo/Envs/contact/local/lib/python2.7/site-packages/rest_framework/fields.py", line 1035, in field_to_native
    value = getattr(self.parent, self.method_name)(obj)
  File "/home/lenovo/projects/contact/reminder/serializers.py", line 16, in get_name
    return len(obj.user_contact.name)
AttributeError: 'Reminder' object has no attribute 'user_contact'
[12/Aug/2014 11:24:19] ERROR [django.request:224] Internal Server Error: /contact/reminders/2/
Traceback (most recent call last):
  File "/home/lenovo/Envs/contact/local/lib/python2.7/site-packages/django/core/handlers/base.py", line 112, in get_response
    response = wrapped_callback(request, *callback_args, **callback_kwargs)
  File "/home/lenovo/Envs/contact/local/lib/python2.7/site-packages/django/views/generic/base.py", line 69, in view
    return self.dispatch(request, *args, **kwargs)
  File "/home/lenovo/Envs/contact/local/lib/python2.7/site-packages/django/views/decorators/csrf.py", line 57, in wrapped_view
    return view_func(*args, **kwargs)
  File "/home/lenovo/Envs/contact/local/lib/python2.7/site-packages/rest_framework/views.py", line 400, in dispatch
    response = self.handle_exception(exc)
  File "/home/lenovo/Envs/contact/local/lib/python2.7/site-packages/rest_framework/views.py", line 397, in dispatch
    response = handler(request, *args, **kwargs)
  File "/home/lenovo/projects/contact/reminder/views.py", line 46, in get
    return Response(get_active_reminders(cid))
  File "/home/lenovo/projects/contact/reminder/__init__.py", line 24, in get_active_reminders
    return slz.data
  File "/home/lenovo/Envs/contact/local/lib/python2.7/site-packages/rest_framework/serializers.py", line 573, in data
    self._data = [self.to_native(item) for item in obj]
  File "/home/lenovo/Envs/contact/local/lib/python2.7/site-packages/rest_framework/serializers.py", line 351, in to_native
    value = field.field_to_native(obj, field_name)
  File "/home/lenovo/Envs/contact/local/lib/python2.7/site-packages/rest_framework/fields.py", line 1035, in field_to_native
    value = getattr(self.parent, self.method_name)(obj)
  File "/home/lenovo/projects/contact/reminder/serializers.py", line 16, in get_name
    return len(obj.user_contact.name)
AttributeError: 'Reminder' object has no attribute 'user_contact'
[13/Aug/2014 04:29:51] WARNING [django.request:143] Not Found: /favicon.ico
[13/Aug/2014 05:24:57] WARNING [django.request:143] Not Found: /rcategorys/toggle/
[13/Aug/2014 05:25:54] ERROR [django.request:224] Internal Server Error: /rcategory/toggle/
Traceback (most recent call last):
  File "/home/lenovo/Envs/contact/local/lib/python2.7/site-packages/django/core/handlers/base.py", line 112, in get_response
    response = wrapped_callback(request, *callback_args, **callback_kwargs)
  File "/home/lenovo/Envs/contact/local/lib/python2.7/site-packages/django/views/generic/base.py", line 69, in view
    return self.dispatch(request, *args, **kwargs)
  File "/home/lenovo/Envs/contact/local/lib/python2.7/site-packages/django/views/generic/base.py", line 87, in dispatch
    return handler(request, *args, **kwargs)
  File "/home/lenovo/projects/contact/zone/views.py", line 32, in post
    ctgrys = [rc for rc in user.removedcategory_set.all() if rc.name == ctgry]
  File "/home/lenovo/Envs/contact/local/lib/python2.7/site-packages/django/db/models/query.py", line 96, in __iter__
    self._fetch_all()
  File "/home/lenovo/Envs/contact/local/lib/python2.7/site-packages/django/db/models/query.py", line 857, in _fetch_all
    self._result_cache = list(self.iterator())
  File "/home/lenovo/Envs/contact/local/lib/python2.7/site-packages/django/db/models/query.py", line 220, in iterator
    for row in compiler.results_iter():
  File "/home/lenovo/Envs/contact/local/lib/python2.7/site-packages/django/db/models/sql/compiler.py", line 713, in results_iter
    for rows in self.execute_sql(MULTI):
  File "/home/lenovo/Envs/contact/local/lib/python2.7/site-packages/django/db/models/sql/compiler.py", line 786, in execute_sql
    cursor.execute(sql, params)
  File "/home/lenovo/Envs/contact/local/lib/python2.7/site-packages/django/db/backends/util.py", line 69, in execute
    return super(CursorDebugWrapper, self).execute(sql, params)
  File "/home/lenovo/Envs/contact/local/lib/python2.7/site-packages/django/db/backends/util.py", line 53, in execute
    return self.cursor.execute(sql, params)
  File "/home/lenovo/Envs/contact/local/lib/python2.7/site-packages/django/db/utils.py", line 99, in __exit__
    six.reraise(dj_exc_type, dj_exc_value, traceback)
  File "/home/lenovo/Envs/contact/local/lib/python2.7/site-packages/django/db/backends/util.py", line 53, in execute
    return self.cursor.execute(sql, params)
ProgrammingError: relation "zone_removedcategory" does not exist
LINE 1: ...ry"."name", "zone_removedcategory"."user_id" FROM "zone_remo...
                                                             ^

[13/Aug/2014 05:32:42] ERROR [django.request:224] Internal Server Error: /rcategorys/
Traceback (most recent call last):
  File "/home/lenovo/Envs/contact/local/lib/python2.7/site-packages/django/core/handlers/base.py", line 112, in get_response
    response = wrapped_callback(request, *callback_args, **callback_kwargs)
  File "/home/lenovo/Envs/contact/local/lib/python2.7/site-packages/django/views/generic/base.py", line 69, in view
    return self.dispatch(request, *args, **kwargs)
  File "/home/lenovo/Envs/contact/local/lib/python2.7/site-packages/django/views/decorators/csrf.py", line 57, in wrapped_view
    return view_func(*args, **kwargs)
  File "/home/lenovo/Envs/contact/local/lib/python2.7/site-packages/rest_framework/views.py", line 400, in dispatch
    response = self.handle_exception(exc)
  File "/home/lenovo/Envs/contact/local/lib/python2.7/site-packages/rest_framework/views.py", line 397, in dispatch
    response = handler(request, *args, **kwargs)
  File "/home/lenovo/projects/contact/zone/views.py", line 49, in get
    Response(slz.data)
  File "/home/lenovo/Envs/contact/local/lib/python2.7/site-packages/rest_framework/serializers.py", line 575, in data
    self._data = self.to_native(obj)
  File "/home/lenovo/Envs/contact/local/lib/python2.7/site-packages/rest_framework/serializers.py", line 351, in to_native
    value = field.field_to_native(obj, field_name)
  File "/home/lenovo/Envs/contact/local/lib/python2.7/site-packages/rest_framework/fields.py", line 339, in field_to_native
    return super(WritableField, self).field_to_native(obj, field_name)
  File "/home/lenovo/Envs/contact/local/lib/python2.7/site-packages/rest_framework/fields.py", line 203, in field_to_native
    value = get_component(value, component)
  File "/home/lenovo/Envs/contact/local/lib/python2.7/site-packages/rest_framework/fields.py", line 56, in get_component
    val = getattr(obj, attr_name)
AttributeError: 'RelatedManager' object has no attribute 'name'
[13/Aug/2014 05:32:51] ERROR [django.request:224] Internal Server Error: /rcategorys/
Traceback (most recent call last):
  File "/home/lenovo/Envs/contact/local/lib/python2.7/site-packages/django/core/handlers/base.py", line 112, in get_response
    response = wrapped_callback(request, *callback_args, **callback_kwargs)
  File "/home/lenovo/Envs/contact/local/lib/python2.7/site-packages/django/views/generic/base.py", line 69, in view
    return self.dispatch(request, *args, **kwargs)
  File "/home/lenovo/Envs/contact/local/lib/python2.7/site-packages/django/views/decorators/csrf.py", line 57, in wrapped_view
    return view_func(*args, **kwargs)
  File "/home/lenovo/Envs/contact/local/lib/python2.7/site-packages/rest_framework/views.py", line 400, in dispatch
    response = self.handle_exception(exc)
  File "/home/lenovo/Envs/contact/local/lib/python2.7/site-packages/rest_framework/views.py", line 397, in dispatch
    response = handler(request, *args, **kwargs)
  File "/home/lenovo/projects/contact/zone/views.py", line 49, in get
    Response(slz.data)
  File "/home/lenovo/Envs/contact/local/lib/python2.7/site-packages/rest_framework/serializers.py", line 575, in data
    self._data = self.to_native(obj)
  File "/home/lenovo/Envs/contact/local/lib/python2.7/site-packages/rest_framework/serializers.py", line 351, in to_native
    value = field.field_to_native(obj, field_name)
  File "/home/lenovo/Envs/contact/local/lib/python2.7/site-packages/rest_framework/fields.py", line 339, in field_to_native
    return super(WritableField, self).field_to_native(obj, field_name)
  File "/home/lenovo/Envs/contact/local/lib/python2.7/site-packages/rest_framework/fields.py", line 203, in field_to_native
    value = get_component(value, component)
  File "/home/lenovo/Envs/contact/local/lib/python2.7/site-packages/rest_framework/fields.py", line 56, in get_component
    val = getattr(obj, attr_name)
AttributeError: 'RelatedManager' object has no attribute 'name'
[13/Aug/2014 05:33:05] ERROR [django.request:224] Internal Server Error: /rcategorys/
Traceback (most recent call last):
  File "/home/lenovo/Envs/contact/local/lib/python2.7/site-packages/django/core/handlers/base.py", line 112, in get_response
    response = wrapped_callback(request, *callback_args, **callback_kwargs)
  File "/home/lenovo/Envs/contact/local/lib/python2.7/site-packages/django/views/generic/base.py", line 69, in view
    return self.dispatch(request, *args, **kwargs)
  File "/home/lenovo/Envs/contact/local/lib/python2.7/site-packages/django/views/decorators/csrf.py", line 57, in wrapped_view
    return view_func(*args, **kwargs)
  File "/home/lenovo/Envs/contact/local/lib/python2.7/site-packages/rest_framework/views.py", line 402, in dispatch
    self.response = self.finalize_response(request, response, *args, **kwargs)
  File "/home/lenovo/Envs/contact/local/lib/python2.7/site-packages/rest_framework/views.py", line 333, in finalize_response
    % type(response)
AssertionError: Expected a `Response`, `HttpResponse` or `HttpStreamingResponse` to be returned from the view, but received a `<type 'NoneType'>`
[13/Aug/2014 05:33:15] ERROR [django.request:224] Internal Server Error: /rcategorys/
Traceback (most recent call last):
  File "/home/lenovo/Envs/contact/local/lib/python2.7/site-packages/django/core/handlers/base.py", line 112, in get_response
    response = wrapped_callback(request, *callback_args, **callback_kwargs)
  File "/home/lenovo/Envs/contact/local/lib/python2.7/site-packages/django/views/generic/base.py", line 69, in view
    return self.dispatch(request, *args, **kwargs)
  File "/home/lenovo/Envs/contact/local/lib/python2.7/site-packages/django/views/decorators/csrf.py", line 57, in wrapped_view
    return view_func(*args, **kwargs)
  File "/home/lenovo/Envs/contact/local/lib/python2.7/site-packages/rest_framework/views.py", line 402, in dispatch
    self.response = self.finalize_response(request, response, *args, **kwargs)
  File "/home/lenovo/Envs/contact/local/lib/python2.7/site-packages/rest_framework/views.py", line 333, in finalize_response
    % type(response)
AssertionError: Expected a `Response`, `HttpResponse` or `HttpStreamingResponse` to be returned from the view, but received a `<type 'NoneType'>`
[13/Aug/2014 05:33:54] ERROR [django.request:224] Internal Server Error: /rcategorys/
Traceback (most recent call last):
  File "/home/lenovo/Envs/contact/local/lib/python2.7/site-packages/django/core/handlers/base.py", line 137, in get_response
    response = response.render()
  File "/home/lenovo/Envs/contact/local/lib/python2.7/site-packages/django/template/response.py", line 105, in render
    self.content = self.rendered_content
  File "/home/lenovo/Envs/contact/local/lib/python2.7/site-packages/rest_framework/response.py", line 59, in rendered_content
    ret = renderer.render(self.data, media_type, context)
  File "/home/lenovo/Envs/contact/local/lib/python2.7/site-packages/rest_framework/renderers.py", line 600, in render
    template = loader.get_template(self.template)
  File "/home/lenovo/Envs/contact/local/lib/python2.7/site-packages/django/template/loader.py", line 138, in get_template
    template, origin = find_template(template_name)
  File "/home/lenovo/Envs/contact/local/lib/python2.7/site-packages/django/template/loader.py", line 131, in find_template
    raise TemplateDoesNotExist(name)
TemplateDoesNotExist: rest_framework/api.html
[13/Aug/2014 06:23:29] WARNING [django.request:143] Not Found: /favicon.ico
