[04/Aug/2014 16:34:21] WARNING [django.request:143] Not Found: /{[l.image_url]}
[04/Aug/2014 16:34:21] ERROR [django.request:224] Internal Server Error: /inbox/refresh/
Traceback (most recent call last):
  File "/home/lenovo/Envs/contact/local/lib/python2.7/site-packages/django/core/handlers/base.py", line 112, in get_response
    response = wrapped_callback(request, *callback_args, **callback_kwargs)
  File "/home/lenovo/Envs/contact/local/lib/python2.7/site-packages/django/views/generic/base.py", line 69, in view
    return self.dispatch(request, *args, **kwargs)
  File "/home/lenovo/Envs/contact/local/lib/python2.7/site-packages/django/views/decorators/csrf.py", line 57, in wrapped_view
    return view_func(*args, **kwargs)
  File "/home/lenovo/Envs/contact/local/lib/python2.7/site-packages/rest_framework/views.py", line 400, in dispatch
    response = self.handle_exception(exc)
  File "/home/lenovo/Envs/contact/local/lib/python2.7/site-packages/rest_framework/views.py", line 397, in dispatch
    response = handler(request, *args, **kwargs)
  File "/home/lenovo/Envs/contact/local/lib/python2.7/site-packages/django/db/transaction.py", line 371, in inner
    return func(*args, **kwargs)
  File "/home/lenovo/projects/contact/gmail/views.py", line 35, in get
    in_import = InboxImport(user)
  File "/home/lenovo/projects/contact/gmail/parsers.py", line 17, in __init__
    self.service = Auth.get_gmail_srv(user)
  File "/home/lenovo/projects/contact/gmail/__init__.py", line 42, in get_gmail_srv
    http = Auth.get_auth_http(user)
  File "/home/lenovo/projects/contact/gmail/__init__.py", line 35, in get_auth_http
    credentials = storage.get()
  File "/home/lenovo/Envs/contact/local/lib/python2.7/site-packages/oauth2client/client.py", line 311, in get
    return self.locked_get()
  File "/home/lenovo/Envs/contact/local/lib/python2.7/site-packages/oauth2client/file.py", line 72, in locked_get
    self._validate_file()
  File "/home/lenovo/Envs/contact/local/lib/python2.7/site-packages/oauth2client/file.py", line 44, in _validate_file
    if os.path.islink(self._filename):
  File "/home/lenovo/Envs/contact/lib/python2.7/posixpath.py", line 142, in islink
    st = os.lstat(path)
TypeError: coercing to Unicode: need string or buffer, SimpleLazyObject found
[04/Aug/2014 16:36:18] ERROR [django.request:224] Internal Server Error: /inbox/refresh/
Traceback (most recent call last):
  File "/home/lenovo/Envs/contact/local/lib/python2.7/site-packages/django/core/handlers/base.py", line 112, in get_response
    response = wrapped_callback(request, *callback_args, **callback_kwargs)
  File "/home/lenovo/Envs/contact/local/lib/python2.7/site-packages/django/views/generic/base.py", line 69, in view
    return self.dispatch(request, *args, **kwargs)
  File "/home/lenovo/Envs/contact/local/lib/python2.7/site-packages/django/views/decorators/csrf.py", line 57, in wrapped_view
    return view_func(*args, **kwargs)
  File "/home/lenovo/Envs/contact/local/lib/python2.7/site-packages/rest_framework/views.py", line 400, in dispatch
    response = self.handle_exception(exc)
  File "/home/lenovo/Envs/contact/local/lib/python2.7/site-packages/rest_framework/views.py", line 397, in dispatch
    response = handler(request, *args, **kwargs)
  File "/home/lenovo/Envs/contact/local/lib/python2.7/site-packages/django/db/transaction.py", line 371, in inner
    return func(*args, **kwargs)
  File "/home/lenovo/projects/contact/gmail/views.py", line 35, in get
    in_import = InboxImport(user)
  File "/home/lenovo/projects/contact/gmail/parsers.py", line 17, in __init__
    self.service = Auth.get_gmail_srv(user)
  File "/home/lenovo/projects/contact/gmail/__init__.py", line 42, in get_gmail_srv
    http = Auth.get_auth_http(user)
  File "/home/lenovo/projects/contact/gmail/__init__.py", line 35, in get_auth_http
    credentials = storage.get()
  File "/home/lenovo/Envs/contact/local/lib/python2.7/site-packages/oauth2client/client.py", line 311, in get
    return self.locked_get()
  File "/home/lenovo/Envs/contact/local/lib/python2.7/site-packages/oauth2client/file.py", line 72, in locked_get
    self._validate_file()
  File "/home/lenovo/Envs/contact/local/lib/python2.7/site-packages/oauth2client/file.py", line 44, in _validate_file
    if os.path.islink(self._filename):
  File "/home/lenovo/Envs/contact/lib/python2.7/posixpath.py", line 142, in islink
    st = os.lstat(path)
TypeError: coercing to Unicode: need string or buffer, SimpleLazyObject found
[04/Aug/2014 16:36:28] ERROR [django.request:224] Internal Server Error: /oauth2callback/
Traceback (most recent call last):
  File "/home/lenovo/Envs/contact/local/lib/python2.7/site-packages/django/core/handlers/base.py", line 112, in get_response
    response = wrapped_callback(request, *callback_args, **callback_kwargs)
  File "/home/lenovo/projects/contact/gmail/views.py", line 18, in callback
    user = Auth.get_user_and_update_cred(code)
  File "/home/lenovo/projects/contact/gmail/__init__.py", line 59, in get_user_and_update_cred
    storage.put(credentials)
  File "/home/lenovo/Envs/contact/local/lib/python2.7/site-packages/oauth2client/client.py", line 325, in put
    self.locked_put(credentials)
  File "/home/lenovo/Envs/contact/local/lib/python2.7/site-packages/oauth2client/file.py", line 111, in locked_put
    self._create_file_if_needed()
  File "/home/lenovo/Envs/contact/local/lib/python2.7/site-packages/oauth2client/file.py", line 94, in _create_file_if_needed
    if not os.path.exists(self._filename):
  File "/home/lenovo/Envs/contact/lib/python2.7/genericpath.py", line 18, in exists
    os.stat(path)
TypeError: coercing to Unicode: need string or buffer, MyUser found
[04/Aug/2014 16:41:21] WARNING [django.request:143] Not Found: /{[l.image_url]}
[04/Aug/2014 16:41:21] ERROR [django.request:224] Internal Server Error: /inbox/refresh/
Traceback (most recent call last):
  File "/home/lenovo/Envs/contact/local/lib/python2.7/site-packages/django/core/handlers/base.py", line 112, in get_response
    response = wrapped_callback(request, *callback_args, **callback_kwargs)
  File "/home/lenovo/Envs/contact/local/lib/python2.7/site-packages/django/views/generic/base.py", line 69, in view
    return self.dispatch(request, *args, **kwargs)
  File "/home/lenovo/Envs/contact/local/lib/python2.7/site-packages/django/views/decorators/csrf.py", line 57, in wrapped_view
    return view_func(*args, **kwargs)
  File "/home/lenovo/Envs/contact/local/lib/python2.7/site-packages/rest_framework/views.py", line 400, in dispatch
    response = self.handle_exception(exc)
  File "/home/lenovo/Envs/contact/local/lib/python2.7/site-packages/rest_framework/views.py", line 397, in dispatch
    response = handler(request, *args, **kwargs)
  File "/home/lenovo/Envs/contact/local/lib/python2.7/site-packages/django/db/transaction.py", line 371, in inner
    return func(*args, **kwargs)
  File "/home/lenovo/projects/contact/gmail/views.py", line 35, in get
    in_import = InboxImport(user)
  File "/home/lenovo/projects/contact/gmail/parsers.py", line 17, in __init__
    self.service = Auth.get_gmail_srv(user)
  File "/home/lenovo/projects/contact/gmail/__init__.py", line 42, in get_gmail_srv
    http = Auth.get_auth_http(user)
  File "/home/lenovo/projects/contact/gmail/__init__.py", line 37, in get_auth_http
    http = credentials.authorize(http)
AttributeError: 'NoneType' object has no attribute 'authorize'
[04/Aug/2014 16:41:25] ERROR [django.request:224] Internal Server Error: /inbox/refresh/
Traceback (most recent call last):
  File "/home/lenovo/Envs/contact/local/lib/python2.7/site-packages/django/core/handlers/base.py", line 112, in get_response
    response = wrapped_callback(request, *callback_args, **callback_kwargs)
  File "/home/lenovo/Envs/contact/local/lib/python2.7/site-packages/django/views/generic/base.py", line 69, in view
    return self.dispatch(request, *args, **kwargs)
  File "/home/lenovo/Envs/contact/local/lib/python2.7/site-packages/django/views/decorators/csrf.py", line 57, in wrapped_view
    return view_func(*args, **kwargs)
  File "/home/lenovo/Envs/contact/local/lib/python2.7/site-packages/rest_framework/views.py", line 400, in dispatch
    response = self.handle_exception(exc)
  File "/home/lenovo/Envs/contact/local/lib/python2.7/site-packages/rest_framework/views.py", line 397, in dispatch
    response = handler(request, *args, **kwargs)
  File "/home/lenovo/Envs/contact/local/lib/python2.7/site-packages/django/db/transaction.py", line 371, in inner
    return func(*args, **kwargs)
  File "/home/lenovo/projects/contact/gmail/views.py", line 35, in get
    in_import = InboxImport(user)
  File "/home/lenovo/projects/contact/gmail/parsers.py", line 17, in __init__
    self.service = Auth.get_gmail_srv(user)
  File "/home/lenovo/projects/contact/gmail/__init__.py", line 42, in get_gmail_srv
    http = Auth.get_auth_http(user)
  File "/home/lenovo/projects/contact/gmail/__init__.py", line 37, in get_auth_http
    http = credentials.authorize(http)
AttributeError: 'NoneType' object has no attribute 'authorize'
[04/Aug/2014 16:41:40] WARNING [django.request:143] Not Found: /{[l.image_url]}
[04/Aug/2014 16:42:20] WARNING [django.request:143] Not Found: /{[l.image_url]}
[04/Aug/2014 16:42:20] WARNING [django.request:143] Not Found: /{[l.image_url]}
[04/Aug/2014 16:42:20] ERROR [django.request:224] Internal Server Error: /inbox/refresh/
Traceback (most recent call last):
  File "/home/lenovo/Envs/contact/local/lib/python2.7/site-packages/django/core/handlers/base.py", line 112, in get_response
    response = wrapped_callback(request, *callback_args, **callback_kwargs)
  File "/home/lenovo/Envs/contact/local/lib/python2.7/site-packages/django/views/generic/base.py", line 69, in view
    return self.dispatch(request, *args, **kwargs)
  File "/home/lenovo/Envs/contact/local/lib/python2.7/site-packages/django/views/decorators/csrf.py", line 57, in wrapped_view
    return view_func(*args, **kwargs)
  File "/home/lenovo/Envs/contact/local/lib/python2.7/site-packages/rest_framework/views.py", line 400, in dispatch
    response = self.handle_exception(exc)
  File "/home/lenovo/Envs/contact/local/lib/python2.7/site-packages/rest_framework/views.py", line 397, in dispatch
    response = handler(request, *args, **kwargs)
  File "/home/lenovo/Envs/contact/local/lib/python2.7/site-packages/django/db/transaction.py", line 371, in inner
    return func(*args, **kwargs)
  File "/home/lenovo/projects/contact/gmail/views.py", line 35, in get
    in_import = InboxImport(user)
  File "/home/lenovo/projects/contact/gmail/parsers.py", line 17, in __init__
    self.service = Auth.get_gmail_srv(user)
  File "/home/lenovo/projects/contact/gmail/__init__.py", line 42, in get_gmail_srv
    http = Auth.get_auth_http(user)
  File "/home/lenovo/projects/contact/gmail/__init__.py", line 37, in get_auth_http
    http = credentials.authorize(http)
AttributeError: 'NoneType' object has no attribute 'authorize'
[04/Aug/2014 16:42:20] WARNING [django.request:143] Not Found: /favicon.ico
[04/Aug/2014 16:42:23] ERROR [django.request:224] Internal Server Error: /inbox/refresh/
Traceback (most recent call last):
  File "/home/lenovo/Envs/contact/local/lib/python2.7/site-packages/django/core/handlers/base.py", line 112, in get_response
    response = wrapped_callback(request, *callback_args, **callback_kwargs)
  File "/home/lenovo/Envs/contact/local/lib/python2.7/site-packages/django/views/generic/base.py", line 69, in view
    return self.dispatch(request, *args, **kwargs)
  File "/home/lenovo/Envs/contact/local/lib/python2.7/site-packages/django/views/decorators/csrf.py", line 57, in wrapped_view
    return view_func(*args, **kwargs)
  File "/home/lenovo/Envs/contact/local/lib/python2.7/site-packages/rest_framework/views.py", line 400, in dispatch
    response = self.handle_exception(exc)
  File "/home/lenovo/Envs/contact/local/lib/python2.7/site-packages/rest_framework/views.py", line 397, in dispatch
    response = handler(request, *args, **kwargs)
  File "/home/lenovo/Envs/contact/local/lib/python2.7/site-packages/django/db/transaction.py", line 371, in inner
    return func(*args, **kwargs)
  File "/home/lenovo/projects/contact/gmail/views.py", line 35, in get
    in_import = InboxImport(user)
  File "/home/lenovo/projects/contact/gmail/parsers.py", line 17, in __init__
    self.service = Auth.get_gmail_srv(user)
  File "/home/lenovo/projects/contact/gmail/__init__.py", line 42, in get_gmail_srv
    http = Auth.get_auth_http(user)
  File "/home/lenovo/projects/contact/gmail/__init__.py", line 37, in get_auth_http
    http = credentials.authorize(http)
AttributeError: 'NoneType' object has no attribute 'authorize'
[04/Aug/2014 16:42:34] WARNING [django.request:143] Not Found: /{[l.image_url]}
[04/Aug/2014 16:42:48] ERROR [django.request:224] Internal Server Error: /inbox/refresh/
Traceback (most recent call last):
  File "/home/lenovo/Envs/contact/local/lib/python2.7/site-packages/django/core/handlers/base.py", line 112, in get_response
    response = wrapped_callback(request, *callback_args, **callback_kwargs)
  File "/home/lenovo/Envs/contact/local/lib/python2.7/site-packages/django/views/generic/base.py", line 69, in view
    return self.dispatch(request, *args, **kwargs)
  File "/home/lenovo/Envs/contact/local/lib/python2.7/site-packages/django/views/decorators/csrf.py", line 57, in wrapped_view
    return view_func(*args, **kwargs)
  File "/home/lenovo/Envs/contact/local/lib/python2.7/site-packages/rest_framework/views.py", line 400, in dispatch
    response = self.handle_exception(exc)
  File "/home/lenovo/Envs/contact/local/lib/python2.7/site-packages/rest_framework/views.py", line 397, in dispatch
    response = handler(request, *args, **kwargs)
  File "/home/lenovo/Envs/contact/local/lib/python2.7/site-packages/django/db/transaction.py", line 371, in inner
    return func(*args, **kwargs)
  File "/home/lenovo/projects/contact/gmail/views.py", line 36, in get
    result = in_import.import_new()
  File "/home/lenovo/projects/contact/gmail/parsers.py", line 49, in import_new
    return self.__import()
  File "/home/lenovo/projects/contact/gmail/parsers.py", line 37, in __import
    self.__process_response(response)
  File "/home/lenovo/projects/contact/gmail/parsers.py", line 28, in __process_response
    mail_import.import_msg()
  File "/home/lenovo/projects/contact/gmail/parsers.py", line 161, in import_msg
    [c.save() for c in self.contact_imports]
  File "/home/lenovo/projects/contact/gmail/parsers.py", line 96, in save
    c = self.__save_contact(c)
  File "/home/lenovo/projects/contact/gmail/parsers.py", line 91, in __save_contact
    contact.save()
  File "/home/lenovo/Envs/contact/local/lib/python2.7/site-packages/django/db/models/base.py", line 545, in save
    force_update=force_update, update_fields=update_fields)
  File "/home/lenovo/Envs/contact/local/lib/python2.7/site-packages/django/db/models/base.py", line 573, in save_base
    updated = self._save_table(raw, cls, force_insert, force_update, using, update_fields)
  File "/home/lenovo/Envs/contact/local/lib/python2.7/site-packages/django/db/models/base.py", line 654, in _save_table
    result = self._do_insert(cls._base_manager, using, fields, update_pk, raw)
  File "/home/lenovo/Envs/contact/local/lib/python2.7/site-packages/django/db/models/base.py", line 687, in _do_insert
    using=using, raw=raw)
  File "/home/lenovo/Envs/contact/local/lib/python2.7/site-packages/django/db/models/manager.py", line 232, in _insert
    return insert_query(self.model, objs, fields, **kwargs)
  File "/home/lenovo/Envs/contact/local/lib/python2.7/site-packages/django/db/models/query.py", line 1514, in insert_query
    return query.get_compiler(using=using).execute_sql(return_id)
  File "/home/lenovo/Envs/contact/local/lib/python2.7/site-packages/django/db/models/sql/compiler.py", line 903, in execute_sql
    cursor.execute(sql, params)
  File "/home/lenovo/Envs/contact/local/lib/python2.7/site-packages/django/db/backends/util.py", line 69, in execute
    return super(CursorDebugWrapper, self).execute(sql, params)
  File "/home/lenovo/Envs/contact/local/lib/python2.7/site-packages/django/db/backends/util.py", line 53, in execute
    return self.cursor.execute(sql, params)
  File "/home/lenovo/Envs/contact/local/lib/python2.7/site-packages/django/db/utils.py", line 99, in __exit__
    six.reraise(dj_exc_type, dj_exc_value, traceback)
  File "/home/lenovo/Envs/contact/local/lib/python2.7/site-packages/django/db/backends/util.py", line 53, in execute
    return self.cursor.execute(sql, params)
DataError: value too long for type character varying(128)

[04/Aug/2014 16:43:33] ERROR [django.request:224] Internal Server Error: /inbox/refresh/
Traceback (most recent call last):
  File "/home/lenovo/Envs/contact/local/lib/python2.7/site-packages/django/core/handlers/base.py", line 112, in get_response
    response = wrapped_callback(request, *callback_args, **callback_kwargs)
  File "/home/lenovo/Envs/contact/local/lib/python2.7/site-packages/django/views/generic/base.py", line 69, in view
    return self.dispatch(request, *args, **kwargs)
  File "/home/lenovo/Envs/contact/local/lib/python2.7/site-packages/django/views/decorators/csrf.py", line 57, in wrapped_view
    return view_func(*args, **kwargs)
  File "/home/lenovo/Envs/contact/local/lib/python2.7/site-packages/rest_framework/views.py", line 400, in dispatch
    response = self.handle_exception(exc)
  File "/home/lenovo/Envs/contact/local/lib/python2.7/site-packages/rest_framework/views.py", line 397, in dispatch
    response = handler(request, *args, **kwargs)
  File "/home/lenovo/Envs/contact/local/lib/python2.7/site-packages/django/db/transaction.py", line 371, in inner
    return func(*args, **kwargs)
  File "/home/lenovo/projects/contact/gmail/views.py", line 36, in get
    result = in_import.import_new()
  File "/home/lenovo/projects/contact/gmail/parsers.py", line 49, in import_new
    return self.__import()
  File "/home/lenovo/projects/contact/gmail/parsers.py", line 37, in __import
    self.__process_response(response)
  File "/home/lenovo/projects/contact/gmail/parsers.py", line 28, in __process_response
    mail_import.import_msg()
  File "/home/lenovo/projects/contact/gmail/parsers.py", line 161, in import_msg
    [c.save() for c in self.contact_imports]
  File "/home/lenovo/projects/contact/gmail/parsers.py", line 96, in save
    c = self.__save_contact(c)
  File "/home/lenovo/projects/contact/gmail/parsers.py", line 91, in __save_contact
    contact.save()
  File "/home/lenovo/Envs/contact/local/lib/python2.7/site-packages/django/db/models/base.py", line 545, in save
    force_update=force_update, update_fields=update_fields)
  File "/home/lenovo/Envs/contact/local/lib/python2.7/site-packages/django/db/models/base.py", line 573, in save_base
    updated = self._save_table(raw, cls, force_insert, force_update, using, update_fields)
  File "/home/lenovo/Envs/contact/local/lib/python2.7/site-packages/django/db/models/base.py", line 654, in _save_table
    result = self._do_insert(cls._base_manager, using, fields, update_pk, raw)
  File "/home/lenovo/Envs/contact/local/lib/python2.7/site-packages/django/db/models/base.py", line 687, in _do_insert
    using=using, raw=raw)
  File "/home/lenovo/Envs/contact/local/lib/python2.7/site-packages/django/db/models/manager.py", line 232, in _insert
    return insert_query(self.model, objs, fields, **kwargs)
  File "/home/lenovo/Envs/contact/local/lib/python2.7/site-packages/django/db/models/query.py", line 1514, in insert_query
    return query.get_compiler(using=using).execute_sql(return_id)
  File "/home/lenovo/Envs/contact/local/lib/python2.7/site-packages/django/db/models/sql/compiler.py", line 903, in execute_sql
    cursor.execute(sql, params)
  File "/home/lenovo/Envs/contact/local/lib/python2.7/site-packages/django/db/backends/util.py", line 69, in execute
    return super(CursorDebugWrapper, self).execute(sql, params)
  File "/home/lenovo/Envs/contact/local/lib/python2.7/site-packages/django/db/backends/util.py", line 53, in execute
    return self.cursor.execute(sql, params)
  File "/home/lenovo/Envs/contact/local/lib/python2.7/site-packages/django/db/utils.py", line 99, in __exit__
    six.reraise(dj_exc_type, dj_exc_value, traceback)
  File "/home/lenovo/Envs/contact/local/lib/python2.7/site-packages/django/db/backends/util.py", line 53, in execute
    return self.cursor.execute(sql, params)
DataError: value too long for type character varying(128)

[04/Aug/2014 16:43:42] WARNING [django.request:143] Not Found: /{[l.image_url]}
[04/Aug/2014 16:43:42] WARNING [django.request:143] Not Found: /{[l.image_url]}
[04/Aug/2014 16:43:49] ERROR [django.request:224] Internal Server Error: /inbox/refresh/
Traceback (most recent call last):
  File "/home/lenovo/Envs/contact/local/lib/python2.7/site-packages/django/core/handlers/base.py", line 112, in get_response
    response = wrapped_callback(request, *callback_args, **callback_kwargs)
  File "/home/lenovo/Envs/contact/local/lib/python2.7/site-packages/django/views/generic/base.py", line 69, in view
    return self.dispatch(request, *args, **kwargs)
  File "/home/lenovo/Envs/contact/local/lib/python2.7/site-packages/django/views/decorators/csrf.py", line 57, in wrapped_view
    return view_func(*args, **kwargs)
  File "/home/lenovo/Envs/contact/local/lib/python2.7/site-packages/rest_framework/views.py", line 400, in dispatch
    response = self.handle_exception(exc)
  File "/home/lenovo/Envs/contact/local/lib/python2.7/site-packages/rest_framework/views.py", line 397, in dispatch
    response = handler(request, *args, **kwargs)
  File "/home/lenovo/Envs/contact/local/lib/python2.7/site-packages/django/db/transaction.py", line 371, in inner
    return func(*args, **kwargs)
  File "/home/lenovo/projects/contact/gmail/views.py", line 36, in get
    result = in_import.import_new()
  File "/home/lenovo/projects/contact/gmail/parsers.py", line 49, in import_new
    return self.__import()
  File "/home/lenovo/projects/contact/gmail/parsers.py", line 37, in __import
    self.__process_response(response)
  File "/home/lenovo/projects/contact/gmail/parsers.py", line 28, in __process_response
    mail_import.import_msg()
  File "/home/lenovo/projects/contact/gmail/parsers.py", line 161, in import_msg
    [c.save() for c in self.contact_imports]
  File "/home/lenovo/projects/contact/gmail/parsers.py", line 96, in save
    c = self.__save_contact(c)
  File "/home/lenovo/projects/contact/gmail/parsers.py", line 91, in __save_contact
    contact.save()
  File "/home/lenovo/Envs/contact/local/lib/python2.7/site-packages/django/db/models/base.py", line 545, in save
    force_update=force_update, update_fields=update_fields)
  File "/home/lenovo/Envs/contact/local/lib/python2.7/site-packages/django/db/models/base.py", line 573, in save_base
    updated = self._save_table(raw, cls, force_insert, force_update, using, update_fields)
  File "/home/lenovo/Envs/contact/local/lib/python2.7/site-packages/django/db/models/base.py", line 654, in _save_table
    result = self._do_insert(cls._base_manager, using, fields, update_pk, raw)
  File "/home/lenovo/Envs/contact/local/lib/python2.7/site-packages/django/db/models/base.py", line 687, in _do_insert
    using=using, raw=raw)
  File "/home/lenovo/Envs/contact/local/lib/python2.7/site-packages/django/db/models/manager.py", line 232, in _insert
    return insert_query(self.model, objs, fields, **kwargs)
  File "/home/lenovo/Envs/contact/local/lib/python2.7/site-packages/django/db/models/query.py", line 1514, in insert_query
    return query.get_compiler(using=using).execute_sql(return_id)
  File "/home/lenovo/Envs/contact/local/lib/python2.7/site-packages/django/db/models/sql/compiler.py", line 903, in execute_sql
    cursor.execute(sql, params)
  File "/home/lenovo/Envs/contact/local/lib/python2.7/site-packages/django/db/backends/util.py", line 69, in execute
    return super(CursorDebugWrapper, self).execute(sql, params)
  File "/home/lenovo/Envs/contact/local/lib/python2.7/site-packages/django/db/backends/util.py", line 53, in execute
    return self.cursor.execute(sql, params)
  File "/home/lenovo/Envs/contact/local/lib/python2.7/site-packages/django/db/utils.py", line 99, in __exit__
    six.reraise(dj_exc_type, dj_exc_value, traceback)
  File "/home/lenovo/Envs/contact/local/lib/python2.7/site-packages/django/db/backends/util.py", line 53, in execute
    return self.cursor.execute(sql, params)
DataError: value too long for type character varying(128)

[04/Aug/2014 16:47:02] WARNING [django.request:143] Not Found: /{[l.image_url]}
[04/Aug/2014 16:47:02] WARNING [django.request:143] Not Found: /{[l.image_url]}
[04/Aug/2014 16:47:07] ERROR [django.request:224] Internal Server Error: /inbox/refresh/
Traceback (most recent call last):
  File "/home/lenovo/Envs/contact/local/lib/python2.7/site-packages/django/core/handlers/base.py", line 112, in get_response
    response = wrapped_callback(request, *callback_args, **callback_kwargs)
  File "/home/lenovo/Envs/contact/local/lib/python2.7/site-packages/django/views/generic/base.py", line 69, in view
    return self.dispatch(request, *args, **kwargs)
  File "/home/lenovo/Envs/contact/local/lib/python2.7/site-packages/django/views/decorators/csrf.py", line 57, in wrapped_view
    return view_func(*args, **kwargs)
  File "/home/lenovo/Envs/contact/local/lib/python2.7/site-packages/rest_framework/views.py", line 400, in dispatch
    response = self.handle_exception(exc)
  File "/home/lenovo/Envs/contact/local/lib/python2.7/site-packages/rest_framework/views.py", line 397, in dispatch
    response = handler(request, *args, **kwargs)
  File "/home/lenovo/Envs/contact/local/lib/python2.7/site-packages/django/db/transaction.py", line 371, in inner
    return func(*args, **kwargs)
  File "/home/lenovo/projects/contact/gmail/views.py", line 36, in get
    result = in_import.import_new()
  File "/home/lenovo/projects/contact/gmail/parsers.py", line 49, in import_new
    return self.__import()
  File "/home/lenovo/projects/contact/gmail/parsers.py", line 37, in __import
    self.__process_response(response)
  File "/home/lenovo/projects/contact/gmail/parsers.py", line 28, in __process_response
    mail_import.import_msg()
  File "/home/lenovo/projects/contact/gmail/parsers.py", line 160, in import_msg
    [c.save() for c in self.contact_imports]
  File "/home/lenovo/projects/contact/gmail/parsers.py", line 95, in save
    c = self.__save_contact(c)
  File "/home/lenovo/projects/contact/gmail/parsers.py", line 90, in __save_contact
    contact.save()
  File "/home/lenovo/Envs/contact/local/lib/python2.7/site-packages/django/db/models/base.py", line 545, in save
    force_update=force_update, update_fields=update_fields)
  File "/home/lenovo/Envs/contact/local/lib/python2.7/site-packages/django/db/models/base.py", line 573, in save_base
    updated = self._save_table(raw, cls, force_insert, force_update, using, update_fields)
  File "/home/lenovo/Envs/contact/local/lib/python2.7/site-packages/django/db/models/base.py", line 654, in _save_table
    result = self._do_insert(cls._base_manager, using, fields, update_pk, raw)
  File "/home/lenovo/Envs/contact/local/lib/python2.7/site-packages/django/db/models/base.py", line 687, in _do_insert
    using=using, raw=raw)
  File "/home/lenovo/Envs/contact/local/lib/python2.7/site-packages/django/db/models/manager.py", line 232, in _insert
    return insert_query(self.model, objs, fields, **kwargs)
  File "/home/lenovo/Envs/contact/local/lib/python2.7/site-packages/django/db/models/query.py", line 1514, in insert_query
    return query.get_compiler(using=using).execute_sql(return_id)
  File "/home/lenovo/Envs/contact/local/lib/python2.7/site-packages/django/db/models/sql/compiler.py", line 903, in execute_sql
    cursor.execute(sql, params)
  File "/home/lenovo/Envs/contact/local/lib/python2.7/site-packages/django/db/backends/util.py", line 69, in execute
    return super(CursorDebugWrapper, self).execute(sql, params)
  File "/home/lenovo/Envs/contact/local/lib/python2.7/site-packages/django/db/backends/util.py", line 53, in execute
    return self.cursor.execute(sql, params)
  File "/home/lenovo/Envs/contact/local/lib/python2.7/site-packages/django/db/utils.py", line 99, in __exit__
    six.reraise(dj_exc_type, dj_exc_value, traceback)
  File "/home/lenovo/Envs/contact/local/lib/python2.7/site-packages/django/db/backends/util.py", line 53, in execute
    return self.cursor.execute(sql, params)
DataError: value too long for type character varying(128)

[04/Aug/2014 16:47:39] WARNING [django.request:143] Not Found: /{[l.image_url]}
[04/Aug/2014 16:47:49] ERROR [django.request:224] Internal Server Error: /inbox/refresh/
Traceback (most recent call last):
  File "/home/lenovo/Envs/contact/local/lib/python2.7/site-packages/django/core/handlers/base.py", line 112, in get_response
    response = wrapped_callback(request, *callback_args, **callback_kwargs)
  File "/home/lenovo/Envs/contact/local/lib/python2.7/site-packages/django/views/generic/base.py", line 69, in view
    return self.dispatch(request, *args, **kwargs)
  File "/home/lenovo/Envs/contact/local/lib/python2.7/site-packages/django/views/decorators/csrf.py", line 57, in wrapped_view
    return view_func(*args, **kwargs)
  File "/home/lenovo/Envs/contact/local/lib/python2.7/site-packages/rest_framework/views.py", line 400, in dispatch
    response = self.handle_exception(exc)
  File "/home/lenovo/Envs/contact/local/lib/python2.7/site-packages/rest_framework/views.py", line 397, in dispatch
    response = handler(request, *args, **kwargs)
  File "/home/lenovo/Envs/contact/local/lib/python2.7/site-packages/django/db/transaction.py", line 371, in inner
    return func(*args, **kwargs)
  File "/home/lenovo/projects/contact/gmail/views.py", line 36, in get
    result = in_import.import_new()
  File "/home/lenovo/projects/contact/gmail/parsers.py", line 49, in import_new
    return self.__import()
  File "/home/lenovo/projects/contact/gmail/parsers.py", line 37, in __import
    self.__process_response(response)
  File "/home/lenovo/projects/contact/gmail/parsers.py", line 28, in __process_response
    mail_import.import_msg()
  File "/home/lenovo/projects/contact/gmail/parsers.py", line 160, in import_msg
    [c.save() for c in self.contact_imports]
  File "/home/lenovo/projects/contact/gmail/parsers.py", line 95, in save
    c = self.__save_contact(c)
  File "/home/lenovo/projects/contact/gmail/parsers.py", line 90, in __save_contact
    contact.save()
  File "/home/lenovo/Envs/contact/local/lib/python2.7/site-packages/django/db/models/base.py", line 545, in save
    force_update=force_update, update_fields=update_fields)
  File "/home/lenovo/Envs/contact/local/lib/python2.7/site-packages/django/db/models/base.py", line 573, in save_base
    updated = self._save_table(raw, cls, force_insert, force_update, using, update_fields)
  File "/home/lenovo/Envs/contact/local/lib/python2.7/site-packages/django/db/models/base.py", line 654, in _save_table
    result = self._do_insert(cls._base_manager, using, fields, update_pk, raw)
  File "/home/lenovo/Envs/contact/local/lib/python2.7/site-packages/django/db/models/base.py", line 687, in _do_insert
    using=using, raw=raw)
  File "/home/lenovo/Envs/contact/local/lib/python2.7/site-packages/django/db/models/manager.py", line 232, in _insert
    return insert_query(self.model, objs, fields, **kwargs)
  File "/home/lenovo/Envs/contact/local/lib/python2.7/site-packages/django/db/models/query.py", line 1514, in insert_query
    return query.get_compiler(using=using).execute_sql(return_id)
  File "/home/lenovo/Envs/contact/local/lib/python2.7/site-packages/django/db/models/sql/compiler.py", line 903, in execute_sql
    cursor.execute(sql, params)
  File "/home/lenovo/Envs/contact/local/lib/python2.7/site-packages/django/db/backends/util.py", line 69, in execute
    return super(CursorDebugWrapper, self).execute(sql, params)
  File "/home/lenovo/Envs/contact/local/lib/python2.7/site-packages/django/db/backends/util.py", line 53, in execute
    return self.cursor.execute(sql, params)
  File "/home/lenovo/Envs/contact/local/lib/python2.7/site-packages/django/db/utils.py", line 99, in __exit__
    six.reraise(dj_exc_type, dj_exc_value, traceback)
  File "/home/lenovo/Envs/contact/local/lib/python2.7/site-packages/django/db/backends/util.py", line 53, in execute
    return self.cursor.execute(sql, params)
DataError: value too long for type character varying(128)

[04/Aug/2014 16:48:13] WARNING [django.request:143] Not Found: /{[l.image_url]}
[04/Aug/2014 16:48:13] WARNING [django.request:143] Not Found: /{[l.image_url]}
[04/Aug/2014 16:48:26] ERROR [django.request:224] Internal Server Error: /inbox/refresh/
Traceback (most recent call last):
  File "/home/lenovo/Envs/contact/local/lib/python2.7/site-packages/django/core/handlers/base.py", line 112, in get_response
    response = wrapped_callback(request, *callback_args, **callback_kwargs)
  File "/home/lenovo/Envs/contact/local/lib/python2.7/site-packages/django/views/generic/base.py", line 69, in view
    return self.dispatch(request, *args, **kwargs)
  File "/home/lenovo/Envs/contact/local/lib/python2.7/site-packages/django/views/decorators/csrf.py", line 57, in wrapped_view
    return view_func(*args, **kwargs)
  File "/home/lenovo/Envs/contact/local/lib/python2.7/site-packages/rest_framework/views.py", line 400, in dispatch
    response = self.handle_exception(exc)
  File "/home/lenovo/Envs/contact/local/lib/python2.7/site-packages/rest_framework/views.py", line 397, in dispatch
    response = handler(request, *args, **kwargs)
  File "/home/lenovo/Envs/contact/local/lib/python2.7/site-packages/django/db/transaction.py", line 371, in inner
    return func(*args, **kwargs)
  File "/home/lenovo/projects/contact/gmail/views.py", line 36, in get
    result = in_import.import_new()
  File "/home/lenovo/projects/contact/gmail/parsers.py", line 49, in import_new
    return self.__import()
  File "/home/lenovo/projects/contact/gmail/parsers.py", line 37, in __import
    self.__process_response(response)
  File "/home/lenovo/projects/contact/gmail/parsers.py", line 28, in __process_response
    mail_import.import_msg()
  File "/home/lenovo/projects/contact/gmail/parsers.py", line 160, in import_msg
    [c.save() for c in self.contact_imports]
  File "/home/lenovo/projects/contact/gmail/parsers.py", line 95, in save
    c = self.__save_contact(c)
  File "/home/lenovo/projects/contact/gmail/parsers.py", line 90, in __save_contact
    contact.save()
  File "/home/lenovo/Envs/contact/local/lib/python2.7/site-packages/django/db/models/base.py", line 545, in save
    force_update=force_update, update_fields=update_fields)
  File "/home/lenovo/Envs/contact/local/lib/python2.7/site-packages/django/db/models/base.py", line 573, in save_base
    updated = self._save_table(raw, cls, force_insert, force_update, using, update_fields)
  File "/home/lenovo/Envs/contact/local/lib/python2.7/site-packages/django/db/models/base.py", line 654, in _save_table
    result = self._do_insert(cls._base_manager, using, fields, update_pk, raw)
  File "/home/lenovo/Envs/contact/local/lib/python2.7/site-packages/django/db/models/base.py", line 687, in _do_insert
    using=using, raw=raw)
  File "/home/lenovo/Envs/contact/local/lib/python2.7/site-packages/django/db/models/manager.py", line 232, in _insert
    return insert_query(self.model, objs, fields, **kwargs)
  File "/home/lenovo/Envs/contact/local/lib/python2.7/site-packages/django/db/models/query.py", line 1514, in insert_query
    return query.get_compiler(using=using).execute_sql(return_id)
  File "/home/lenovo/Envs/contact/local/lib/python2.7/site-packages/django/db/models/sql/compiler.py", line 903, in execute_sql
    cursor.execute(sql, params)
  File "/home/lenovo/Envs/contact/local/lib/python2.7/site-packages/django/db/backends/util.py", line 69, in execute
    return super(CursorDebugWrapper, self).execute(sql, params)
  File "/home/lenovo/Envs/contact/local/lib/python2.7/site-packages/django/db/backends/util.py", line 53, in execute
    return self.cursor.execute(sql, params)
  File "/home/lenovo/Envs/contact/local/lib/python2.7/site-packages/django/db/utils.py", line 99, in __exit__
    six.reraise(dj_exc_type, dj_exc_value, traceback)
  File "/home/lenovo/Envs/contact/local/lib/python2.7/site-packages/django/db/backends/util.py", line 53, in execute
    return self.cursor.execute(sql, params)
DataError: value too long for type character varying(128)

[04/Aug/2014 16:48:35] WARNING [django.request:143] Not Found: /{[l.image_url]}
[04/Aug/2014 16:48:46] ERROR [django.request:224] Internal Server Error: /inbox/refresh/
Traceback (most recent call last):
  File "/home/lenovo/Envs/contact/local/lib/python2.7/site-packages/django/core/handlers/base.py", line 112, in get_response
    response = wrapped_callback(request, *callback_args, **callback_kwargs)
  File "/home/lenovo/Envs/contact/local/lib/python2.7/site-packages/django/views/generic/base.py", line 69, in view
    return self.dispatch(request, *args, **kwargs)
  File "/home/lenovo/Envs/contact/local/lib/python2.7/site-packages/django/views/decorators/csrf.py", line 57, in wrapped_view
    return view_func(*args, **kwargs)
  File "/home/lenovo/Envs/contact/local/lib/python2.7/site-packages/rest_framework/views.py", line 400, in dispatch
    response = self.handle_exception(exc)
  File "/home/lenovo/Envs/contact/local/lib/python2.7/site-packages/rest_framework/views.py", line 397, in dispatch
    response = handler(request, *args, **kwargs)
  File "/home/lenovo/Envs/contact/local/lib/python2.7/site-packages/django/db/transaction.py", line 371, in inner
    return func(*args, **kwargs)
  File "/home/lenovo/projects/contact/gmail/views.py", line 36, in get
    result = in_import.import_new()
  File "/home/lenovo/projects/contact/gmail/parsers.py", line 49, in import_new
    return self.__import()
  File "/home/lenovo/projects/contact/gmail/parsers.py", line 37, in __import
    self.__process_response(response)
  File "/home/lenovo/projects/contact/gmail/parsers.py", line 28, in __process_response
    mail_import.import_msg()
  File "/home/lenovo/projects/contact/gmail/parsers.py", line 160, in import_msg
    [c.save() for c in self.contact_imports]
  File "/home/lenovo/projects/contact/gmail/parsers.py", line 95, in save
    c = self.__save_contact(c)
  File "/home/lenovo/projects/contact/gmail/parsers.py", line 90, in __save_contact
    contact.save()
  File "/home/lenovo/Envs/contact/local/lib/python2.7/site-packages/django/db/models/base.py", line 545, in save
    force_update=force_update, update_fields=update_fields)
  File "/home/lenovo/Envs/contact/local/lib/python2.7/site-packages/django/db/models/base.py", line 573, in save_base
    updated = self._save_table(raw, cls, force_insert, force_update, using, update_fields)
  File "/home/lenovo/Envs/contact/local/lib/python2.7/site-packages/django/db/models/base.py", line 654, in _save_table
    result = self._do_insert(cls._base_manager, using, fields, update_pk, raw)
  File "/home/lenovo/Envs/contact/local/lib/python2.7/site-packages/django/db/models/base.py", line 687, in _do_insert
    using=using, raw=raw)
  File "/home/lenovo/Envs/contact/local/lib/python2.7/site-packages/django/db/models/manager.py", line 232, in _insert
    return insert_query(self.model, objs, fields, **kwargs)
  File "/home/lenovo/Envs/contact/local/lib/python2.7/site-packages/django/db/models/query.py", line 1514, in insert_query
    return query.get_compiler(using=using).execute_sql(return_id)
  File "/home/lenovo/Envs/contact/local/lib/python2.7/site-packages/django/db/models/sql/compiler.py", line 903, in execute_sql
    cursor.execute(sql, params)
  File "/home/lenovo/Envs/contact/local/lib/python2.7/site-packages/django/db/backends/util.py", line 69, in execute
    return super(CursorDebugWrapper, self).execute(sql, params)
  File "/home/lenovo/Envs/contact/local/lib/python2.7/site-packages/django/db/backends/util.py", line 53, in execute
    return self.cursor.execute(sql, params)
  File "/home/lenovo/Envs/contact/local/lib/python2.7/site-packages/django/db/utils.py", line 99, in __exit__
    six.reraise(dj_exc_type, dj_exc_value, traceback)
  File "/home/lenovo/Envs/contact/local/lib/python2.7/site-packages/django/db/backends/util.py", line 53, in execute
    return self.cursor.execute(sql, params)
DataError: value too long for type character varying(128)

[04/Aug/2014 16:50:45] WARNING [django.request:143] Not Found: /{[l.image_url]}
[04/Aug/2014 16:50:55] ERROR [django.request:224] Internal Server Error: /inbox/refresh/
Traceback (most recent call last):
  File "/home/lenovo/Envs/contact/local/lib/python2.7/site-packages/django/core/handlers/base.py", line 112, in get_response
    response = wrapped_callback(request, *callback_args, **callback_kwargs)
  File "/home/lenovo/Envs/contact/local/lib/python2.7/site-packages/django/views/generic/base.py", line 69, in view
    return self.dispatch(request, *args, **kwargs)
  File "/home/lenovo/Envs/contact/local/lib/python2.7/site-packages/django/views/decorators/csrf.py", line 57, in wrapped_view
    return view_func(*args, **kwargs)
  File "/home/lenovo/Envs/contact/local/lib/python2.7/site-packages/rest_framework/views.py", line 400, in dispatch
    response = self.handle_exception(exc)
  File "/home/lenovo/Envs/contact/local/lib/python2.7/site-packages/rest_framework/views.py", line 397, in dispatch
    response = handler(request, *args, **kwargs)
  File "/home/lenovo/Envs/contact/local/lib/python2.7/site-packages/django/db/transaction.py", line 371, in inner
    return func(*args, **kwargs)
  File "/home/lenovo/projects/contact/gmail/views.py", line 36, in get
    result = in_import.import_new()
  File "/home/lenovo/projects/contact/gmail/parsers.py", line 49, in import_new
    return self.__import()
  File "/home/lenovo/projects/contact/gmail/parsers.py", line 37, in __import
    self.__process_response(response)
  File "/home/lenovo/projects/contact/gmail/parsers.py", line 28, in __process_response
    mail_import.import_msg()
  File "/home/lenovo/projects/contact/gmail/parsers.py", line 161, in import_msg
    [c.save() for c in self.contact_imports]
  File "/home/lenovo/projects/contact/gmail/parsers.py", line 96, in save
    c = self.__save_contact(c)
  File "/home/lenovo/projects/contact/gmail/parsers.py", line 90, in __save_contact
    contact.save()
  File "/home/lenovo/Envs/contact/local/lib/python2.7/site-packages/django/db/models/base.py", line 545, in save
    force_update=force_update, update_fields=update_fields)
  File "/home/lenovo/Envs/contact/local/lib/python2.7/site-packages/django/db/models/base.py", line 573, in save_base
    updated = self._save_table(raw, cls, force_insert, force_update, using, update_fields)
  File "/home/lenovo/Envs/contact/local/lib/python2.7/site-packages/django/db/models/base.py", line 654, in _save_table
    result = self._do_insert(cls._base_manager, using, fields, update_pk, raw)
  File "/home/lenovo/Envs/contact/local/lib/python2.7/site-packages/django/db/models/base.py", line 687, in _do_insert
    using=using, raw=raw)
  File "/home/lenovo/Envs/contact/local/lib/python2.7/site-packages/django/db/models/manager.py", line 232, in _insert
    return insert_query(self.model, objs, fields, **kwargs)
  File "/home/lenovo/Envs/contact/local/lib/python2.7/site-packages/django/db/models/query.py", line 1514, in insert_query
    return query.get_compiler(using=using).execute_sql(return_id)
  File "/home/lenovo/Envs/contact/local/lib/python2.7/site-packages/django/db/models/sql/compiler.py", line 903, in execute_sql
    cursor.execute(sql, params)
  File "/home/lenovo/Envs/contact/local/lib/python2.7/site-packages/django/db/backends/util.py", line 69, in execute
    return super(CursorDebugWrapper, self).execute(sql, params)
  File "/home/lenovo/Envs/contact/local/lib/python2.7/site-packages/django/db/backends/util.py", line 53, in execute
    return self.cursor.execute(sql, params)
  File "/home/lenovo/Envs/contact/local/lib/python2.7/site-packages/django/db/utils.py", line 99, in __exit__
    six.reraise(dj_exc_type, dj_exc_value, traceback)
  File "/home/lenovo/Envs/contact/local/lib/python2.7/site-packages/django/db/backends/util.py", line 53, in execute
    return self.cursor.execute(sql, params)
DataError: value too long for type character varying(128)

[04/Aug/2014 17:48:13] WARNING [django.request:143] Not Found: /{[l.image_url]}
[04/Aug/2014 17:48:17] ERROR [django.request:224] Internal Server Error: /inbox/refresh/
Traceback (most recent call last):
  File "/home/lenovo/Envs/contact/local/lib/python2.7/site-packages/django/core/handlers/base.py", line 112, in get_response
    response = wrapped_callback(request, *callback_args, **callback_kwargs)
  File "/home/lenovo/Envs/contact/local/lib/python2.7/site-packages/django/views/generic/base.py", line 69, in view
    return self.dispatch(request, *args, **kwargs)
  File "/home/lenovo/Envs/contact/local/lib/python2.7/site-packages/django/views/decorators/csrf.py", line 57, in wrapped_view
    return view_func(*args, **kwargs)
  File "/home/lenovo/Envs/contact/local/lib/python2.7/site-packages/rest_framework/views.py", line 400, in dispatch
    response = self.handle_exception(exc)
  File "/home/lenovo/Envs/contact/local/lib/python2.7/site-packages/rest_framework/views.py", line 397, in dispatch
    response = handler(request, *args, **kwargs)
  File "/home/lenovo/Envs/contact/local/lib/python2.7/site-packages/django/db/transaction.py", line 371, in inner
    return func(*args, **kwargs)
  File "/home/lenovo/projects/contact/gmail/views.py", line 36, in get
    result = in_import.import_new()
  File "/home/lenovo/projects/contact/gmail/parsers.py", line 49, in import_new
    return self.__import()
  File "/home/lenovo/projects/contact/gmail/parsers.py", line 37, in __import
    self.__process_response(response)
  File "/home/lenovo/projects/contact/gmail/parsers.py", line 28, in __process_response
    mail_import.import_msg()
  File "/home/lenovo/projects/contact/gmail/parsers.py", line 164, in import_msg
    self.__import_msg()
  File "/home/lenovo/projects/contact/gmail/parsers.py", line 138, in __import_msg
    self.__import_from_header()
  File "/home/lenovo/projects/contact/gmail/parsers.py", line 151, in __import_from_header
    self.__import_contacts(value, MailDirection.value(name))
  File "/home/lenovo/projects/contact/gmail/parsers.py", line 130, in __import_contacts
    contact_in = ContactsImport(response, dir_type, self.user, self.mail)
  File "/home/lenovo/projects/contact/gmail/parsers.py", line 73, in __init__
    if ',' in c and '<' not in c:
TypeError: argument of type 'MailContact' is not iterable
[04/Aug/2014 17:51:58] WARNING [django.request:143] Not Found: /{[l.image_url]}
[04/Aug/2014 17:52:05] ERROR [django.request:224] Internal Server Error: /inbox/refresh/
Traceback (most recent call last):
  File "/home/lenovo/Envs/contact/local/lib/python2.7/site-packages/django/core/handlers/base.py", line 112, in get_response
    response = wrapped_callback(request, *callback_args, **callback_kwargs)
  File "/home/lenovo/Envs/contact/local/lib/python2.7/site-packages/django/views/generic/base.py", line 69, in view
    return self.dispatch(request, *args, **kwargs)
  File "/home/lenovo/Envs/contact/local/lib/python2.7/site-packages/django/views/decorators/csrf.py", line 57, in wrapped_view
    return view_func(*args, **kwargs)
  File "/home/lenovo/Envs/contact/local/lib/python2.7/site-packages/rest_framework/views.py", line 400, in dispatch
    response = self.handle_exception(exc)
  File "/home/lenovo/Envs/contact/local/lib/python2.7/site-packages/rest_framework/views.py", line 397, in dispatch
    response = handler(request, *args, **kwargs)
  File "/home/lenovo/Envs/contact/local/lib/python2.7/site-packages/django/db/transaction.py", line 371, in inner
    return func(*args, **kwargs)
  File "/home/lenovo/projects/contact/gmail/views.py", line 36, in get
    result = in_import.import_new()
  File "/home/lenovo/projects/contact/gmail/parsers.py", line 49, in import_new
    return self.__import()
  File "/home/lenovo/projects/contact/gmail/parsers.py", line 37, in __import
    self.__process_response(response)
  File "/home/lenovo/projects/contact/gmail/parsers.py", line 28, in __process_response
    mail_import.import_msg()
  File "/home/lenovo/projects/contact/gmail/parsers.py", line 165, in import_msg
    self.__import_msg()
  File "/home/lenovo/projects/contact/gmail/parsers.py", line 139, in __import_msg
    self.__import_from_header()
  File "/home/lenovo/projects/contact/gmail/parsers.py", line 152, in __import_from_header
    self.__import_contacts(value, MailDirection.value(name))
  File "/home/lenovo/projects/contact/gmail/parsers.py", line 131, in __import_contacts
    contact_in = ContactsImport(response, dir_type, self.user, self.mail)
  File "/home/lenovo/projects/contact/gmail/parsers.py", line 74, in __init__
    if ',' in c and '<' not in c:
TypeError: argument of type 'MailContact' is not iterable
[04/Aug/2014 17:53:28] WARNING [django.request:143] Not Found: /{[l.image_url]}
[04/Aug/2014 17:53:34] ERROR [django.request:224] Internal Server Error: /inbox/refresh/
Traceback (most recent call last):
  File "/home/lenovo/Envs/contact/local/lib/python2.7/site-packages/django/core/handlers/base.py", line 112, in get_response
    response = wrapped_callback(request, *callback_args, **callback_kwargs)
  File "/home/lenovo/Envs/contact/local/lib/python2.7/site-packages/django/views/generic/base.py", line 69, in view
    return self.dispatch(request, *args, **kwargs)
  File "/home/lenovo/Envs/contact/local/lib/python2.7/site-packages/django/views/decorators/csrf.py", line 57, in wrapped_view
    return view_func(*args, **kwargs)
  File "/home/lenovo/Envs/contact/local/lib/python2.7/site-packages/rest_framework/views.py", line 400, in dispatch
    response = self.handle_exception(exc)
  File "/home/lenovo/Envs/contact/local/lib/python2.7/site-packages/rest_framework/views.py", line 397, in dispatch
    response = handler(request, *args, **kwargs)
  File "/home/lenovo/Envs/contact/local/lib/python2.7/site-packages/django/db/transaction.py", line 371, in inner
    return func(*args, **kwargs)
  File "/home/lenovo/projects/contact/gmail/views.py", line 36, in get
    result = in_import.import_new()
  File "/home/lenovo/projects/contact/gmail/parsers.py", line 49, in import_new
    return self.__import()
  File "/home/lenovo/projects/contact/gmail/parsers.py", line 37, in __import
    self.__process_response(response)
  File "/home/lenovo/projects/contact/gmail/parsers.py", line 28, in __process_response
    mail_import.import_msg()
  File "/home/lenovo/projects/contact/gmail/parsers.py", line 165, in import_msg
    self.__import_msg()
  File "/home/lenovo/projects/contact/gmail/parsers.py", line 139, in __import_msg
    self.__import_from_header()
  File "/home/lenovo/projects/contact/gmail/parsers.py", line 152, in __import_from_header
    self.__import_contacts(value, MailDirection.value(name))
  File "/home/lenovo/projects/contact/gmail/parsers.py", line 131, in __import_contacts
    contact_in = ContactsImport(response, dir_type, self.user, self.mail)
  File "/home/lenovo/projects/contact/gmail/parsers.py", line 75, in __init__
    self.contacts += c.split(',')
AttributeError: 'MailContact' object has no attribute 'split'
[04/Aug/2014 17:55:01] WARNING [django.request:143] Not Found: /{[l.image_url]}
[04/Aug/2014 17:55:14] ERROR [django.request:224] Internal Server Error: /inbox/refresh/
Traceback (most recent call last):
  File "/home/lenovo/Envs/contact/local/lib/python2.7/site-packages/django/core/handlers/base.py", line 112, in get_response
    response = wrapped_callback(request, *callback_args, **callback_kwargs)
  File "/home/lenovo/Envs/contact/local/lib/python2.7/site-packages/django/views/generic/base.py", line 69, in view
    return self.dispatch(request, *args, **kwargs)
  File "/home/lenovo/Envs/contact/local/lib/python2.7/site-packages/django/views/decorators/csrf.py", line 57, in wrapped_view
    return view_func(*args, **kwargs)
  File "/home/lenovo/Envs/contact/local/lib/python2.7/site-packages/rest_framework/views.py", line 400, in dispatch
    response = self.handle_exception(exc)
  File "/home/lenovo/Envs/contact/local/lib/python2.7/site-packages/rest_framework/views.py", line 397, in dispatch
    response = handler(request, *args, **kwargs)
  File "/home/lenovo/Envs/contact/local/lib/python2.7/site-packages/django/db/transaction.py", line 371, in inner
    return func(*args, **kwargs)
  File "/home/lenovo/projects/contact/gmail/views.py", line 36, in get
    result = in_import.import_new()
  File "/home/lenovo/projects/contact/gmail/parsers.py", line 49, in import_new
    return self.__import()
  File "/home/lenovo/projects/contact/gmail/parsers.py", line 37, in __import
    self.__process_response(response)
  File "/home/lenovo/projects/contact/gmail/parsers.py", line 28, in __process_response
    mail_import.import_msg()
  File "/home/lenovo/projects/contact/gmail/parsers.py", line 163, in import_msg
    self.__import_msg()
  File "/home/lenovo/projects/contact/gmail/parsers.py", line 137, in __import_msg
    self.__import_from_header()
  File "/home/lenovo/projects/contact/gmail/parsers.py", line 150, in __import_from_header
    self.__import_contacts(value, MailDirection.value(name))
  File "/home/lenovo/projects/contact/gmail/parsers.py", line 129, in __import_contacts
    contact_in = ContactsImport(response, dir_type, self.user, self.mail)
  File "/home/lenovo/projects/contact/gmail/parsers.py", line 74, in __init__
    self.contacts += [self.__get_contact(m) for m in c.split(',')]
AttributeError: 'MailContact' object has no attribute 'split'
[04/Aug/2014 17:55:55] WARNING [django.request:143] Not Found: /{[l.image_url]}
[04/Aug/2014 17:55:55] WARNING [django.request:143] Not Found: /{[l.image_url]}
[04/Aug/2014 17:56:30] WARNING [django.request:143] Not Found: /{[l.image_url]}
[04/Aug/2014 17:56:30] WARNING [django.request:143] Not Found: /{[l.image_url]}
[04/Aug/2014 18:00:51] WARNING [django.request:143] Not Found: /{[l.image_url]}
[04/Aug/2014 18:01:19] WARNING [django.request:143] Not Found: /{[l.image_url]}
[04/Aug/2014 18:01:19] WARNING [django.request:143] Not Found: /{[l.image_url]}
[04/Aug/2014 18:05:42] ERROR [django.request:224] Internal Server Error: /lkdn/duplicates/18/
Traceback (most recent call last):
  File "/home/lenovo/Envs/contact/local/lib/python2.7/site-packages/django/core/handlers/base.py", line 112, in get_response
    response = wrapped_callback(request, *callback_args, **callback_kwargs)
  File "/home/lenovo/Envs/contact/local/lib/python2.7/site-packages/django/views/generic/base.py", line 69, in view
    return self.dispatch(request, *args, **kwargs)
  File "/home/lenovo/Envs/contact/local/lib/python2.7/site-packages/django/views/decorators/csrf.py", line 57, in wrapped_view
    return view_func(*args, **kwargs)
  File "/home/lenovo/Envs/contact/local/lib/python2.7/site-packages/rest_framework/views.py", line 400, in dispatch
    response = self.handle_exception(exc)
  File "/home/lenovo/Envs/contact/local/lib/python2.7/site-packages/rest_framework/views.py", line 397, in dispatch
    response = handler(request, *args, **kwargs)
  File "/home/lenovo/projects/contact/lkdn/views.py", line 42, in get
    c = UserContact.objects.get(pk=cid)
  File "/home/lenovo/Envs/contact/local/lib/python2.7/site-packages/django/db/models/manager.py", line 151, in get
    return self.get_queryset().get(*args, **kwargs)
  File "/home/lenovo/Envs/contact/local/lib/python2.7/site-packages/django/db/models/query.py", line 310, in get
    self.model._meta.object_name)
DoesNotExist: UserContact matching query does not exist.
[04/Aug/2014 18:05:43] ERROR [django.request:224] Internal Server Error: /contact/duplicates/18/
Traceback (most recent call last):
  File "/home/lenovo/Envs/contact/local/lib/python2.7/site-packages/django/core/handlers/base.py", line 112, in get_response
    response = wrapped_callback(request, *callback_args, **callback_kwargs)
  File "/home/lenovo/Envs/contact/local/lib/python2.7/site-packages/django/views/generic/base.py", line 69, in view
    return self.dispatch(request, *args, **kwargs)
  File "/home/lenovo/Envs/contact/local/lib/python2.7/site-packages/django/views/decorators/csrf.py", line 57, in wrapped_view
    return view_func(*args, **kwargs)
  File "/home/lenovo/Envs/contact/local/lib/python2.7/site-packages/rest_framework/views.py", line 400, in dispatch
    response = self.handle_exception(exc)
  File "/home/lenovo/Envs/contact/local/lib/python2.7/site-packages/rest_framework/views.py", line 397, in dispatch
    response = handler(request, *args, **kwargs)
  File "/home/lenovo/projects/contact/manager/views.py", line 42, in get
    c = UserContact.objects.get(pk=cid)
  File "/home/lenovo/Envs/contact/local/lib/python2.7/site-packages/django/db/models/manager.py", line 151, in get
    return self.get_queryset().get(*args, **kwargs)
  File "/home/lenovo/Envs/contact/local/lib/python2.7/site-packages/django/db/models/query.py", line 310, in get
    self.model._meta.object_name)
DoesNotExist: UserContact matching query does not exist.
[04/Aug/2014 18:05:43] ERROR [django.request:224] Internal Server Error: /contact/comm_items/18/
Traceback (most recent call last):
  File "/home/lenovo/Envs/contact/local/lib/python2.7/site-packages/django/core/handlers/base.py", line 112, in get_response
    response = wrapped_callback(request, *callback_args, **callback_kwargs)
  File "/home/lenovo/Envs/contact/local/lib/python2.7/site-packages/django/views/generic/base.py", line 69, in view
    return self.dispatch(request, *args, **kwargs)
  File "/home/lenovo/Envs/contact/local/lib/python2.7/site-packages/django/views/decorators/csrf.py", line 57, in wrapped_view
    return view_func(*args, **kwargs)
  File "/home/lenovo/Envs/contact/local/lib/python2.7/site-packages/rest_framework/views.py", line 400, in dispatch
    response = self.handle_exception(exc)
  File "/home/lenovo/Envs/contact/local/lib/python2.7/site-packages/rest_framework/views.py", line 397, in dispatch
    response = handler(request, *args, **kwargs)
  File "/home/lenovo/projects/contact/contact/views.py", line 41, in get
    contact = UserContact.objects.get(pk=cid)
  File "/home/lenovo/Envs/contact/local/lib/python2.7/site-packages/django/db/models/manager.py", line 151, in get
    return self.get_queryset().get(*args, **kwargs)
  File "/home/lenovo/Envs/contact/local/lib/python2.7/site-packages/django/db/models/query.py", line 310, in get
    self.model._meta.object_name)
DoesNotExist: UserContact matching query does not exist.
[04/Aug/2014 18:12:45] WARNING [django.request:143] Not Found: /{[l.image_url]}
[04/Aug/2014 18:12:45] WARNING [django.request:143] Not Found: /{[l.image_url]}
[04/Aug/2014 18:12:46] WARNING [django.request:143] Not Found: /{[l.image_url]}
[05/Aug/2014 04:07:36] WARNING [django.request:143] Not Found: /favicon.ico
[05/Aug/2014 04:10:45] WARNING [django.request:143] Not Found: /favicon.ico
[05/Aug/2014 05:44:29] ERROR [django.request:224] Internal Server Error: /contact/bymonth/23/
Traceback (most recent call last):
  File "/home/lenovo/Envs/contact/local/lib/python2.7/site-packages/django/core/handlers/base.py", line 112, in get_response
    response = wrapped_callback(request, *callback_args, **callback_kwargs)
  File "/home/lenovo/Envs/contact/local/lib/python2.7/site-packages/django/views/generic/base.py", line 69, in view
    return self.dispatch(request, *args, **kwargs)
  File "/home/lenovo/Envs/contact/local/lib/python2.7/site-packages/django/views/generic/base.py", line 87, in dispatch
    return handler(request, *args, **kwargs)
  File "/home/lenovo/projects/contact/contact/views.py", line 54, in get
    item = result.get(c.month, [])
AttributeError: CommItem instance has no attribute 'month'
[05/Aug/2014 05:58:53] WARNING [django.request:143] Not Found: /contact/bymonth/11/
[05/Aug/2014 05:59:00] ERROR [django.request:224] Internal Server Error: /contact/by_month/11/
Traceback (most recent call last):
  File "/home/lenovo/Envs/contact/local/lib/python2.7/site-packages/django/core/handlers/base.py", line 112, in get_response
    response = wrapped_callback(request, *callback_args, **callback_kwargs)
  File "/home/lenovo/Envs/contact/local/lib/python2.7/site-packages/django/views/generic/base.py", line 69, in view
    return self.dispatch(request, *args, **kwargs)
  File "/home/lenovo/Envs/contact/local/lib/python2.7/site-packages/django/views/generic/base.py", line 87, in dispatch
    return handler(request, *args, **kwargs)
  File "/home/lenovo/projects/contact/contact/views.py", line 59, in get
    for (k,v) in inter_result:
ValueError: too many values to unpack
[05/Aug/2014 06:23:25] ERROR [django.request:224] Internal Server Error: /contact/by_month/11/
Traceback (most recent call last):
  File "/home/lenovo/Envs/contact/local/lib/python2.7/site-packages/django/core/handlers/base.py", line 137, in get_response
    response = response.render()
  File "/home/lenovo/Envs/contact/local/lib/python2.7/site-packages/django/template/response.py", line 105, in render
    self.content = self.rendered_content
  File "/home/lenovo/Envs/contact/local/lib/python2.7/site-packages/rest_framework/response.py", line 59, in rendered_content
    ret = renderer.render(self.data, media_type, context)
  File "/home/lenovo/Envs/contact/local/lib/python2.7/site-packages/rest_framework/renderers.py", line 600, in render
    template = loader.get_template(self.template)
  File "/home/lenovo/Envs/contact/local/lib/python2.7/site-packages/django/template/loader.py", line 138, in get_template
    template, origin = find_template(template_name)
  File "/home/lenovo/Envs/contact/local/lib/python2.7/site-packages/django/template/loader.py", line 131, in find_template
    raise TemplateDoesNotExist(name)
TemplateDoesNotExist: rest_framework/api.html
[05/Aug/2014 06:39:14] ERROR [django.request:224] Internal Server Error: /contact/by_month/11/
Traceback (most recent call last):
  File "/home/lenovo/Envs/contact/local/lib/python2.7/site-packages/django/core/handlers/base.py", line 112, in get_response
    response = wrapped_callback(request, *callback_args, **callback_kwargs)
  File "/home/lenovo/Envs/contact/local/lib/python2.7/site-packages/django/views/generic/base.py", line 69, in view
    return self.dispatch(request, *args, **kwargs)
  File "/home/lenovo/Envs/contact/local/lib/python2.7/site-packages/django/views/decorators/csrf.py", line 57, in wrapped_view
    return view_func(*args, **kwargs)
  File "/home/lenovo/Envs/contact/local/lib/python2.7/site-packages/rest_framework/views.py", line 400, in dispatch
    response = self.handle_exception(exc)
  File "/home/lenovo/Envs/contact/local/lib/python2.7/site-packages/rest_framework/views.py", line 397, in dispatch
    response = handler(request, *args, **kwargs)
  File "/home/lenovo/projects/contact/contact/views.py", line 58, in get
    result = [CommStat(month=month_name[i], count=inter_result[i], index=i) for i in inter_result]
  File "/usr/lib/python2.7/calendar.py", line 56, in __getitem__
    funcs = self._months[i]
TypeError: list indices must be integers, not str
[05/Aug/2014 06:39:19] ERROR [django.request:224] Internal Server Error: /contact/by_month/11/
Traceback (most recent call last):
  File "/home/lenovo/Envs/contact/local/lib/python2.7/site-packages/django/core/handlers/base.py", line 112, in get_response
    response = wrapped_callback(request, *callback_args, **callback_kwargs)
  File "/home/lenovo/Envs/contact/local/lib/python2.7/site-packages/django/views/generic/base.py", line 69, in view
    return self.dispatch(request, *args, **kwargs)
  File "/home/lenovo/Envs/contact/local/lib/python2.7/site-packages/django/views/decorators/csrf.py", line 57, in wrapped_view
    return view_func(*args, **kwargs)
  File "/home/lenovo/Envs/contact/local/lib/python2.7/site-packages/rest_framework/views.py", line 400, in dispatch
    response = self.handle_exception(exc)
  File "/home/lenovo/Envs/contact/local/lib/python2.7/site-packages/rest_framework/views.py", line 397, in dispatch
    response = handler(request, *args, **kwargs)
  File "/home/lenovo/projects/contact/contact/views.py", line 58, in get
    result = [CommStat(month=month_name[i], count=inter_result[i], index=i) for i in inter_result]
  File "/usr/lib/python2.7/calendar.py", line 56, in __getitem__
    funcs = self._months[i]
TypeError: list indices must be integers, not str
[05/Aug/2014 06:40:10] ERROR [django.request:224] Internal Server Error: /contact/by_month/11/
Traceback (most recent call last):
  File "/home/lenovo/Envs/contact/local/lib/python2.7/site-packages/django/core/handlers/base.py", line 112, in get_response
    response = wrapped_callback(request, *callback_args, **callback_kwargs)
  File "/home/lenovo/Envs/contact/local/lib/python2.7/site-packages/django/views/generic/base.py", line 69, in view
    return self.dispatch(request, *args, **kwargs)
  File "/home/lenovo/Envs/contact/local/lib/python2.7/site-packages/django/views/decorators/csrf.py", line 57, in wrapped_view
    return view_func(*args, **kwargs)
  File "/home/lenovo/Envs/contact/local/lib/python2.7/site-packages/rest_framework/views.py", line 400, in dispatch
    response = self.handle_exception(exc)
  File "/home/lenovo/Envs/contact/local/lib/python2.7/site-packages/rest_framework/views.py", line 397, in dispatch
    response = handler(request, *args, **kwargs)
  File "/home/lenovo/projects/contact/contact/views.py", line 58, in get
    result = [CommStat(month=month_name[int(i)], count=inter_result[i], index=i) for i in inter_result]
ValueError: invalid literal for int() with base 10: 'July'
[05/Aug/2014 06:41:21] ERROR [django.request:224] Internal Server Error: /contact/by_month/11/
Traceback (most recent call last):
  File "/home/lenovo/Envs/contact/local/lib/python2.7/site-packages/django/core/handlers/base.py", line 112, in get_response
    response = wrapped_callback(request, *callback_args, **callback_kwargs)
  File "/home/lenovo/Envs/contact/local/lib/python2.7/site-packages/django/views/generic/base.py", line 69, in view
    return self.dispatch(request, *args, **kwargs)
  File "/home/lenovo/Envs/contact/local/lib/python2.7/site-packages/django/views/decorators/csrf.py", line 57, in wrapped_view
    return view_func(*args, **kwargs)
  File "/home/lenovo/Envs/contact/local/lib/python2.7/site-packages/rest_framework/views.py", line 400, in dispatch
    response = self.handle_exception(exc)
  File "/home/lenovo/Envs/contact/local/lib/python2.7/site-packages/rest_framework/views.py", line 397, in dispatch
    response = handler(request, *args, **kwargs)
  File "/home/lenovo/projects/contact/contact/views.py", line 59, in get
    result.sort(lambda x: x.index)
TypeError: <lambda>() takes exactly 1 argument (2 given)
[05/Aug/2014 06:48:25] ERROR [django.request:224] Internal Server Error: /
Traceback (most recent call last):
  File "/home/lenovo/Envs/contact/local/lib/python2.7/site-packages/django/core/handlers/base.py", line 112, in get_response
    response = wrapped_callback(request, *callback_args, **callback_kwargs)
  File "/home/lenovo/Envs/contact/local/lib/python2.7/site-packages/django/contrib/auth/decorators.py", line 22, in _wrapped_view
    return view_func(request, *args, **kwargs)
  File "/home/lenovo/projects/contact/manager/views.py", line 19, in home
    return render_to_response('inbox_home.html')
  File "/home/lenovo/Envs/contact/local/lib/python2.7/site-packages/django/shortcuts/__init__.py", line 29, in render_to_response
    return HttpResponse(loader.render_to_string(*args, **kwargs), **httpresponse_kwargs)
  File "/home/lenovo/Envs/contact/local/lib/python2.7/site-packages/django/template/loader.py", line 162, in render_to_string
    t = get_template(template_name)
  File "/home/lenovo/Envs/contact/local/lib/python2.7/site-packages/django/template/loader.py", line 138, in get_template
    template, origin = find_template(template_name)
  File "/home/lenovo/Envs/contact/local/lib/python2.7/site-packages/django/template/loader.py", line 127, in find_template
    source, display_name = loader(name, dirs)
  File "/home/lenovo/Envs/contact/local/lib/python2.7/site-packages/django/template/loader.py", line 43, in __call__
    return self.load_template(template_name, template_dirs)
  File "/home/lenovo/Envs/contact/local/lib/python2.7/site-packages/django/template/loader.py", line 49, in load_template
    template = get_template_from_string(source, origin, template_name)
  File "/home/lenovo/Envs/contact/local/lib/python2.7/site-packages/django/template/loader.py", line 149, in get_template_from_string
    return Template(source, origin, name)
  File "/home/lenovo/Envs/contact/local/lib/python2.7/site-packages/django/template/base.py", line 125, in __init__
    self.nodelist = compile_string(template_string, origin)
  File "/home/lenovo/Envs/contact/local/lib/python2.7/site-packages/django/template/base.py", line 153, in compile_string
    return parser.parse()
  File "/home/lenovo/Envs/contact/local/lib/python2.7/site-packages/django/template/base.py", line 254, in parse
    filter_expression = self.compile_filter(token.contents)
  File "/home/lenovo/Envs/contact/local/lib/python2.7/site-packages/django/template/base.py", line 360, in compile_filter
    return FilterExpression(token, self)
  File "/home/lenovo/Envs/contact/local/lib/python2.7/site-packages/django/template/base.py", line 571, in __init__
    filter_func = parser.find_filter(filter_name)
  File "/home/lenovo/Envs/contact/local/lib/python2.7/site-packages/django/template/base.py", line 366, in find_filter
    raise TemplateSyntaxError("Invalid filter: '%s'" % filter_name)
TemplateSyntaxError: Invalid filter: 'date_mdy'
[05/Aug/2014 06:49:12] ERROR [django.request:224] Internal Server Error: /
Traceback (most recent call last):
  File "/home/lenovo/Envs/contact/local/lib/python2.7/site-packages/django/core/handlers/base.py", line 112, in get_response
    response = wrapped_callback(request, *callback_args, **callback_kwargs)
  File "/home/lenovo/Envs/contact/local/lib/python2.7/site-packages/django/contrib/auth/decorators.py", line 22, in _wrapped_view
    return view_func(request, *args, **kwargs)
  File "/home/lenovo/projects/contact/manager/views.py", line 19, in home
    return render_to_response('inbox_home.html')
  File "/home/lenovo/Envs/contact/local/lib/python2.7/site-packages/django/shortcuts/__init__.py", line 29, in render_to_response
    return HttpResponse(loader.render_to_string(*args, **kwargs), **httpresponse_kwargs)
  File "/home/lenovo/Envs/contact/local/lib/python2.7/site-packages/django/template/loader.py", line 162, in render_to_string
    t = get_template(template_name)
  File "/home/lenovo/Envs/contact/local/lib/python2.7/site-packages/django/template/loader.py", line 138, in get_template
    template, origin = find_template(template_name)
  File "/home/lenovo/Envs/contact/local/lib/python2.7/site-packages/django/template/loader.py", line 127, in find_template
    source, display_name = loader(name, dirs)
  File "/home/lenovo/Envs/contact/local/lib/python2.7/site-packages/django/template/loader.py", line 43, in __call__
    return self.load_template(template_name, template_dirs)
  File "/home/lenovo/Envs/contact/local/lib/python2.7/site-packages/django/template/loader.py", line 49, in load_template
    template = get_template_from_string(source, origin, template_name)
  File "/home/lenovo/Envs/contact/local/lib/python2.7/site-packages/django/template/loader.py", line 149, in get_template_from_string
    return Template(source, origin, name)
  File "/home/lenovo/Envs/contact/local/lib/python2.7/site-packages/django/template/base.py", line 125, in __init__
    self.nodelist = compile_string(template_string, origin)
  File "/home/lenovo/Envs/contact/local/lib/python2.7/site-packages/django/template/base.py", line 153, in compile_string
    return parser.parse()
  File "/home/lenovo/Envs/contact/local/lib/python2.7/site-packages/django/template/base.py", line 254, in parse
    filter_expression = self.compile_filter(token.contents)
  File "/home/lenovo/Envs/contact/local/lib/python2.7/site-packages/django/template/base.py", line 360, in compile_filter
    return FilterExpression(token, self)
  File "/home/lenovo/Envs/contact/local/lib/python2.7/site-packages/django/template/base.py", line 571, in __init__
    filter_func = parser.find_filter(filter_name)
  File "/home/lenovo/Envs/contact/local/lib/python2.7/site-packages/django/template/base.py", line 366, in find_filter
    raise TemplateSyntaxError("Invalid filter: '%s'" % filter_name)
TemplateSyntaxError: Invalid filter: 'date_mdy'
[05/Aug/2014 06:49:35] ERROR [django.request:224] Internal Server Error: /
Traceback (most recent call last):
  File "/home/lenovo/Envs/contact/local/lib/python2.7/site-packages/django/core/handlers/base.py", line 112, in get_response
    response = wrapped_callback(request, *callback_args, **callback_kwargs)
  File "/home/lenovo/Envs/contact/local/lib/python2.7/site-packages/django/contrib/auth/decorators.py", line 22, in _wrapped_view
    return view_func(request, *args, **kwargs)
  File "/home/lenovo/projects/contact/manager/views.py", line 19, in home
    return render_to_response('inbox_home.html')
  File "/home/lenovo/Envs/contact/local/lib/python2.7/site-packages/django/shortcuts/__init__.py", line 29, in render_to_response
    return HttpResponse(loader.render_to_string(*args, **kwargs), **httpresponse_kwargs)
  File "/home/lenovo/Envs/contact/local/lib/python2.7/site-packages/django/template/loader.py", line 162, in render_to_string
    t = get_template(template_name)
  File "/home/lenovo/Envs/contact/local/lib/python2.7/site-packages/django/template/loader.py", line 138, in get_template
    template, origin = find_template(template_name)
  File "/home/lenovo/Envs/contact/local/lib/python2.7/site-packages/django/template/loader.py", line 127, in find_template
    source, display_name = loader(name, dirs)
  File "/home/lenovo/Envs/contact/local/lib/python2.7/site-packages/django/template/loader.py", line 43, in __call__
    return self.load_template(template_name, template_dirs)
  File "/home/lenovo/Envs/contact/local/lib/python2.7/site-packages/django/template/loader.py", line 49, in load_template
    template = get_template_from_string(source, origin, template_name)
  File "/home/lenovo/Envs/contact/local/lib/python2.7/site-packages/django/template/loader.py", line 149, in get_template_from_string
    return Template(source, origin, name)
  File "/home/lenovo/Envs/contact/local/lib/python2.7/site-packages/django/template/base.py", line 125, in __init__
    self.nodelist = compile_string(template_string, origin)
  File "/home/lenovo/Envs/contact/local/lib/python2.7/site-packages/django/template/base.py", line 153, in compile_string
    return parser.parse()
  File "/home/lenovo/Envs/contact/local/lib/python2.7/site-packages/django/template/base.py", line 254, in parse
    filter_expression = self.compile_filter(token.contents)
  File "/home/lenovo/Envs/contact/local/lib/python2.7/site-packages/django/template/base.py", line 360, in compile_filter
    return FilterExpression(token, self)
  File "/home/lenovo/Envs/contact/local/lib/python2.7/site-packages/django/template/base.py", line 571, in __init__
    filter_func = parser.find_filter(filter_name)
  File "/home/lenovo/Envs/contact/local/lib/python2.7/site-packages/django/template/base.py", line 366, in find_filter
    raise TemplateSyntaxError("Invalid filter: '%s'" % filter_name)
TemplateSyntaxError: Invalid filter: 'date_mdy'
[05/Aug/2014 06:49:36] ERROR [django.request:224] Internal Server Error: /
Traceback (most recent call last):
  File "/home/lenovo/Envs/contact/local/lib/python2.7/site-packages/django/core/handlers/base.py", line 112, in get_response
    response = wrapped_callback(request, *callback_args, **callback_kwargs)
  File "/home/lenovo/Envs/contact/local/lib/python2.7/site-packages/django/contrib/auth/decorators.py", line 22, in _wrapped_view
    return view_func(request, *args, **kwargs)
  File "/home/lenovo/projects/contact/manager/views.py", line 19, in home
    return render_to_response('inbox_home.html')
  File "/home/lenovo/Envs/contact/local/lib/python2.7/site-packages/django/shortcuts/__init__.py", line 29, in render_to_response
    return HttpResponse(loader.render_to_string(*args, **kwargs), **httpresponse_kwargs)
  File "/home/lenovo/Envs/contact/local/lib/python2.7/site-packages/django/template/loader.py", line 162, in render_to_string
    t = get_template(template_name)
  File "/home/lenovo/Envs/contact/local/lib/python2.7/site-packages/django/template/loader.py", line 138, in get_template
    template, origin = find_template(template_name)
  File "/home/lenovo/Envs/contact/local/lib/python2.7/site-packages/django/template/loader.py", line 127, in find_template
    source, display_name = loader(name, dirs)
  File "/home/lenovo/Envs/contact/local/lib/python2.7/site-packages/django/template/loader.py", line 43, in __call__
    return self.load_template(template_name, template_dirs)
  File "/home/lenovo/Envs/contact/local/lib/python2.7/site-packages/django/template/loader.py", line 49, in load_template
    template = get_template_from_string(source, origin, template_name)
  File "/home/lenovo/Envs/contact/local/lib/python2.7/site-packages/django/template/loader.py", line 149, in get_template_from_string
    return Template(source, origin, name)
  File "/home/lenovo/Envs/contact/local/lib/python2.7/site-packages/django/template/base.py", line 125, in __init__
    self.nodelist = compile_string(template_string, origin)
  File "/home/lenovo/Envs/contact/local/lib/python2.7/site-packages/django/template/base.py", line 153, in compile_string
    return parser.parse()
  File "/home/lenovo/Envs/contact/local/lib/python2.7/site-packages/django/template/base.py", line 254, in parse
    filter_expression = self.compile_filter(token.contents)
  File "/home/lenovo/Envs/contact/local/lib/python2.7/site-packages/django/template/base.py", line 360, in compile_filter
    return FilterExpression(token, self)
  File "/home/lenovo/Envs/contact/local/lib/python2.7/site-packages/django/template/base.py", line 571, in __init__
    filter_func = parser.find_filter(filter_name)
  File "/home/lenovo/Envs/contact/local/lib/python2.7/site-packages/django/template/base.py", line 366, in find_filter
    raise TemplateSyntaxError("Invalid filter: '%s'" % filter_name)
TemplateSyntaxError: Invalid filter: 'date_mdy'
[05/Aug/2014 07:09:48] ERROR [django.request:224] Internal Server Error: /
Traceback (most recent call last):
  File "/home/lenovo/Envs/contact/local/lib/python2.7/site-packages/django/core/handlers/base.py", line 112, in get_response
    response = wrapped_callback(request, *callback_args, **callback_kwargs)
  File "/home/lenovo/Envs/contact/local/lib/python2.7/site-packages/django/contrib/auth/decorators.py", line 22, in _wrapped_view
    return view_func(request, *args, **kwargs)
  File "/home/lenovo/projects/contact/manager/views.py", line 22, in home
    return HttpResponse(t.render())
TypeError: render() takes exactly 2 arguments (1 given)
[05/Aug/2014 07:10:01] ERROR [django.request:224] Internal Server Error: /
Traceback (most recent call last):
  File "/home/lenovo/Envs/contact/local/lib/python2.7/site-packages/django/core/handlers/base.py", line 112, in get_response
    response = wrapped_callback(request, *callback_args, **callback_kwargs)
  File "/home/lenovo/Envs/contact/local/lib/python2.7/site-packages/django/contrib/auth/decorators.py", line 22, in _wrapped_view
    return view_func(request, *args, **kwargs)
  File "/home/lenovo/projects/contact/manager/views.py", line 22, in home
    return HttpResponse(t.render(None))
  File "/home/lenovo/Envs/contact/local/lib/python2.7/site-packages/django/template/base.py", line 138, in render
    context.render_context.push()
AttributeError: 'NoneType' object has no attribute 'render_context'
[05/Aug/2014 07:10:32] ERROR [django.request:224] Internal Server Error: /
Traceback (most recent call last):
  File "/home/lenovo/Envs/contact/local/lib/python2.7/site-packages/django/core/handlers/base.py", line 112, in get_response
    response = wrapped_callback(request, *callback_args, **callback_kwargs)
  File "/home/lenovo/Envs/contact/local/lib/python2.7/site-packages/django/contrib/auth/decorators.py", line 22, in _wrapped_view
    return view_func(request, *args, **kwargs)
  File "/home/lenovo/projects/contact/manager/views.py", line 22, in home
    return HttpResponse(t.render({}))
  File "/home/lenovo/Envs/contact/local/lib/python2.7/site-packages/django/template/base.py", line 138, in render
    context.render_context.push()
AttributeError: 'dict' object has no attribute 'render_context'
[05/Aug/2014 08:41:05] ERROR [django.request:224] Internal Server Error: /contact/by_month/13/
Traceback (most recent call last):
  File "/home/lenovo/Envs/contact/local/lib/python2.7/site-packages/django/core/handlers/base.py", line 112, in get_response
    response = wrapped_callback(request, *callback_args, **callback_kwargs)
  File "/home/lenovo/Envs/contact/local/lib/python2.7/site-packages/django/views/generic/base.py", line 69, in view
    return self.dispatch(request, *args, **kwargs)
  File "/home/lenovo/Envs/contact/local/lib/python2.7/site-packages/django/views/decorators/csrf.py", line 57, in wrapped_view
    return view_func(*args, **kwargs)
  File "/home/lenovo/Envs/contact/local/lib/python2.7/site-packages/rest_framework/views.py", line 400, in dispatch
    response = self.handle_exception(exc)
  File "/home/lenovo/Envs/contact/local/lib/python2.7/site-packages/rest_framework/views.py", line 397, in dispatch
    response = handler(request, *args, **kwargs)
  File "/home/lenovo/projects/contact/contact/views.py", line 65, in get
    return Response(slz.data)
  File "/home/lenovo/Envs/contact/local/lib/python2.7/site-packages/rest_framework/serializers.py", line 573, in data
    self._data = [self.to_native(item) for item in obj]
  File "/home/lenovo/Envs/contact/local/lib/python2.7/site-packages/rest_framework/serializers.py", line 351, in to_native
    value = field.field_to_native(obj, field_name)
  File "/home/lenovo/Envs/contact/local/lib/python2.7/site-packages/rest_framework/fields.py", line 339, in field_to_native
    return super(WritableField, self).field_to_native(obj, field_name)
  File "/home/lenovo/Envs/contact/local/lib/python2.7/site-packages/rest_framework/fields.py", line 203, in field_to_native
    value = get_component(value, component)
  File "/home/lenovo/Envs/contact/local/lib/python2.7/site-packages/rest_framework/fields.py", line 56, in get_component
    val = getattr(obj, attr_name)
AttributeError: CommStat instance has no attribute 'count'
[05/Aug/2014 08:41:07] ERROR [django.request:224] Internal Server Error: /contact/by_month/11/
Traceback (most recent call last):
  File "/home/lenovo/Envs/contact/local/lib/python2.7/site-packages/django/core/handlers/base.py", line 112, in get_response
    response = wrapped_callback(request, *callback_args, **callback_kwargs)
  File "/home/lenovo/Envs/contact/local/lib/python2.7/site-packages/django/views/generic/base.py", line 69, in view
    return self.dispatch(request, *args, **kwargs)
  File "/home/lenovo/Envs/contact/local/lib/python2.7/site-packages/django/views/decorators/csrf.py", line 57, in wrapped_view
    return view_func(*args, **kwargs)
  File "/home/lenovo/Envs/contact/local/lib/python2.7/site-packages/rest_framework/views.py", line 400, in dispatch
    response = self.handle_exception(exc)
  File "/home/lenovo/Envs/contact/local/lib/python2.7/site-packages/rest_framework/views.py", line 397, in dispatch
    response = handler(request, *args, **kwargs)
  File "/home/lenovo/projects/contact/contact/views.py", line 65, in get
    return Response(slz.data)
  File "/home/lenovo/Envs/contact/local/lib/python2.7/site-packages/rest_framework/serializers.py", line 573, in data
    self._data = [self.to_native(item) for item in obj]
  File "/home/lenovo/Envs/contact/local/lib/python2.7/site-packages/rest_framework/serializers.py", line 351, in to_native
    value = field.field_to_native(obj, field_name)
  File "/home/lenovo/Envs/contact/local/lib/python2.7/site-packages/rest_framework/fields.py", line 339, in field_to_native
    return super(WritableField, self).field_to_native(obj, field_name)
  File "/home/lenovo/Envs/contact/local/lib/python2.7/site-packages/rest_framework/fields.py", line 203, in field_to_native
    value = get_component(value, component)
  File "/home/lenovo/Envs/contact/local/lib/python2.7/site-packages/rest_framework/fields.py", line 56, in get_component
    val = getattr(obj, attr_name)
AttributeError: CommStat instance has no attribute 'count'
[05/Aug/2014 08:41:24] ERROR [django.request:224] Internal Server Error: /contact/by_month/11/
Traceback (most recent call last):
  File "/home/lenovo/Envs/contact/local/lib/python2.7/site-packages/django/core/handlers/base.py", line 112, in get_response
    response = wrapped_callback(request, *callback_args, **callback_kwargs)
  File "/home/lenovo/Envs/contact/local/lib/python2.7/site-packages/django/views/generic/base.py", line 69, in view
    return self.dispatch(request, *args, **kwargs)
  File "/home/lenovo/Envs/contact/local/lib/python2.7/site-packages/django/views/decorators/csrf.py", line 57, in wrapped_view
    return view_func(*args, **kwargs)
  File "/home/lenovo/Envs/contact/local/lib/python2.7/site-packages/rest_framework/views.py", line 400, in dispatch
    response = self.handle_exception(exc)
  File "/home/lenovo/Envs/contact/local/lib/python2.7/site-packages/rest_framework/views.py", line 397, in dispatch
    response = handler(request, *args, **kwargs)
  File "/home/lenovo/projects/contact/contact/views.py", line 65, in get
    return Response(slz.data)
  File "/home/lenovo/Envs/contact/local/lib/python2.7/site-packages/rest_framework/serializers.py", line 573, in data
    self._data = [self.to_native(item) for item in obj]
  File "/home/lenovo/Envs/contact/local/lib/python2.7/site-packages/rest_framework/serializers.py", line 351, in to_native
    value = field.field_to_native(obj, field_name)
  File "/home/lenovo/Envs/contact/local/lib/python2.7/site-packages/rest_framework/fields.py", line 339, in field_to_native
    return super(WritableField, self).field_to_native(obj, field_name)
  File "/home/lenovo/Envs/contact/local/lib/python2.7/site-packages/rest_framework/fields.py", line 203, in field_to_native
    value = get_component(value, component)
  File "/home/lenovo/Envs/contact/local/lib/python2.7/site-packages/rest_framework/fields.py", line 56, in get_component
    val = getattr(obj, attr_name)
AttributeError: CommStat instance has no attribute 'count'
[05/Aug/2014 09:02:53] WARNING [django.request:143] Not Found: /favicon.ico
[05/Aug/2014 09:02:53] WARNING [django.request:143] Not Found: /favicon.ico
[05/Aug/2014 09:04:56] WARNING [django.request:143] Not Found: /mobile/user_id/
[05/Aug/2014 09:04:56] WARNING [django.request:143] Not Found: /favicon.ico
[05/Aug/2014 09:34:24] ERROR [django.request:224] Internal Server Error: /contacts/
Traceback (most recent call last):
  File "/home/lenovo/Envs/contact/local/lib/python2.7/site-packages/django/core/handlers/base.py", line 112, in get_response
    response = wrapped_callback(request, *callback_args, **callback_kwargs)
  File "/home/lenovo/Envs/contact/local/lib/python2.7/site-packages/django/views/generic/base.py", line 69, in view
    return self.dispatch(request, *args, **kwargs)
  File "/home/lenovo/Envs/contact/local/lib/python2.7/site-packages/django/views/decorators/csrf.py", line 57, in wrapped_view
    return view_func(*args, **kwargs)
  File "/home/lenovo/Envs/contact/local/lib/python2.7/site-packages/rest_framework/views.py", line 400, in dispatch
    response = self.handle_exception(exc)
  File "/home/lenovo/Envs/contact/local/lib/python2.7/site-packages/rest_framework/views.py", line 397, in dispatch
    response = handler(request, *args, **kwargs)
  File "/home/lenovo/projects/contact/manager/views.py", line 26, in get
    slz = ContactZoneSerializer(manager.contacts_with_zone, many=True)
  File "/home/lenovo/projects/contact/zone/__init__.py", line 28, in contacts_with_zone
    self.contacts.sort(key=lambda x: x.delta)
AttributeError: 'QuerySet' object has no attribute 'sort'
[05/Aug/2014 10:19:52] WARNING [django.request:143] Not Found: /mobile/user_id/+918592859274
